Workbook

Sheet BOT
A1: Value | B1: 2025/06/06 | C1: 2025/06/30 | D1: 2025/07/31 | E1: 2025/08/31 | F1: 2025/09/30 | G1: 2025/10/31 | H1: 2025/11/30 | I1: 2025/12/31 | J1: 2026/01/31 | K1: 2026/02/28 | L1: 2026/03/31 | M1: 2026/04/30 | N1: 2026/05/31 | O1: 2026/06/30 | P1: 2026/07/31 | Q1: 2026/08/31 | R1: 2026/09/30 | S1: 2026/10/31 | T1: 2026/11/30 | U1: 2026/12/31 | V1: 2027/01/31 | W1: 2027/02/28 | X1: 2027/03/31 | Y1: 2027/04/30 | Z1: 2027/05/31 | AA1: 2027/06/30 | AB1: 2027/07/31 | AC1: 2027/08/31 | AD1: 2027/09/30 | AE1: 2027/10/31 | AF1: 2027/11/30 | AG1: 2027/12/31 | AH1: 2028/01/31 | AI1: 2028/02/29 | AJ1: 2028/03/31 | AK1: 2028/04/30 | AL1: 2028/05/31 | AM1: 2028/06/30 | AN1: 2028/07/31 | AO1: 2028/08/31 | AP1: 2028/09/30 | AQ1: 2028/10/31 | AR1: 2028/11/30 | AS1: 2028/12/31 | AT1: 2029/01/31 | AU1: 2029/02/28 | AV1: 2029/03/31 | AW1: 2029/04/30 | AX1: 2029/05/31 | AY1: 2029/06/30 | AZ1: 2029/07/31 | BA1: 2029/08/31 | BB1: 2029/09/30 | BC1: 2029/10/31 | BD1: 2029/11/30 | BE1: 2029/12/31 | BF1: 2030/01/31 | BG1: 2030/02/28 | BH1: 2030/03/31 | BI1: 2030/04/30 | BJ1: 2030/05/31 | BK1: 2030/06/30 | BL1: 2030/07/31
A2: fml_count | B2: 475 | C2: 381 | D2: 377 | E2: 367 | F2: 362 | G2: 361 | H2: 340 | I2: 334 | J2: 333 | K2: 331 | L2: 310 | M2: 297 | N2: 266 | O2: 255 | P2: 244 | Q2: 234 | R2: 217 | S2: 211 | T2: 201 | U2: 192 | V2: 185 | W2: 180 | X2: 171 | Y2: 166 | Z2: 160 | AA2: 158 | AB2: 152 | AC2: 142 | AD2: 139 | AE2: 128 | AF2: 126 | AG2: 125 | AH2: 125 | AI2: 121 | AJ2: 114 | AK2: 87 | AL2: 69 | AM2: 67 | AN2: 62 | AO2: 59 | AP2: 52 | AQ2: 48 | AR2: 40 | AS2: 40 | AT2: 37 | AU2: 33 | AV2: 30 | AW2: 29 | AX2: 26 | AY2: 25 | AZ2: 23 | BA2: 22 | BB2: 21 | BC2: 19 | BD2: 14 | BE2: 12 | BF2: 11 | BG2: 9 | BH2: 8 | BI2: 4 | BJ2: 0 | BK2: 0 | BL2: 0
A3: olmm_count | B3: 24 | C3: 20 | D3: 20 | E3: 20 | F3: 19 | G3: 18 | H3: 17 | I3: 16 | J3: 16 | K3: 16 | L3: 15 | M3: 14 | N3: 14 | O3: 14 | P3: 14 | Q3: 14 | R3: 13 | S3: 13 | T3: 13 | U3: 13 | V3: 13 | W3: 12 | X3: 11 | Y3: 10 | Z3: 9 | AA3: 8 | AB3: 8 | AC3: 6 | AD3: 6 | AE3: 6 | AF3: 6 | AG3: 5 | AH3: 5 | AI3: 5 | AJ3: 4 | AK3: 4 | AL3: 4 | AM3: 4 | AN3: 3 | AO3: 2 | AP3: 2 | AQ3: 2 | AR3: 2 | AS3: 2 | AT3: 2 | AU3: 2 | AV3: 2 | AW3: 2 | AX3: 2 | AY3: 2 | AZ3: 2 | BA3: 2 | BB3: 1 | BC3: 1 | BD3: 1 | BE3: 1 | BF3: 1 | BG3: 0 | BH3: 0 | BI3: 0 | BJ3: 0 | BK3: 0 | BL3: 0
A4: pl_count | B4: 0 | C4: 0 | D4: 0 | E4: 0 | F4: 0 | G4: 0 | H4: 0 | I4: 0 | J4: 0 | K4: 0 | L4: 0 | M4: 0 | N4: 0 | O4: 0 | P4: 0 | Q4: 0 | R4: 0 | S4: 0 | T4: 0 | U4: 0 | V4: 0 | W4: 0 | X4: 0 | Y4: 0 | Z4: 0 | AA4: 0 | AB4: 0 | AC4: 0 | AD4: 0 | AE4: 0 | AF4: 0 | AG4: 0 | AH4: 0 | AI4: 0 | AJ4: 0 | AK4: 0 | AL4: 0 | AM4: 0 | AN4: 0 | AO4: 0 | AP4: 0 | AQ4: 0 | AR4: 0 | AS4: 0 | AT4: 0 | AU4: 0 | AV4: 0 | AW4: 0 | AX4: 0 | AY4: 0 | AZ4: 0 | BA4: 0 | BB4: 0 | BC4: 0 | BD4: 0 | BE4: 0 | BF4: 0 | BG4: 0 | BH4: 0 | BI4: 0 | BJ4: 0 | BK4: 0 | BL4: 0
A5: revenue_p_m | B5: 4962187.6 | C5: 4172192.8 | D5: 4125217.5 | E5: 3985602.6 | F5: 3908387.9 | G5: 3881528.1 | H5: 3719033.9 | I5: 3675761.8 | J5: 3662318.8 | K5: 3644039.8 | L5: 3493851.7 | M5: 3368205.8 | N5: 3098877.1 | O5: 2964392.4 | P5: 2858410.3 | Q5: 2763297.3 | R5: 2568700.6 | S5: 2477895.6 | T5: 2347004.5 | U5: 2239170.5 | V5: 2150987.5 | W5: 2065239.3 | X5: 1966785.6 | Y5: 1902066.5 | Z5: 1810962.2 | AA5: 1777110.1 | AB5: 1674406.2 | AC5: 1588462 | AD5: 1540260.1 | AE5: 1421304.5 | AF5: 1403328.1 | AG5: 1382263.9 | AH5: 1382263.9 | AI5: 1332494.2 | AJ5: 1246150.6 | AK5: 1075462.7 | AL5: 884121.3 | AM5: 872779.83 | AN5: 810616.81 | AO5: 733333.36 | AP5: 665338.36 | AQ5: 594758.88 | AR5: 513115.45 | AS5: 513115.45 | AT5: 452820.35 | AU5: 414001.8 | AV5: 364513.69 | AW5: 352715.13 | AX5: 327538.32 | AY5: 320510.12 | AZ5: 310494.33 | BA5: 298305.72 | BB5: 265106.21 | BC5: 242757.47 | BD5: 189192.61 | BE5: 170847.19 | BF5: 164578.86 | BG5: 138315.89 | BH5: 100642.59 | BI5: 45172.83 | BJ5: 0 | BK5: 0 | BL5: 0
A6: depreciation_p_m | B6: 2668122.3 | C6: 2267367.5 | D6: 2240025.9 | E6: 2161712 | F6: 2113937.3 | G6: 2096871.8 | H6: 1998904.2 | I6: 1976975.3 | J6: 1972099.1 | K6: 1962244.3 | L6: 1877055.8 | M6: 1802993.2 | N6: 1654241.2 | O6: 1584406.1 | P6: 1525881 | Q6: 1475919.4 | R6: 1365854.4 | S6: 1312184.2 | T6: 1236623.3 | U6: 1177073.8 | V6: 1127379.5 | W6: 1079275.6 | X6: 1033510.3 | Y6: 1008357.8 | Z6: 956569.88 | AA6: 935638.39 | AB6: 874437.52 | AC6: 830868.74 | AD6: 801981.73 | AE6: 737504.41 | AF6: 726584.72 | AG6: 714367.96 | AH6: 714367.96 | AI6: 685113.89 | AJ6: 634796.55 | AK6: 547650.34 | AL6: 448118.92 | AM6: 443221.76 | AN6: 408766.49 | AO6: 381348.41 | AP6: 345824.59 | AQ6: 314089.43 | AR6: 274346.69 | AS6: 274346.69 | AT6: 240760.03 | AU6: 219325.95 | AV6: 201073.57 | AW6: 194339.66 | AX6: 182179.67 | AY6: 178766.57 | AZ6: 173781.54 | BA6: 167495.58 | BB6: 147114.84 | BC6: 134897.2 | BD6: 106340.69 | BE6: 95868.84 | BF6: 92341.94 | BG6: 76745.71 | BH6: 55748.98 | BI6: 21780.23 | BJ6: 0 | BK6: 0 | BL6: 0
A7: interest_p_m | B7: 737545.95 | C7: 630685.61 | D7: 624938.06 | E7: 608178.83 | F7: 599924.16 | G7: 596784.9 | H7: 571897.16 | I7: 565384.11 | J7: 565193.46 | K7: 563069.12 | L7: 549646.93 | M7: 529829.86 | N7: 481913.7 | O7: 457477 | P7: 442866.58 | Q7: 425863.73 | R7: 389616.41 | S7: 379259.43 | T7: 361778.06 | U7: 347544.89 | V7: 334127.25 | W7: 324155.18 | X7: 312378.19 | Y7: 307073.52 | Z7: 292330.98 | AA7: 287618.74 | AB7: 273551.73 | AC7: 257511.38 | AD7: 250787.29 | AE7: 228906.93 | AF7: 225897.55 | AG7: 221656.11 | AH7: 221656.11 | AI7: 212789.07 | AJ7: 196808.58 | AK7: 170126.36 | AL7: 138547.94 | AM7: 136694.47 | AN7: 127259.41 | AO7: 118748.68 | AP7: 108896.41 | AQ7: 99144.85 | AR7: 85384.27 | AS7: 85384.27 | AT7: 77282.52 | AU7: 70519.11 | AV7: 64063 | AW7: 61523.04 | AX7: 57945.05 | AY7: 56127.53 | AZ7: 54727.51 | BA7: 52450.71 | BB7: 46247.63 | BC7: 41092.95 | BD7: 32788.33 | BE7: 29722.41 | BF7: 28697.35 | BG7: 23906.3 | BH7: 17315.74 | BI7: 7583.79 | BJ7: 0 | BK7: 0 | BL7: 0
A8: admin_p_m | B8: 471769.89 | C8: 407200.32 | D8: 404891.14 | E8: 394934.45 | F8: 389695.44 | G8: 387529.38 | H8: 373654.46 | I8: 368888.01 | J8: 367816.9 | K8: 366871.95 | L8: 359023.84 | M8: 349029.63 | N8: 318668.02 | O8: 303351.43 | P8: 296065.83 | Q8: 286005.1 | R8: 262360.39 | S8: 253998.26 | T8: 243835.2 | U8: 236874.14 | V8: 227901.47 | W8: 221129.61 | X8: 209242.1 | Y8: 201067.91 | Z8: 191185.12 | AA8: 188022.56 | AB8: 179459.59 | AC8: 170025.13 | AD8: 165931.18 | AE8: 153502.01 | AF8: 151691.17 | AG8: 148915.78 | AH8: 148915.78 | AI8: 143610.51 | AJ8: 133288.95 | AK8: 114871.01 | AL8: 93729.6 | AM8: 92700.11 | AN8: 86071.82 | AO8: 79874.15 | AP8: 73525.22 | AQ8: 67105.88 | AR8: 57917.9 | AS8: 57917.9 | AT8: 52136.59 | AU8: 48078.1 | AV8: 43428.66 | AW8: 41985.68 | AX8: 39533.64 | AY8: 38609.18 | AZ8: 37739.58 | BA8: 36426.36 | BB8: 32140.8 | BC8: 29225.96 | BD8: 23186.16 | BE8: 21269.45 | BF8: 20623.95 | BG8: 17200.02 | BH8: 12278.2 | BI8: 6155.44 | BJ8: 0 | BK8: 0 | BL8: 0
A9: maint_prov_p_m | B9: 22977696 | C9: 12435450 | D9: 12223543 | E9: 11431551 | F9: 11117320 | G9: 11048284 | H9: 10307242 | I9: 10068142 | J9: 10000577 | K9: 9890029.1 | L9: 9165476.9 | M9: 8572543.4 | N9: 7821197.3 | O9: 7330808.8 | P9: 6855876.3 | Q9: 6562705 | R9: 6094363.4 | S9: 5823487.8 | T9: 5456953.2 | U9: 5147949.1 | V9: 4897613 | W9: 4700357.8 | X9: 4237782.8 | Y9: 3924317.4 | Z9: 3677687.4 | AA9: 3532245.8 | AB9: 3284596.1 | AC9: 2901091.6 | AD9: 2805662.5 | AE9: 2528706.5 | AF9: 2490140.5 | AG9: 2457639.7 | AH9: 2457639.7 | AI9: 2333189.3 | AJ9: 2255127.7 | AK9: 2119626.6 | AL9: 1657802.6 | AM9: 1566906.3 | AN9: 1425989.9 | AO9: 1209185.2 | AP9: 1030103.7 | AQ9: 867737.94 | AR9: 644683.09 | AS9: 644683.09 | AT9: 503415.48 | AU9: 380671.47 | AV9: 287506.86 | AW9: 272181.21 | AX9: 232819.28 | AY9: 215053.18 | AZ9: 184597.14 | BA9: 159818.21 | BB9: 139927.04 | BC9: 124323 | BD9: 66731.69 | BE9: 49592.61 | BF9: 46150.76 | BG9: 38830.34 | BH9: 23517.77 | BI9: 12696.95 | BJ9: 0 | BK9: 0 | BL9: 0
A10: maintenance_fund | B10: 13257588 | C10: 8080983.3 | D10: 7963378.7 | E10: 7576470.3 | F10: 7433785.8 | G10: 7405436.7 | H10: 7025375 | I10: 6874342.2 | J10: 6851788.3 | K10: 6830399.1 | L10: 6562993.2 | M10: 6384230.6 | N10: 5963135.9 | O10: 5586774.1 | P10: 5363876.2 | Q10: 5188050.7 | R10: 4855830.2 | S10: 4610476.6 | T10: 4337029.7 | U10: 4104176.6 | V10: 3896057.7 | W10: 3753724.4 | X10: 3463700 | Y10: 3240230.8 | Z10: 3044243.6 | AA10: 2918448.3 | AB10: 2699058.2 | AC10: 2365119.3 | AD10: 2278897.9 | AE10: 2132416 | AF10: 2093850 | AG10: 2061349.2 | AH10: 2061349.2 | AI10: 1949932.9 | AJ10: 1875079.4 | AK10: 1746762.3 | AL10: 1429138.4 | AM10: 1345966.4 | AN10: 1220899 | AO10: 1038555.2 | AP10: 862786.72 | AQ10: 707880.4 | AR10: 500573.64 | AS10: 500573.64 | AT10: 424783.76 | AU10: 345252.83 | AV10: 284101.44 | AW10: 268775.79 | AX10: 229413.86 | AY10: 211647.76 | AZ10: 181191.72 | BA10: 159818.21 | BB10: 139927.04 | BC10: 124323 | BD10: 66731.69 | BE10: 49592.61 | BF10: 46150.76 | BG10: 38830.34 | BH10: 23517.77 | BI10: 12696.95 | BJ10: 0 | BK10: 0 | BL10: 0
A11: other_fee_p_m | B11: 201610.65 | C11: 179272.35 | D11: 174288.46 | E11: 172803.7 | F11: 171651.83 | G11: 171205.33 | H11: 168398.86 | I11: 167193.14 | J11: 167133.14 | K11: 167013.14 | L11: 164170.66 | M11: 163390.66 | N11: 151748.51 | O11: 146275.43 | P11: 145308.93 | Q11: 140651.81 | R11: 132877.86 | S11: 127240.21 | T11: 120023.22 | U11: 107289.47 | V11: 102814.81 | W11: 95902.29 | X11: 94995.79 | Y11: 91530.86 | Z11: 87237.95 | AA11: 87037.95 | AB11: 78823.3 | AC11: 78103.3 | AD11: 75088.87 | AE11: 68947.5 | AF11: 67609.11 | AG11: 67489.11 | AH11: 67489.11 | AI11: 66866.61 | AJ11: 64754.11 | AK11: 54191.93 | AL11: 47052.25 | AM11: 46932.25 | AN11: 45604.75 | AO11: 34648.19 | AP11: 32938.19 | AQ11: 28507.55 | AR11: 23125.95 | AS11: 23125.95 | AT11: 17007.07 | AU11: 16767.07 | AV11: 8414.19 | AW11: 8354.19 | AX11: 7101.62 | AY11: 7041.62 | AZ11: 6921.62 | BA11: 6861.62 | BB11: 6741.62 | BC11: 6561.62 | BD11: 4125.02 | BE11: 3682.52 | BF11: 3300.02 | BG11: 2475.02 | BH11: 2415.02 | BI11: 1530.02 | BJ11: 0 | BK11: 0 | BL11: 0
A12: total_cost | B12: 1.8097802e+08 | C12: 1.5321032e+08 | D12: 1.5194827e+08 | E12: 1.4798652e+08 | F12: 1.4591233e+08 | G12: 1.4513108e+08 | H12: 1.3901625e+08 | I12: 1.3717322e+08 | J12: 1.3674477e+08 | K12: 1.3624916e+08 | L12: 1.3210466e+08 | M12: 1.2750744e+08 | N12: 1.1722332e+08 | O12: 1.1210884e+08 | P12: 1.0825801e+08 | Q12: 1.0447934e+08 | R12: 96581095 | S12: 93837215 | T12: 89240027 | U12: 85863940 | V12: 82914238 | W12: 80525876 | X12: 76729938 | Y12: 74509768 | Z12: 71039290 | AA12: 69734215 | AB12: 66153890 | AC12: 62354725 | AD12: 60799103 | AE12: 56103638 | AF12: 55324298 | AG12: 54371410 | AH12: 54371410 | AI12: 52327657 | AJ12: 48690075 | AK12: 42704587 | AL12: 35549893 | AM12: 35035143 | AN12: 32344318 | AO12: 29930024 | AP12: 27246663 | AQ12: 24703133 | AR12: 21440250 | AS12: 21440250 | AT12: 19133082 | AU12: 17430516 | AV12: 15724376 | AW12: 15147183 | AX12: 14265238 | AY12: 13803005 | AZ12: 13422739 | BA12: 12897450 | BB12: 11309785 | BC12: 10143847 | BD12: 8053369.3 | BE12: 7271913.5 | BF12: 7004807.8 | BG12: 5729167.3 | BH12: 4252619 | BI12: 1773259.8 | BJ12: 0 | BK12: 0 | BL12: 0
A13: nbv | B13: 1.1214437e+08 | C13: 1.0511136e+08 | D13: 1.0237632e+08 | E13: 98605758 | F13: 95859915 | G13: 93562887 | H13: 89161929 | I13: 86476123 | J13: 84444582 | K13: 82279337 | L13: 79125103 | M13: 75552720 | N13: 68696729 | O13: 64516329 | P13: 61542210 | Q13: 58238919 | R13: 52997014 | S13: 50923658 | T13: 47804519 | U13: 45305156 | V13: 42994852 | W13: 41079028 | X13: 38951942 | Y13: 37524987 | Z13: 35534347 | AA13: 34415056 | AB13: 32736576 | AC13: 30459593 | AD13: 29293862 | AE13: 26399583 | AF13: 25461884 | AG13: 24445072 | AH13: 23730704 | AI13: 22449052 | AJ13: 20298934 | AK13: 16875186 | AL13: 13709958 | AM13: 13063489 | AN13: 12015113 | AO13: 11176423 | AP13: 10052884 | AQ13: 9159043.9 | AR13: 7808893.9 | AS13: 7534547.2 | AT13: 6955467.4 | AU13: 6299129.5 | AV13: 5565394.4 | AW13: 5191162.5 | AX13: 4764551.4 | AY13: 4334182.6 | AZ13: 4072536.3 | BA13: 3750622.9 | BB13: 3254218.5 | BC13: 2668239.6 | BD13: 2127698.9 | BE13: 1868213.4 | BF13: 1713325.9 | BG13: 1326416.1 | BH13: 1011929.1 | BI13: 496230.26 | BJ13: 0 | BK13: 0 | BL13: 0
... A16: olmm_fleet_drop | B16: 0 | C16: 4 | D16: 0 | E16: 0 | F16: 1 | G16: 1 | H16: 1 | I16: 1 | J16: 0 | K16: 0 | L16: 1 | M16: 1 | N16: 0 | O16: 0 | P16: 0 | Q16: 0 | R16: 1 | S16: 0 | T16: 0 | U16: 0 | V16: 0 | W16: 1 | X16: 1 | Y16: 1 | Z16: 1 | AA16: 1 | AB16: 0 | AC16: 2 | AD16: 0 | AE16: 0 | AF16: 0 | AG16: 1 | AH16: 0 | AI16: 0 | AJ16: 1 | AK16: 0 | AL16: 0 | AM16: 0 | AN16: 1 | AO16: 1 | AP16: 0 | AQ16: 0 | AR16: 0 | AS16: 0 | AT16: 0 | AU16: 0 | AV16: 0 | AW16: 0 | AX16: 0 | AY16: 0 | AZ16: 0 | BA16: 0 | BB16: 1 | BC16: 0 | BD16: 0 | BE16: 0 | BF16: 0 | BG16: 1 | BH16: 0 | BI16: 0 | BJ16: 0 | BK16: 0 | BL16: 0

Sheet GHA
A1: Value | B1: 2025/06/06 | C1: 2025/06/30 | D1: 2025/07/31 | E1: 2025/08/31 | F1: 2025/09/30 | G1: 2025/10/31 | H1: 2025/11/30 | I1: 2025/12/31 | J1: 2026/01/31 | K1: 2026/02/28 | L1: 2026/03/31 | M1: 2026/04/30 | N1: 2026/05/31 | O1: 2026/06/30 | P1: 2026/07/31 | Q1: 2026/08/31 | R1: 2026/09/30 | S1: 2026/10/31 | T1: 2026/11/30 | U1: 2026/12/31 | V1: 2027/01/31 | W1: 2027/02/28 | X1: 2027/03/31 | Y1: 2027/04/30 | Z1: 2027/05/31 | AA1: 2027/06/30 | AB1: 2027/07/31 | AC1: 2027/08/31 | AD1: 2027/09/30 | AE1: 2027/10/31 | AF1: 2027/11/30 | AG1: 2027/12/31 | AH1: 2028/01/31 | AI1: 2028/02/29 | AJ1: 2028/03/31 | AK1: 2028/04/30 | AL1: 2028/05/31 | AM1: 2028/06/30 | AN1: 2028/07/31 | AO1: 2028/08/31 | AP1: 2028/09/30 | AQ1: 2028/10/31 | AR1: 2028/11/30 | AS1: 2028/12/31 | AT1: 2029/01/31 | AU1: 2029/02/28 | AV1: 2029/03/31 | AW1: 2029/04/30 | AX1: 2029/05/31 | AY1: 2029/06/30 | AZ1: 2029/07/31 | BA1: 2029/08/31 | BB1: 2029/09/30 | BC1: 2029/10/31 | BD1: 2029/11/30 | BE1: 2029/12/31 | BF1: 2030/01/31 | BG1: 2030/02/28 | BH1: 2030/03/31 | BI1: 2030/04/30 | BJ1: 2030/05/31 | BK1: 2030/06/30 | BL1: 2030/07/31
A2: fml_count | B2: 11 | C2: 11 | D2: 11 | E2: 10 | F2: 4 | G2: 4 | H2: 4 | I2: 0 | J2: 0 | K2: 0 | L2: 0 | M2: 0 | N2: 0 | O2: 0 | P2: 0 | Q2: 0 | R2: 0 | S2: 0 | T2: 0 | U2: 0 | V2: 0 | W2: 0 | X2: 0 | Y2: 0 | Z2: 0 | AA2: 0 | AB2: 0 | AC2: 0 | AD2: 0 | AE2: 0 | AF2: 0 | AG2: 0 | AH2: 0 | AI2: 0 | AJ2: 0 | AK2: 0 | AL2: 0 | AM2: 0 | AN2: 0 | AO2: 0 | AP2: 0 | AQ2: 0 | AR2: 0 | AS2: 0 | AT2: 0 | AU2: 0 | AV2: 0 | AW2: 0 | AX2: 0 | AY2: 0 | AZ2: 0 | BA2: 0 | BB2: 0 | BC2: 0 | BD2: 0 | BE2: 0 | BF2: 0 | BG2: 0 | BH2: 0 | BI2: 0 | BJ2: 0 | BK2: 0 | BL2: 0
A3: olmm_count | B3: 0 | C3: 0 | D3: 0 | E3: 0 | F3: 0 | G3: 0 | H3: 0 | I3: 0 | J3: 0 | K3: 0 | L3: 0 | M3: 0 | N3: 0 | O3: 0 | P3: 0 | Q3: 0 | R3: 0 | S3: 0 | T3: 0 | U3: 0 | V3: 0 | W3: 0 | X3: 0 | Y3: 0 | Z3: 0 | AA3: 0 | AB3: 0 | AC3: 0 | AD3: 0 | AE3: 0 | AF3: 0 | AG3: 0 | AH3: 0 | AI3: 0 | AJ3: 0 | AK3: 0 | AL3: 0 | AM3: 0 | AN3: 0 | AO3: 0 | AP3: 0 | AQ3: 0 | AR3: 0 | AS3: 0 | AT3: 0 | AU3: 0 | AV3: 0 | AW3: 0 | AX3: 0 | AY3: 0 | AZ3: 0 | BA3: 0 | BB3: 0 | BC3: 0 | BD3: 0 | BE3: 0 | BF3: 0 | BG3: 0 | BH3: 0 | BI3: 0 | BJ3: 0 | BK3: 0 | BL3: 0
A4: pl_count | B4: 0 | C4: 0 | D4: 0 | E4: 0 | F4: 0 | G4: 0 | H4: 0 | I4: 0 | J4: 0 | K4: 0 | L4: 0 | M4: 0 | N4: 0 | O4: 0 | P4: 0 | Q4: 0 | R4: 0 | S4: 0 | T4: 0 | U4: 0 | V4: 0 | W4: 0 | X4: 0 | Y4: 0 | Z4: 0 | AA4: 0 | AB4: 0 | AC4: 0 | AD4: 0 | AE4: 0 | AF4: 0 | AG4: 0 | AH4: 0 | AI4: 0 | AJ4: 0 | AK4: 0 | AL4: 0 | AM4: 0 | AN4: 0 | AO4: 0 | AP4: 0 | AQ4: 0 | AR4: 0 | AS4: 0 | AT4: 0 | AU4: 0 | AV4: 0 | AW4: 0 | AX4: 0 | AY4: 0 | AZ4: 0 | BA4: 0 | BB4: 0 | BC4: 0 | BD4: 0 | BE4: 0 | BF4: 0 | BG4: 0 | BH4: 0 | BI4: 0 | BJ4: 0 | BK4: 0 | BL4: 0
A5: revenue_p_m | B5: 8735.23 | C5: 8735.23 | D5: 8735.23 | E5: 8340.19 | F5: 1804.33 | G5: 1804.33 | H5: 1804.33 | I5: 0 | J5: 0 | K5: 0 | L5: 0 | M5: 0 | N5: 0 | O5: 0 | P5: 0 | Q5: 0 | R5: 0 | S5: 0 | T5: 0 | U5: 0 | V5: 0 | W5: 0 | X5: 0 | Y5: 0 | Z5: 0 | AA5: 0 | AB5: 0 | AC5: 0 | AD5: 0 | AE5: 0 | AF5: 0 | AG5: 0 | AH5: 0 | AI5: 0 | AJ5: 0 | AK5: 0 | AL5: 0 | AM5: 0 | AN5: 0 | AO5: 0 | AP5: 0 | AQ5: 0 | AR5: 0 | AS5: 0 | AT5: 0 | AU5: 0 | AV5: 0 | AW5: 0 | AX5: 0 | AY5: 0 | AZ5: 0 | BA5: 0 | BB5: 0 | BC5: 0 | BD5: 0 | BE5: 0 | BF5: 0 | BG5: 0 | BH5: 0 | BI5: 0 | BJ5: 0 | BK5: 0 | BL5: 0
A6: depreciation_p_m | B6: 2927.43 | C6: 2927.43 | D6: 2927.43 | E6: 2860.57 | F6: 358.15 | G6: 358.15 | H6: 358.15 | I6: 0 | J6: 0 | K6: 0 | L6: 0 | M6: 0 | N6: 0 | O6: 0 | P6: 0 | Q6: 0 | R6: 0 | S6: 0 | T6: 0 | U6: 0 | V6: 0 | W6: 0 | X6: 0 | Y6: 0 | Z6: 0 | AA6: 0 | AB6: 0 | AC6: 0 | AD6: 0 | AE6: 0 | AF6: 0 | AG6: 0 | AH6: 0 | AI6: 0 | AJ6: 0 | AK6: 0 | AL6: 0 | AM6: 0 | AN6: 0 | AO6: 0 | AP6: 0 | AQ6: 0 | AR6: 0 | AS6: 0 | AT6: 0 | AU6: 0 | AV6: 0 | AW6: 0 | AX6: 0 | AY6: 0 | AZ6: 0 | BA6: 0 | BB6: 0 | BC6: 0 | BD6: 0 | BE6: 0 | BF6: 0 | BG6: 0 | BH6: 0 | BI6: 0 | BJ6: 0 | BK6: 0 | BL6: 0
A7: interest_p_m | B7: 1197.83 | C7: 1197.83 | D7: 1197.83 | E7: 1172.72 | F7: 316.52 | G7: 316.52 | H7: 316.52 | I7: 0 | J7: 0 | K7: 0 | L7: 0 | M7: 0 | N7: 0 | O7: 0 | P7: 0 | Q7: 0 | R7: 0 | S7: 0 | T7: 0 | U7: 0 | V7: 0 | W7: 0 | X7: 0 | Y7: 0 | Z7: 0 | AA7: 0 | AB7: 0 | AC7: 0 | AD7: 0 | AE7: 0 | AF7: 0 | AG7: 0 | AH7: 0 | AI7: 0 | AJ7: 0 | AK7: 0 | AL7: 0 | AM7: 0 | AN7: 0 | AO7: 0 | AP7: 0 | AQ7: 0 | AR7: 0 | AS7: 0 | AT7: 0 | AU7: 0 | AV7: 0 | AW7: 0 | AX7: 0 | AY7: 0 | AZ7: 0 | BA7: 0 | BB7: 0 | BC7: 0 | BD7: 0 | BE7: 0 | BF7: 0 | BG7: 0 | BH7: 0 | BI7: 0 | BJ7: 0 | BK7: 0 | BL7: 0
A8: admin_p_m | B8: 1129.54 | C8: 1129.54 | D8: 1129.54 | E8: 1049.54 | F8: 320 | G8: 320 | H8: 320 | I8: 0 | J8: 0 | K8: 0 | L8: 0 | M8: 0 | N8: 0 | O8: 0 | P8: 0 | Q8: 0 | R8: 0 | S8: 0 | T8: 0 | U8: 0 | V8: 0 | W8: 0 | X8: 0 | Y8: 0 | Z8: 0 | AA8: 0 | AB8: 0 | AC8: 0 | AD8: 0 | AE8: 0 | AF8: 0 | AG8: 0 | AH8: 0 | AI8: 0 | AJ8: 0 | AK8: 0 | AL8: 0 | AM8: 0 | AN8: 0 | AO8: 0 | AP8: 0 | AQ8: 0 | AR8: 0 | AS8: 0 | AT8: 0 | AU8: 0 | AV8: 0 | AW8: 0 | AX8: 0 | AY8: 0 | AZ8: 0 | BA8: 0 | BB8: 0 | BC8: 0 | BD8: 0 | BE8: 0 | BF8: 0 | BG8: 0 | BH8: 0 | BI8: 0 | BJ8: 0 | BK8: 0 | BL8: 0
A9: maint_prov_p_m | B9: 89467.93 | C9: 89467.93 | D9: 89467.93 | E9: 83784.47 | F9: 21412.67 | G9: 21412.67 | H9: 21412.67 | I9: 0 | J9: 0 | K9: 0 | L9: 0 | M9: 0 | N9: 0 | O9: 0 | P9: 0 | Q9: 0 | R9: 0 | S9: 0 | T9: 0 | U9: 0 | V9: 0 | W9: 0 | X9: 0 | Y9: 0 | Z9: 0 | AA9: 0 | AB9: 0 | AC9: 0 | AD9: 0 | AE9: 0 | AF9: 0 | AG9: 0 | AH9: 0 | AI9: 0 | AJ9: 0 | AK9: 0 | AL9: 0 | AM9: 0 | AN9: 0 | AO9: 0 | AP9: 0 | AQ9: 0 | AR9: 0 | AS9: 0 | AT9: 0 | AU9: 0 | AV9: 0 | AW9: 0 | AX9: 0 | AY9: 0 | AZ9: 0 | BA9: 0 | BB9: 0 | BC9: 0 | BD9: 0 | BE9: 0 | BF9: 0 | BG9: 0 | BH9: 0 | BI9: 0 | BJ9: 0 | BK9: 0 | BL9: 0
A10: maintenance_fund | B10: 50104 | C10: 50104 | D10: 50104 | E10: 46766.11 | F10: 5594.12 | G10: 5594.12 | H10: 5594.12 | I10: 0 | J10: 0 | K10: 0 | L10: 0 | M10: 0 | N10: 0 | O10: 0 | P10: 0 | Q10: 0 | R10: 0 | S10: 0 | T10: 0 | U10: 0 | V10: 0 | W10: 0 | X10: 0 | Y10: 0 | Z10: 0 | AA10: 0 | AB10: 0 | AC10: 0 | AD10: 0 | AE10: 0 | AF10: 0 | AG10: 0 | AH10: 0 | AI10: 0 | AJ10: 0 | AK10: 0 | AL10: 0 | AM10: 0 | AN10: 0 | AO10: 0 | AP10: 0 | AQ10: 0 | AR10: 0 | AS10: 0 | AT10: 0 | AU10: 0 | AV10: 0 | AW10: 0 | AX10: 0 | AY10: 0 | AZ10: 0 | BA10: 0 | BB10: 0 | BC10: 0 | BD10: 0 | BE10: 0 | BF10: 0 | BG10: 0 | BH10: 0 | BI10: 0 | BJ10: 0 | BK10: 0 | BL10: 0
A11: other_fee_p_m | B11: 2003.25 | C11: 2003.25 | D11: 2003.25 | E11: 1894.52 | F11: 434.84 | G11: 434.84 | H11: 434.84 | I11: 0 | J11: 0 | K11: 0 | L11: 0 | M11: 0 | N11: 0 | O11: 0 | P11: 0 | Q11: 0 | R11: 0 | S11: 0 | T11: 0 | U11: 0 | V11: 0 | W11: 0 | X11: 0 | Y11: 0 | Z11: 0 | AA11: 0 | AB11: 0 | AC11: 0 | AD11: 0 | AE11: 0 | AF11: 0 | AG11: 0 | AH11: 0 | AI11: 0 | AJ11: 0 | AK11: 0 | AL11: 0 | AM11: 0 | AN11: 0 | AO11: 0 | AP11: 0 | AQ11: 0 | AR11: 0 | AS11: 0 | AT11: 0 | AU11: 0 | AV11: 0 | AW11: 0 | AX11: 0 | AY11: 0 | AZ11: 0 | BA11: 0 | BB11: 0 | BC11: 0 | BD11: 0 | BE11: 0 | BF11: 0 | BG11: 0 | BH11: 0 | BI11: 0 | BJ11: 0 | BK11: 0 | BL11: 0
A12: total_cost | B12: 245056.84 | C12: 245056.84 | D12: 245056.84 | E12: 231755.14 | F12: 53197 | G12: 53197 | H12: 53197 | I12: 0 | J12: 0 | K12: 0 | L12: 0 | M12: 0 | N12: 0 | O12: 0 | P12: 0 | Q12: 0 | R12: 0 | S12: 0 | T12: 0 | U12: 0 | V12: 0 | W12: 0 | X12: 0 | Y12: 0 | Z12: 0 | AA12: 0 | AB12: 0 | AC12: 0 | AD12: 0 | AE12: 0 | AF12: 0 | AG12: 0 | AH12: 0 | AI12: 0 | AJ12: 0 | AK12: 0 | AL12: 0 | AM12: 0 | AN12: 0 | AO12: 0 | AP12: 0 | AQ12: 0 | AR12: 0 | AS12: 0 | AT12: 0 | AU12: 0 | AV12: 0 | AW12: 0 | AX12: 0 | AY12: 0 | AZ12: 0 | BA12: 0 | BB12: 0 | BC12: 0 | BD12: 0 | BE12: 0 | BF12: 0 | BG12: 0 | BH12: 0 | BI12: 0 | BJ12: 0 | BK12: 0 | BL12: 0
A13: nbv | B13: 87189.01 | C13: 87189.01 | D13: 84261.58 | E13: 79450.09 | F13: 15643.02 | G13: 15284.87 | H13: 14926.72 | I13: 0 | J13: 0 | K13: 0 | L13: 0 | M13: 0 | N13: 0 | O13: 0 | P13: 0 | Q13: 0 | R13: 0 | S13: 0 | T13: 0 | U13: 0 | V13: 0 | W13: 0 | X13: 0 | Y13: 0 | Z13: 0 | AA13: 0 | AB13: 0 | AC13: 0 | AD13: 0 | AE13: 0 | AF13: 0 | AG13: 0 | AH13: 0 | AI13: 0 | AJ13: 0 | AK13: 0 | AL13: 0 | AM13: 0 | AN13: 0 | AO13: 0 | AP13: 0 | AQ13: 0 | AR13: 0 | AS13: 0 | AT13: 0 | AU13: 0 | AV13: 0 | AW13: 0 | AX13: 0 | AY13: 0 | AZ13: 0 | BA13: 0 | BB13: 0 | BC13: 0 | BD13: 0 | BE13: 0 | BF13: 0 | BG13: 0 | BH13: 0 | BI13: 0 | BJ13: 0 | BK13: 0 | BL13: 0
... A16: olmm_fleet_drop | B16: 0 | C16: 0 | D16: 0 | E16: 0 | F16: 0 | G16: 0 | H16: 0 | I16: 0 | J16: 0 | K16: 0 | L16: 0 | M16: 0 | N16: 0 | O16: 0 | P16: 0 | Q16: 0 | R16: 0 | S16: 0 | T16: 0 | U16: 0 | V16: 0 | W16: 0 | X16: 0 | Y16: 0 | Z16: 0 | AA16: 0 | AB16: 0 | AC16: 0 | AD16: 0 | AE16: 0 | AF16: 0 | AG16: 0 | AH16: 0 | AI16: 0 | AJ16: 0 | AK16: 0 | AL16: 0 | AM16: 0 | AN16: 0 | AO16: 0 | AP16: 0 | AQ16: 0 | AR16: 0 | AS16: 0 | AT16: 0 | AU16: 0 | AV16: 0 | AW16: 0 | AX16: 0 | AY16: 0 | AZ16: 0 | BA16: 0 | BB16: 0 | BC16: 0 | BD16: 0 | BE16: 0 | BF16: 0 | BG16: 0 | BH16: 0 | BI16: 0 | BJ16: 0 | BK16: 0 | BL16: 0

Sheet GHC
A1: Value | B1: 2025/06/06 | C1: 2025/06/30 | D1: 2025/07/31 | E1: 2025/08/31 | F1: 2025/09/30 | G1: 2025/10/31 | H1: 2025/11/30 | I1: 2025/12/31 | J1: 2026/01/31 | K1: 2026/02/28 | L1: 2026/03/31 | M1: 2026/04/30 | N1: 2026/05/31 | O1: 2026/06/30 | P1: 2026/07/31 | Q1: 2026/08/31 | R1: 2026/09/30 | S1: 2026/10/31 | T1: 2026/11/30 | U1: 2026/12/31 | V1: 2027/01/31 | W1: 2027/02/28 | X1: 2027/03/31 | Y1: 2027/04/30 | Z1: 2027/05/31 | AA1: 2027/06/30 | AB1: 2027/07/31 | AC1: 2027/08/31 | AD1: 2027/09/30 | AE1: 2027/10/31 | AF1: 2027/11/30 | AG1: 2027/12/31 | AH1: 2028/01/31 | AI1: 2028/02/29 | AJ1: 2028/03/31 | AK1: 2028/04/30 | AL1: 2028/05/31 | AM1: 2028/06/30 | AN1: 2028/07/31 | AO1: 2028/08/31 | AP1: 2028/09/30 | AQ1: 2028/10/31 | AR1: 2028/11/30 | AS1: 2028/12/31 | AT1: 2029/01/31 | AU1: 2029/02/28 | AV1: 2029/03/31 | AW1: 2029/04/30 | AX1: 2029/05/31 | AY1: 2029/06/30 | AZ1: 2029/07/31 | BA1: 2029/08/31 | BB1: 2029/09/30 | BC1: 2029/10/31 | BD1: 2029/11/30 | BE1: 2029/12/31 | BF1: 2030/01/31 | BG1: 2030/02/28 | BH1: 2030/03/31 | BI1: 2030/04/30 | BJ1: 2030/05/31 | BK1: 2030/06/30 | BL1: 2030/07/31
A2: fml_count | B2: 163 | C2: 139 | D2: 137 | E2: 136 | F2: 135 | G2: 135 | H2: 135 | I2: 134 | J2: 133 | K2: 128 | L2: 120 | M2: 119 | N2: 107 | O2: 104 | P2: 103 | Q2: 67 | R2: 65 | S2: 65 | T2: 65 | U2: 65 | V2: 64 | W2: 63 | X2: 58 | Y2: 57 | Z2: 57 | AA2: 46 | AB2: 46 | AC2: 46 | AD2: 46 | AE2: 46 | AF2: 46 | AG2: 46 | AH2: 44 | AI2: 44 | AJ2: 44 | AK2: 44 | AL2: 44 | AM2: 44 | AN2: 43 | AO2: 43 | AP2: 42 | AQ2: 42 | AR2: 42 | AS2: 42 | AT2: 42 | AU2: 42 | AV2: 42 | AW2: 42 | AX2: 41 | AY2: 1 | AZ2: 1 | BA2: 1 | BB2: 0 | BC2: 0 | BD2: 0 | BE2: 0 | BF2: 0 | BG2: 0 | BH2: 0 | BI2: 0 | BJ2: 0 | BK2: 0 | BL2: 0
A3: olmm_count | B3: 0 | C3: 0 | D3: 0 | E3: 0 | F3: 0 | G3: 0 | H3: 0 | I3: 0 | J3: 0 | K3: 0 | L3: 0 | M3: 0 | N3: 0 | O3: 0 | P3: 0 | Q3: 0 | R3: 0 | S3: 0 | T3: 0 | U3: 0 | V3: 0 | W3: 0 | X3: 0 | Y3: 0 | Z3: 0 | AA3: 0 | AB3: 0 | AC3: 0 | AD3: 0 | AE3: 0 | AF3: 0 | AG3: 0 | AH3: 0 | AI3: 0 | AJ3: 0 | AK3: 0 | AL3: 0 | AM3: 0 | AN3: 0 | AO3: 0 | AP3: 0 | AQ3: 0 | AR3: 0 | AS3: 0 | AT3: 0 | AU3: 0 | AV3: 0 | AW3: 0 | AX3: 0 | AY3: 0 | AZ3: 0 | BA3: 0 | BB3: 0 | BC3: 0 | BD3: 0 | BE3: 0 | BF3: 0 | BG3: 0 | BH3: 0 | BI3: 0 | BJ3: 0 | BK3: 0 | BL3: 0
A4: pl_count | B4: 0 | C4: 0 | D4: 0 | E4: 0 | F4: 0 | G4: 0 | H4: 0 | I4: 0 | J4: 0 | K4: 0 | L4: 0 | M4: 0 | N4: 0 | O4: 0 | P4: 0 | Q4: 0 | R4: 0 | S4: 0 | T4: 0 | U4: 0 | V4: 0 | W4: 0 | X4: 0 | Y4: 0 | Z4: 0 | AA4: 0 | AB4: 0 | AC4: 0 | AD4: 0 | AE4: 0 | AF4: 0 | AG4: 0 | AH4: 0 | AI4: 0 | AJ4: 0 | AK4: 0 | AL4: 0 | AM4: 0 | AN4: 0 | AO4: 0 | AP4: 0 | AQ4: 0 | AR4: 0 | AS4: 0 | AT4: 0 | AU4: 0 | AV4: 0 | AW4: 0 | AX4: 0 | AY4: 0 | AZ4: 0 | BA4: 0 | BB4: 0 | BC4: 0 | BD4: 0 | BE4: 0 | BF4: 0 | BG4: 0 | BH4: 0 | BI4: 0 | BJ4: 0 | BK4: 0 | BL4: 0
A5: revenue_p_m | B5: 2648489 | C5: 2464196.9 | D5: 2456677.2 | E5: 2450630.3 | F5: 2439276.6 | G5: 2439276.6 | H5: 2439276.6 | I5: 2428596.8 | J5: 2423689.9 | K5: 2377064.3 | L5: 2310233.7 | M5: 2298084.8 | N5: 2187806.4 | O5: 2136713.9 | P5: 2128616 | Q5: 1770250.2 | R5: 1739046.3 | S5: 1739046.3 | T5: 1739046.3 | U5: 1739046.3 | V5: 1711860.9 | W5: 1700335.2 | X5: 1649701.6 | Y5: 1639720.3 | Z5: 1639720.3 | AA5: 1307002.4 | AB5: 1307002.4 | AC5: 1307002.4 | AD5: 1307002.4 | AE5: 1307002.4 | AF5: 1307002.4 | AG5: 1307002.4 | AH5: 1261301.6 | AI5: 1261301.6 | AJ5: 1261301.6 | AK5: 1261301.6 | AL5: 1261301.6 | AM5: 1261301.6 | AN5: 1242826.4 | AO5: 1242826.4 | AP5: 1222232.9 | AQ5: 1222232.9 | AR5: 1222232.9 | AS5: 1222232.9 | AT5: 1222232.9 | AU5: 1222232.9 | AV5: 1222232.9 | AW5: 1222232.9 | AX5: 1170874.2 | AY5: 53283.12 | AZ5: 53283.12 | BA5: 53283.12 | BB5: 0 | BC5: 0 | BD5: 0 | BE5: 0 | BF5: 0 | BG5: 0 | BH5: 0 | BI5: 0 | BJ5: 0 | BK5: 0 | BL5: 0
A6: depreciation_p_m | B6: 711918.8 | C6: 664816.9 | D6: 664816.9 | E6: 664259.79 | F6: 662888.39 | G6: 662888.39 | H6: 662888.39 | I6: 661902.26 | J6: 661324.82 | K6: 656122.09 | L6: 645828.81 | M6: 643623 | N6: 609016.92 | O6: 595603.6 | P6: 593708.86 | Q6: 527237.59 | R6: 519042.58 | S6: 519042.58 | T6: 519042.58 | U6: 519042.58 | V6: 512261.4 | W6: 508659.36 | X6: 495130.56 | Y6: 492127.29 | Z6: 492127.29 | AA6: 370437.75 | AB6: 370437.75 | AC6: 370437.75 | AD6: 370437.75 | AE6: 370437.75 | AF6: 370437.75 | AG6: 370437.75 | AH6: 358295.09 | AI6: 358295.09 | AJ6: 358295.09 | AK6: 358295.09 | AL6: 358295.09 | AM6: 358295.09 | AN6: 353041.51 | AO6: 353041.51 | AP6: 347492.57 | AQ6: 347492.57 | AR6: 347492.57 | AS6: 347492.57 | AT6: 347492.57 | AU6: 347492.57 | AV6: 347492.57 | AW6: 347492.57 | AX6: 332726.37 | AY6: 17606.19 | AZ6: 17606.19 | BA6: 17606.19 | BB6: 0 | BC6: 0 | BD6: 0 | BE6: 0 | BF6: 0 | BG6: 0 | BH6: 0 | BI6: 0 | BJ6: 0 | BK6: 0 | BL6: 0
A7: interest_p_m | B7: 812546.68 | C7: 795400.15 | D7: 794218.02 | E7: 794491.4 | F7: 792434.67 | G7: 792434.67 | H7: 792434.67 | I7: 791160.36 | J7: 789958.74 | K7: 783205.84 | L7: 763649.5 | M7: 760768.63 | N7: 732240.85 | O7: 711861.73 | P7: 708871.4 | Q7: 612349.69 | R7: 601957.72 | S7: 601957.72 | T7: 601957.72 | U7: 601957.72 | V7: 590185.74 | W7: 587066.81 | X7: 574022.85 | Y7: 571345.17 | Z7: 571345.17 | AA7: 464310.5 | AB7: 464310.5 | AC7: 464310.5 | AD7: 464310.5 | AE7: 464310.5 | AF7: 464310.5 | AG7: 464310.5 | AH7: 449171.74 | AI7: 449171.74 | AJ7: 449171.74 | AK7: 449171.74 | AL7: 449171.74 | AM7: 449171.74 | AN7: 442712.32 | AO7: 442712.32 | AP7: 435084.11 | AQ7: 435084.11 | AR7: 435084.11 | AS7: 435084.11 | AT7: 435084.11 | AU7: 435084.11 | AV7: 435084.11 | AW7: 435084.11 | AX7: 412867.42 | AY7: 23615.34 | AZ7: 23615.34 | BA7: 23615.34 | BB7: 0 | BC7: 0 | BD7: 0 | BE7: 0 | BF7: 0 | BG7: 0 | BH7: 0 | BI7: 0 | BJ7: 0 | BK7: 0 | BL7: 0
A8: admin_p_m | B8: 213363.24 | C8: 184478.92 | D8: 182845.42 | E8: 182133.53 | F8: 181111.15 | G8: 181111.15 | H8: 181111.15 | I8: 179143.96 | J8: 177894.13 | K8: 173074.48 | L8: 164649.03 | M8: 163195.96 | N8: 155134.61 | O8: 151750.05 | P8: 150648.85 | Q8: 108943.49 | R8: 105219.94 | S8: 105219.94 | T8: 105219.94 | U8: 105219.94 | V8: 102986.56 | W8: 101792.73 | X8: 97011.14 | Y8: 95691.57 | Z8: 95691.57 | AA8: 68504.51 | AB8: 68504.51 | AC8: 68504.51 | AD8: 68504.51 | AE8: 68504.51 | AF8: 68504.51 | AG8: 68504.51 | AH8: 64995.61 | AI8: 64995.61 | AJ8: 64995.61 | AK8: 64995.61 | AL8: 64995.61 | AM8: 64995.61 | AN8: 63594.85 | AO8: 63594.85 | AP8: 62533.85 | AQ8: 62533.85 | AR8: 62533.85 | AS8: 62533.85 | AT8: 62533.85 | AU8: 62533.85 | AV8: 62533.85 | AW8: 62533.85 | AX8: 58842.3 | AY8: 3619.07 | AZ8: 3619.07 | BA8: 3619.07 | BB8: 0 | BC8: 0 | BD8: 0 | BE8: 0 | BF8: 0 | BG8: 0 | BH8: 0 | BI8: 0 | BJ8: 0 | BK8: 0 | BL8: 0
A9: maint_prov_p_m | B9: 10083547 | C9: 7754269 | D9: 7622820.6 | E9: 7497335.1 | F9: 7426166.2 | G9: 7426166.2 | H9: 7426166.2 | I9: 7370039 | J9: 7271505.9 | K9: 6598221.2 | L9: 5902196.7 | M9: 5823477.4 | N9: 5191872.5 | O9: 5053904 | P9: 5035454 | Q9: 2648744.9 | R9: 2540937.3 | S9: 2540937.3 | T9: 2540937.3 | U9: 2540937.3 | V9: 2494870.5 | W9: 2437587.7 | X9: 2157796.9 | Y9: 2123868.8 | Z9: 2123868.8 | AA9: 1786208 | AB9: 1786208 | AC9: 1786208 | AD9: 1786208 | AE9: 1786208 | AF9: 1786208 | AG9: 1786208 | AH9: 1625088 | AI9: 1625088 | AJ9: 1625088 | AK9: 1625088 | AL9: 1625088 | AM9: 1625088 | AN9: 1576501.7 | AO9: 1576501.7 | AP9: 1548330.4 | AQ9: 1548330.4 | AR9: 1548330.4 | AS9: 1548330.4 | AT9: 1548330.4 | AU9: 1548330.4 | AV9: 1548330.4 | AW9: 1548330.4 | AX9: 1543434.4 | AY9: 70701.93 | AZ9: 70701.93 | BA9: 70701.93 | BB9: 0 | BC9: 0 | BD9: 0 | BE9: 0 | BF9: 0 | BG9: 0 | BH9: 0 | BI9: 0 | BJ9: 0 | BK9: 0 | BL9: 0
A10: maintenance_fund | B10: 5057825.7 | C10: 3704786.7 | D10: 3666380.7 | E10: 3615064.7 | F10: 3602028.9 | G10: 3602028.9 | H10: 3602028.9 | I10: 3591239.4 | J10: 3515106.5 | K10: 3371320.9 | L10: 3092610 | M10: 3033504.8 | N10: 2817811.8 | O10: 2758063.5 | P10: 2744143.6 | Q10: 1882781.5 | R10: 1855500.5 | S10: 1855500.5 | T10: 1855500.5 | U10: 1855500.5 | V10: 1823861.1 | W10: 1795684.4 | X10: 1762163 | Y10: 1757438.1 | Z10: 1757438.1 | AA10: 1540826.2 | AB10: 1540826.2 | AC10: 1540826.2 | AD10: 1540826.2 | AE10: 1540826.2 | AF10: 1540826.2 | AG10: 1540826.2 | AH10: 1433503.5 | AI10: 1433503.5 | AJ10: 1433503.5 | AK10: 1433503.5 | AL10: 1433503.5 | AM10: 1433503.5 | AN10: 1420212.3 | AO10: 1420212.3 | AP10: 1432083.1 | AQ10: 1432083.1 | AR10: 1432083.1 | AS10: 1432083.1 | AT10: 1432083.1 | AU10: 1432083.1 | AV10: 1432083.1 | AW10: 1432083.1 | AX10: 1427187.1 | AY10: 68281.91 | AZ10: 68281.91 | BA10: 68281.91 | BB10: 0 | BC10: 0 | BD10: 0 | BE10: 0 | BF10: 0 | BG10: 0 | BH10: 0 | BI10: 0 | BJ10: 0 | BK10: 0 | BL10: 0
A11: other_fee_p_m | B11: 489053.1 | C11: 463262.08 | D11: 461939.74 | E11: 461074.36 | F11: 459171.24 | G11: 459171.24 | H11: 459171.24 | I11: 457219.05 | J11: 457091.05 | K11: 452544.59 | L11: 447060.99 | M11: 444451.86 | N11: 426024.95 | O11: 416965.32 | P11: 415075.86 | Q11: 353246.17 | R11: 348247.31 | S11: 348247.31 | T11: 348247.31 | U11: 348247.31 | V11: 343308.95 | W11: 341130.2 | X11: 333531.97 | Y11: 331503.97 | Z11: 331503.97 | AA11: 267287.94 | AB11: 267287.94 | AC11: 267287.94 | AD11: 267287.94 | AE11: 267287.94 | AF11: 267287.94 | AG11: 267287.94 | AH11: 260433.48 | AI11: 260433.48 | AJ11: 260433.48 | AK11: 260433.48 | AL11: 260433.48 | AM11: 260433.48 | AN11: 257096.48 | AO11: 257096.48 | AP11: 253531.51 | AQ11: 253531.51 | AR11: 253531.51 | AS11: 253531.51 | AT11: 253531.51 | AU11: 253531.51 | AV11: 253531.51 | AW11: 253531.51 | AX11: 245295.26 | AY11: 586.75 | AZ11: 586.75 | BA11: 586.75 | BB11: 0 | BC11: 0 | BD11: 0 | BE11: 0 | BF11: 0 | BG11: 0 | BH11: 0 | BI11: 0 | BJ11: 0 | BK11: 0 | BL11: 0
A12: total_cost | B12: 59843147 | C12: 54954461 | D12: 54718417 | E12: 54616039 | F12: 54339324 | G12: 54339324 | H12: 54339324 | I12: 54033255 | J12: 53839760 | K12: 52955106 | L12: 51231636 | M12: 50906898 | N12: 48168954 | O12: 46864941 | P12: 46578883 | Q12: 37525396 | R12: 36797370 | S12: 36797370 | T12: 36797370 | U12: 36797370 | V12: 36142353 | W12: 35855833 | X12: 34732244 | Y12: 34478329 | Z12: 34478329 | AA12: 25214041 | AB12: 25214041 | AC12: 25214041 | AD12: 25214041 | AE12: 25214041 | AF12: 25214041 | AG12: 25214041 | AH12: 24371905 | AI12: 24371905 | AJ12: 24371905 | AK12: 24371905 | AL12: 24371905 | AM12: 24371905 | AN12: 23951675 | AO12: 23951675 | AP12: 23547275 | AQ12: 23547275 | AR12: 23547275 | AS12: 23547275 | AT12: 23547275 | AU12: 23547275 | AV12: 23547275 | AW12: 23547275 | AX12: 22439810 | AY12: 1240825 | AZ12: 1240825 | BA12: 1240825 | BB12: 0 | BC12: 0 | BD12: 0 | BE12: 0 | BF12: 0 | BG12: 0 | BH12: 0 | BI12: 0 | BJ12: 0 | BK12: 0 | BL12: 0
A13: nbv | B13: 36089298 | C13: 35101273 | D13: 34393459 | E13: 33717294 | F13: 32971035 | G13: 32308147 | H13: 31645259 | I13: 30904866 | J13: 30198053 | K13: 29344048 | L13: 28145645 | M13: 27407261 | N13: 26000359 | O13: 24896712 | P13: 24193551 | Q13: 21271759 | R13: 20550334 | S13: 20031291 | T13: 19512249 | U13: 18993206 | V13: 18204963 | W13: 17618701 | X13: 16819882 | Y13: 16256855 | Z13: 15764728 | AA13: 11935273 | AB13: 11564835 | AC13: 11194398 | AD13: 10823960 | AE13: 10453522 | AF13: 10083084 | AG13: 9712646.7 | AH13: 9107205.8 | AI13: 8748910.7 | AJ13: 8390615.6 | AK13: 8032320.6 | AL13: 7674025.5 | AM13: 7315730.4 | AN13: 6852419.6 | AO13: 6499378.1 | AP13: 6058006.7 | AQ13: 5710514.1 | AR13: 5363021.6 | AS13: 5015529 | AT13: 4668036.4 | AU13: 4320543.8 | AV13: 3973051.3 | AW13: 3625558.7 | AX13: 2879378.6 | AY13: 254878.36 | AZ13: 237272.17 | BA13: 219665.98 | BB13: 0 | BC13: 0 | BD13: 0 | BE13: 0 | BF13: 0 | BG13: 0 | BH13: 0 | BI13: 0 | BJ13: 0 | BK13: 0 | BL13: 0
... A16: olmm_fleet_drop | B16: 0 | C16: 0 | D16: 0 | E16: 0 | F16: 0 | G16: 0 | H16: 0 | I16: 0 | J16: 0 | K16: 0 | L16: 0 | M16: 0 | N16: 0 | O16: 0 | P16: 0 | Q16: 0 | R16: 0 | S16: 0 | T16: 0 | U16: 0 | V16: 0 | W16: 0 | X16: 0 | Y16: 0 | Z16: 0 | AA16: 0 | AB16: 0 | AC16: 0 | AD16: 0 | AE16: 0 | AF16: 0 | AG16: 0 | AH16: 0 | AI16: 0 | AJ16: 0 | AK16: 0 | AL16: 0 | AM16: 0 | AN16: 0 | AO16: 0 | AP16: 0 | AQ16: 0 | AR16: 0 | AS16: 0 | AT16: 0 | AU16: 0 | AV16: 0 | AW16: 0 | AX16: 0 | AY16: 0 | AZ16: 0 | BA16: 0 | BB16: 0 | BC16: 0 | BD16: 0 | BE16: 0 | BF16: 0 | BG16: 0 | BH16: 0 | BI16: 0 | BJ16: 0 | BK16: 0 | BL16: 0

Sheet MOZ
A1: Value | B1: 2025/06/06 | C1: 2025/06/30 | D1: 2025/07/31 | E1: 2025/08/31 | F1: 2025/09/30 | G1: 2025/10/31 | H1: 2025/11/30 | I1: 2025/12/31 | J1: 2026/01/31 | K1: 2026/02/28 | L1: 2026/03/31 | M1: 2026/04/30 | N1: 2026/05/31 | O1: 2026/06/30 | P1: 2026/07/31 | Q1: 2026/08/31 | R1: 2026/09/30 | S1: 2026/10/31 | T1: 2026/11/30 | U1: 2026/12/31 | V1: 2027/01/31 | W1: 2027/02/28 | X1: 2027/03/31 | Y1: 2027/04/30 | Z1: 2027/05/31 | AA1: 2027/06/30 | AB1: 2027/07/31 | AC1: 2027/08/31 | AD1: 2027/09/30 | AE1: 2027/10/31 | AF1: 2027/11/30 | AG1: 2027/12/31 | AH1: 2028/01/31 | AI1: 2028/02/29 | AJ1: 2028/03/31 | AK1: 2028/04/30 | AL1: 2028/05/31 | AM1: 2028/06/30 | AN1: 2028/07/31 | AO1: 2028/08/31 | AP1: 2028/09/30 | AQ1: 2028/10/31 | AR1: 2028/11/30 | AS1: 2028/12/31 | AT1: 2029/01/31 | AU1: 2029/02/28 | AV1: 2029/03/31 | AW1: 2029/04/30 | AX1: 2029/05/31 | AY1: 2029/06/30 | AZ1: 2029/07/31 | BA1: 2029/08/31 | BB1: 2029/09/30 | BC1: 2029/10/31 | BD1: 2029/11/30 | BE1: 2029/12/31 | BF1: 2030/01/31 | BG1: 2030/02/28 | BH1: 2030/03/31 | BI1: 2030/04/30 | BJ1: 2030/05/31 | BK1: 2030/06/30 | BL1: 2030/07/31
A2: fml_count | B2: 259 | C2: 224 | D2: 222 | E2: 222 | F2: 222 | G2: 215 | H2: 213 | I2: 212 | J2: 207 | K2: 206 | L2: 199 | M2: 197 | N2: 195 | O2: 193 | P2: 193 | Q2: 184 | R2: 184 | S2: 182 | T2: 181 | U2: 180 | V2: 180 | W2: 179 | X2: 179 | Y2: 170 | Z2: 157 | AA2: 156 | AB2: 129 | AC2: 116 | AD2: 98 | AE2: 98 | AF2: 90 | AG2: 84 | AH2: 82 | AI2: 78 | AJ2: 74 | AK2: 69 | AL2: 69 | AM2: 69 | AN2: 56 | AO2: 45 | AP2: 44 | AQ2: 39 | AR2: 35 | AS2: 34 | AT2: 34 | AU2: 34 | AV2: 32 | AW2: 28 | AX2: 26 | AY2: 15 | AZ2: 8 | BA2: 7 | BB2: 7 | BC2: 5 | BD2: 5 | BE2: 3 | BF2: 1 | BG2: 1 | BH2: 0 | BI2: 0 | BJ2: 0 | BK2: 0 | BL2: 0
A3: olmm_count | B3: 43 | C3: 41 | D3: 41 | E3: 40 | F3: 40 | G3: 40 | H3: 40 | I3: 38 | J3: 38 | K3: 37 | L3: 37 | M3: 36 | N3: 34 | O3: 34 | P3: 32 | Q3: 32 | R3: 22 | S3: 22 | T3: 22 | U3: 22 | V3: 22 | W3: 22 | X3: 22 | Y3: 22 | Z3: 20 | AA3: 20 | AB3: 20 | AC3: 20 | AD3: 20 | AE3: 20 | AF3: 18 | AG3: 14 | AH3: 13 | AI3: 13 | AJ3: 13 | AK3: 13 | AL3: 11 | AM3: 11 | AN3: 5 | AO3: 4 | AP3: 1 | AQ3: 1 | AR3: 1 | AS3: 1 | AT3: 0 | AU3: 0 | AV3: 0 | AW3: 0 | AX3: 0 | AY3: 0 | AZ3: 0 | BA3: 0 | BB3: 0 | BC3: 0 | BD3: 0 | BE3: 0 | BF3: 0 | BG3: 0 | BH3: 0 | BI3: 0 | BJ3: 0 | BK3: 0 | BL3: 0
A4: pl_count | B4: 0 | C4: 0 | D4: 0 | E4: 0 | F4: 0 | G4: 0 | H4: 0 | I4: 0 | J4: 0 | K4: 0 | L4: 0 | M4: 0 | N4: 0 | O4: 0 | P4: 0 | Q4: 0 | R4: 0 | S4: 0 | T4: 0 | U4: 0 | V4: 0 | W4: 0 | X4: 0 | Y4: 0 | Z4: 0 | AA4: 0 | AB4: 0 | AC4: 0 | AD4: 0 | AE4: 0 | AF4: 0 | AG4: 0 | AH4: 0 | AI4: 0 | AJ4: 0 | AK4: 0 | AL4: 0 | AM4: 0 | AN4: 0 | AO4: 0 | AP4: 0 | AQ4: 0 | AR4: 0 | AS4: 0 | AT4: 0 | AU4: 0 | AV4: 0 | AW4: 0 | AX4: 0 | AY4: 0 | AZ4: 0 | BA4: 0 | BB4: 0 | BC4: 0 | BD4: 0 | BE4: 0 | BF4: 0 | BG4: 0 | BH4: 0 | BI4: 0 | BJ4: 0 | BK4: 0 | BL4: 0
A5: revenue_p_m | B5: 22289797 | C5: 20132176 | D5: 20052084 | E5: 19951198 | F5: 19951198 | G5: 19323804 | H5: 19166127 | I5: 18770197 | J5: 18423636 | K5: 18166395 | L5: 17766140 | M5: 17520835 | N5: 17176223 | O5: 16951421 | P5: 16791160 | Q5: 16261947 | R5: 15150787 | S5: 15046075 | T5: 14968235 | U5: 14914010 | V5: 14914010 | W5: 14829864 | X5: 14829864 | Y5: 13975217 | Z5: 12761039 | AA5: 12690690 | AB5: 11404358 | AC5: 10628963 | AD5: 9555243.3 | AE5: 9555243.3 | AF5: 8906812.3 | AG5: 7825525 | AH5: 7709392.8 | AI5: 7427625.9 | AJ5: 6737289.7 | AK5: 6112159.4 | AL5: 5882997.7 | AM5: 5882997.7 | AN5: 4695630.8 | AO5: 3791164.5 | AP5: 3383430.8 | AQ5: 3068001.3 | AR5: 2767201.3 | AS5: 2725926.2 | AT5: 2647625.1 | AU5: 2647625.1 | AV5: 2514054.1 | AW5: 2151124.3 | AX5: 2071482.6 | AY5: 1440832.2 | AZ5: 825180.41 | BA5: 739875 | BB5: 739875 | BC5: 451416.89 | BD5: 451416.89 | BE5: 209410.4 | BF5: 39820.84 | BG5: 39820.84 | BH5: 0 | BI5: 0 | BJ5: 0 | BK5: 0 | BL5: 0
A6: depreciation_p_m | B6: 9376783.9 | C6: 8629957.5 | D6: 8594188.3 | E6: 8544108.2 | F6: 8544108.2 | G6: 8274468.4 | H6: 8220129.2 | I6: 7972901.1 | J6: 7837732.5 | K6: 7698862 | L6: 7548973.7 | M6: 7442444.2 | N6: 7290173 | O6: 7177898.7 | P6: 7104180.7 | Q6: 6870728.2 | R6: 6358228.2 | S6: 6316528.2 | T6: 6287425.5 | U6: 6266623 | V6: 6266623 | W6: 6230498 | X6: 6230498 | Y6: 5843218.7 | Z6: 5352893.9 | AA6: 5327376.3 | AB6: 4833354.9 | AC6: 4543569.3 | AD6: 4164762.1 | AE6: 4164762.1 | AF6: 3899115.4 | AG6: 3397160.9 | AH6: 3355401.9 | AI6: 3220288.7 | AJ6: 2856576.4 | AK6: 2514972.3 | AL6: 2407784.8 | AM6: 2407784.8 | AN6: 1919772.5 | AO6: 1528785.2 | AP6: 1339571.8 | AQ6: 1206295.4 | AR6: 1076999.1 | AS6: 1062895.7 | AT6: 1022244.5 | AU6: 1022244.5 | AV6: 973233.6 | AW6: 826087.81 | AX6: 799533.59 | AY6: 560809.36 | AZ6: 337768.15 | BA6: 307072.61 | BB6: 307072.61 | BC6: 174346.75 | BD6: 174346.75 | BE6: 78367.35 | BF6: 13277.11 | BG6: 13277.11 | BH6: 0 | BI6: 0 | BJ6: 0 | BK6: 0 | BL6: 0
A7: interest_p_m | B7: 7218517.1 | C7: 6699479.2 | D7: 6673716 | E7: 6634355.1 | F7: 6634355.1 | G7: 6422079.9 | H7: 6370103.1 | I7: 6267244.1 | J7: 6137392.8 | K7: 6051329.6 | L7: 5937997 | M7: 5847893.4 | N7: 5743789.1 | O7: 5673354.8 | P7: 5606237.2 | Q7: 5438090.6 | R7: 4971477.4 | S7: 4941442.6 | T7: 4912890.4 | U7: 4893700 | V7: 4893700 | W7: 4860809.4 | X7: 4860809.4 | Y7: 4580291.3 | Z7: 4154116.4 | AA7: 4125699.8 | AB7: 3670256 | AC7: 3422780.2 | AD7: 3062183.8 | AE7: 3062183.8 | AF7: 2834161.2 | AG7: 2490881.1 | AH7: 2449540.3 | AI7: 2374676.6 | AJ7: 2206516 | AK7: 2067415.7 | AL7: 1970427 | AM7: 1970427 | AN7: 1586471 | AO7: 1317800.8 | AP7: 1155074.6 | AQ7: 1065116.4 | AR7: 978425.59 | AS7: 964992.82 | AT7: 936056.45 | AU7: 936056.45 | AV7: 899972 | AW7: 758830.47 | AX7: 733383.95 | AY7: 513647.47 | AZ7: 280155.87 | BA7: 247955.08 | BB7: 247955.08 | BC7: 146432.26 | BD7: 146432.26 | BE7: 63874.26 | BF7: 12723.26 | BG7: 12723.26 | BH7: 0 | BI7: 0 | BJ7: 0 | BK7: 0 | BL7: 0
A8: admin_p_m | B8: 1839367.8 | C8: 1682511.1 | D8: 1675556 | E8: 1666207.7 | F8: 1666207.7 | G8: 1611276.1 | H8: 1599033.5 | I8: 1572533.1 | J8: 1541144.4 | K8: 1518110.2 | L8: 1488054.4 | M8: 1465450.7 | N8: 1444834.1 | O8: 1426523.1 | P8: 1409322.3 | Q8: 1363928.8 | R8: 1244345.5 | S8: 1236237.2 | T8: 1229528.8 | U8: 1224699.7 | V8: 1224699.7 | W8: 1216270.5 | X8: 1216270.5 | Y8: 1144855.5 | Z8: 1035822.4 | AA8: 1028880.8 | AB8: 912059.47 | AC8: 849325.67 | AD8: 759302.85 | AE8: 759302.85 | AF8: 701899.49 | AG8: 620548.3 | AH8: 603081.11 | AI8: 591050.46 | AJ8: 541831.41 | AK8: 492427.11 | AL8: 472418.79 | AM8: 472418.79 | AN8: 381133.95 | AO8: 305762.6 | AP8: 270774.04 | AQ8: 246527.26 | AR8: 223578.19 | AS8: 220689.19 | AT8: 214221.96 | AU8: 214221.96 | AV8: 205560 | AW8: 175276.1 | AX8: 169814.46 | AY8: 122003.87 | AZ8: 69966.7 | BA8: 62805.37 | BB8: 62805.37 | BC8: 36768.93 | BD8: 36768.93 | BE8: 15999.84 | BF8: 2730.82 | BG8: 2730.82 | BH8: 0 | BI8: 0 | BJ8: 0 | BK8: 0 | BL8: 0
A9: maint_prov_p_m | B9: 84693357 | C9: 60039265 | D9: 59457912 | E9: 59457912 | F9: 59457912 | G9: 55165131 | H9: 54202853 | I9: 53917853 | J9: 52316437 | K9: 52108295 | L9: 48769534 | M9: 47939862 | N9: 47056294 | O9: 46364683 | P9: 46364683 | Q9: 42859867 | R9: 42859867 | S9: 41817267 | T9: 41315147 | U9: 41156513 | V9: 41156513 | W9: 40916614 | X9: 40916614 | Y9: 38181393 | Z9: 33310473 | AA9: 33028441 | AB9: 26943019 | AC9: 23483578 | AD9: 18382887 | AE9: 18382887 | AF9: 16736373 | AG9: 15171481 | AH9: 14797247 | AI9: 13636500 | AJ9: 13122603 | AK9: 12529839 | AL9: 12529839 | AM9: 12529839 | AN9: 9398884.3 | AO9: 6605952.8 | AP9: 6357009.1 | AQ9: 5314930.9 | AR9: 4351055.7 | AS9: 4180055.7 | AT9: 4180055.7 | AU9: 4180055.7 | AV9: 3959933.7 | AW9: 3401933.7 | AX9: 3141533.7 | AY9: 1910418.2 | AZ9: 834427.56 | BA9: 700450.06 | BB9: 700450.06 | BC9: 488950 | BD9: 488950 | BE9: 215950 | BF9: 37200 | BG9: 37200 | BH9: 0 | BI9: 0 | BJ9: 0 | BK9: 0 | BL9: 0
A10: maintenance_fund | B10: 50705548 | C10: 34611111 | D10: 34649907 | E10: 34649907 | F10: 34649907 | G10: 32679527 | H10: 32066517 | I10: 31795783 | J10: 31001896 | K10: 30835568 | L10: 29641224 | M10: 29174366 | N10: 28599474 | O10: 28033519 | P10: 28033519 | Q10: 27186880 | R10: 27186880 | S10: 26839794 | T10: 26531028 | U10: 26467831 | V10: 26467831 | W10: 26409783 | X10: 26409783 | Y10: 24863614 | Z10: 22516401 | AA10: 22293117 | AB10: 19697585 | AC10: 17754831 | AD10: 14857474 | AE10: 14857474 | AF10: 13210960 | AG10: 12103104 | AH10: 11860351 | AI10: 10933263 | AJ10: 10506308 | AK10: 10004331 | AL10: 10004331 | AM10: 10004331 | AN10: 7403234.8 | AO10: 5620212.2 | AP10: 5422971.8 | AQ10: 4738960.7 | AR10: 4061848 | AS10: 3964995.7 | AT10: 3964995.7 | AU10: 3964995.7 | AV10: 3748952.6 | AW10: 3254074 | AX10: 3018527 | AY10: 1858772.5 | AZ10: 793581.91 | BA10: 659604.41 | BB10: 659604.41 | BC10: 475307.28 | BD10: 475307.28 | BE10: 215950 | BF10: 37200 | BG10: 37200 | BH10: 0 | BI10: 0 | BJ10: 0 | BK10: 0 | BL10: 0
A11: other_fee_p_m | B11: 506790.24 | C11: 454453.9 | D11: 452702.9 | E11: 450606.6 | F11: 450606.6 | G11: 444554.6 | H11: 442804.6 | I11: 438462 | J11: 430417 | K11: 428320.7 | L11: 422370.7 | M11: 419373.4 | N11: 414865.6 | O11: 413140.1 | P11: 410915.4 | Q11: 403265.4 | R11: 390802.4 | S11: 389102.4 | T11: 387302.4 | U11: 383187.4 | V11: 383187.4 | W11: 382337.4 | X11: 382337.4 | Y11: 368422.4 | Z11: 345564.6 | AA11: 343714.6 | AB11: 300586.1 | AC11: 277955.1 | AD11: 248553.1 | AE11: 248553.1 | AF11: 237828.4 | AG11: 219800 | AH11: 216853.7 | AI11: 212056.6 | AJ11: 205391.6 | AK11: 199141.6 | AL11: 194164.32 | AM11: 194164.32 | AN11: 164456.52 | AO11: 118370.22 | AP11: 108880.22 | AQ11: 91338.6 | AR11: 77668.6 | AS11: 75818.6 | AT11: 73572.3 | AU11: 73572.3 | AV11: 69932.65 | AW11: 62774.05 | AX11: 59194.75 | AY11: 31508.6 | AZ11: 18558.6 | BA11: 16708.6 | BB11: 16708.6 | BC11: 13068.95 | BD11: 13068.95 | BE11: 9368.95 | BF11: 1789.65 | BG11: 1789.65 | BH11: 0 | BI11: 0 | BJ11: 0 | BK11: 0 | BL11: 0
A12: total_cost | B12: 6.4451369e+08 | C12: 5.7621473e+08 | D12: 5.7383011e+08 | E12: 5.7062498e+08 | F12: 5.7062498e+08 | G12: 5.5180497e+08 | H12: 5.4761437e+08 | I12: 5.3852853e+08 | J12: 5.2779408e+08 | K12: 5.1989664e+08 | L12: 5.0961238e+08 | M12: 5.0186939e+08 | N12: 4.9259824e+08 | O12: 4.8632019e+08 | P12: 4.8042275e+08 | Q12: 4.6485925e+08 | R12: 4.2385925e+08 | S12: 4.2107925e+08 | T12: 4.1877925e+08 | U12: 4.1712354e+08 | V12: 4.1712354e+08 | W12: 4.1423354e+08 | X12: 4.1423354e+08 | Y12: 3.8977579e+08 | Z12: 3.5244784e+08 | AA12: 3.5006784e+08 | AB12: 3.1003536e+08 | AC12: 2.8861232e+08 | AD12: 2.5774732e+08 | AE12: 2.5774732e+08 | AF12: 2.3806615e+08 | AG12: 2.1018115e+08 | AH12: 2.0671177e+08 | AI12: 1.9870344e+08 | AJ12: 1.8264644e+08 | AK12: 1.688323e+08 | AL12: 1.619723e+08 | AM12: 1.619723e+08 | AN12: 1.3067461e+08 | AO12: 1.0483298e+08 | AP12: 92836893 | AQ12: 84523699 | AR12: 76655438 | AS12: 75664921 | AT12: 73447582 | AU12: 73447582 | AV12: 70477766 | AW12: 60094708 | AX12: 58222144 | AY12: 41829929 | AZ12: 23988595 | BA12: 21533279 | BB12: 21533279 | BC12: 12606496 | BD12: 12606496 | BE12: 5485662.9 | BF12: 936281.9 | BG12: 936281.9 | BH12: 0 | BI12: 0 | BJ12: 0 | BK12: 0 | BL12: 0
A13: nbv | B13: 3.7309269e+08 | C13: 3.6090936e+08 | D13: 3.5200518e+08 | E13: 3.4255962e+08 | F13: 3.3401552e+08 | G13: 3.2082446e+08 | H13: 3.1125084e+08 | I13: 3.0176937e+08 | J13: 2.8947453e+08 | K13: 2.7998069e+08 | L13: 2.7052411e+08 | M13: 2.6156546e+08 | N13: 2.5178964e+08 | O13: 2.4266767e+08 | P13: 2.3394169e+08 | Q13: 2.2528116e+08 | R13: 2.0764793e+08 | S13: 2.010117e+08 | T13: 1.9411223e+08 | U13: 1.8714682e+08 | V13: 1.8088019e+08 | W13: 1.7389107e+08 | X13: 1.6766057e+08 | Y13: 1.5591868e+08 | Z13: 1.4067055e+08 | AA13: 1.3446871e+08 | AB13: 1.1862492e+08 | AC13: 1.0646612e+08 | AD13: 90314450 | AE13: 86149688 | AF13: 75182596 | AG13: 65656180 | AH13: 61286081 | AI13: 56450053 | AJ13: 51572875 | AK13: 47957572 | AL13: 43620412 | AM13: 41212627 | AN13: 33827076 | AO13: 29247653 | AP13: 24985428 | AQ13: 23281263 | AR13: 21964490 | AS13: 20743172 | AT13: 19414195 | AU13: 18391951 | AV13: 16957988 | AW13: 14430443 | AX13: 13325045 | AY13: 10353954 | AZ13: 5211500.8 | BA13: 4229453.5 | BB13: 3922380.9 | BC13: 2631851.6 | BD13: 2457504.9 | BE13: 921088.63 | BF13: 166209.52 | BG13: 152932.41 | BH13: 0 | BI13: 0 | BJ13: 0 | BK13: 0 | BL13: 0
... A16: olmm_fleet_drop | B16: 0 | C16: 2 | D16: 0 | E16: 1 | F16: 0 | G16: 0 | H16: 0 | I16: 2 | J16: 0 | K16: 1 | L16: 0 | M16: 1 | N16: 2 | O16: 0 | P16: 2 | Q16: 0 | R16: 10 | S16: 0 | T16: 0 | U16: 0 | V16: 0 | W16: 0 | X16: 0 | Y16: 0 | Z16: 2 | AA16: 0 | AB16: 0 | AC16: 0 | AD16: 0 | AE16: 0 | AF16: 2 | AG16: 4 | AH16: 1 | AI16: 0 | AJ16: 0 | AK16: 0 | AL16: 2 | AM16: 0 | AN16: 6 | AO16: 1 | AP16: 3 | AQ16: 0 | AR16: 0 | AS16: 0 | AT16: 1 | AU16: 0 | AV16: 0 | AW16: 0 | AX16: 0 | AY16: 0 | AZ16: 0 | BA16: 0 | BB16: 0 | BC16: 0 | BD16: 0 | BE16: 0 | BF16: 0 | BG16: 0 | BH16: 0 | BI16: 0 | BJ16: 0 | BK16: 0 | BL16: 0

Sheet NAM
A1: Value | B1: 2025/06/06 | C1: 2025/06/30 | D1: 2025/07/31 | E1: 2025/08/31 | F1: 2025/09/30 | G1: 2025/10/31 | H1: 2025/11/30 | I1: 2025/12/31 | J1: 2026/01/31 | K1: 2026/02/28 | L1: 2026/03/31 | M1: 2026/04/30 | N1: 2026/05/31 | O1: 2026/06/30 | P1: 2026/07/31 | Q1: 2026/08/31 | R1: 2026/09/30 | S1: 2026/10/31 | T1: 2026/11/30 | U1: 2026/12/31 | V1: 2027/01/31 | W1: 2027/02/28 | X1: 2027/03/31 | Y1: 2027/04/30 | Z1: 2027/05/31 | AA1: 2027/06/30 | AB1: 2027/07/31 | AC1: 2027/08/31 | AD1: 2027/09/30 | AE1: 2027/10/31 | AF1: 2027/11/30 | AG1: 2027/12/31 | AH1: 2028/01/31 | AI1: 2028/02/29 | AJ1: 2028/03/31 | AK1: 2028/04/30 | AL1: 2028/05/31 | AM1: 2028/06/30 | AN1: 2028/07/31 | AO1: 2028/08/31 | AP1: 2028/09/30 | AQ1: 2028/10/31 | AR1: 2028/11/30 | AS1: 2028/12/31 | AT1: 2029/01/31 | AU1: 2029/02/28 | AV1: 2029/03/31 | AW1: 2029/04/30 | AX1: 2029/05/31 | AY1: 2029/06/30 | AZ1: 2029/07/31 | BA1: 2029/08/31 | BB1: 2029/09/30 | BC1: 2029/10/31 | BD1: 2029/11/30 | BE1: 2029/12/31 | BF1: 2030/01/31 | BG1: 2030/02/28 | BH1: 2030/03/31 | BI1: 2030/04/30 | BJ1: 2030/05/31 | BK1: 2030/06/30 | BL1: 2030/07/31
A2: fml_count | B2: 1042 | C2: 943 | D2: 893 | E2: 875 | F2: 856 | G2: 804 | H2: 783 | I2: 766 | J2: 758 | K2: 731 | L2: 717 | M2: 706 | N2: 697 | O2: 682 | P2: 661 | Q2: 649 | R2: 635 | S2: 627 | T2: 614 | U2: 610 | V2: 595 | W2: 572 | X2: 561 | Y2: 549 | Z2: 536 | AA2: 527 | AB2: 504 | AC2: 489 | AD2: 473 | AE2: 459 | AF2: 421 | AG2: 401 | AH2: 393 | AI2: 369 | AJ2: 348 | AK2: 328 | AL2: 314 | AM2: 309 | AN2: 300 | AO2: 282 | AP2: 265 | AQ2: 240 | AR2: 222 | AS2: 205 | AT2: 192 | AU2: 170 | AV2: 165 | AW2: 151 | AX2: 138 | AY2: 131 | AZ2: 125 | BA2: 113 | BB2: 102 | BC2: 96 | BD2: 81 | BE2: 61 | BF2: 59 | BG2: 53 | BH2: 39 | BI2: 30 | BJ2: 17 | BK2: 7 | BL2: 3
A3: olmm_count | B3: 270 | C3: 262 | D3: 261 | E3: 259 | F3: 259 | G3: 253 | H3: 250 | I3: 248 | J3: 247 | K3: 237 | L3: 232 | M3: 228 | N3: 226 | O3: 216 | P3: 213 | Q3: 208 | R3: 200 | S3: 199 | T3: 198 | U3: 194 | V3: 191 | W3: 188 | X3: 185 | Y3: 180 | Z3: 165 | AA3: 163 | AB3: 155 | AC3: 151 | AD3: 146 | AE3: 140 | AF3: 136 | AG3: 133 | AH3: 129 | AI3: 123 | AJ3: 113 | AK3: 107 | AL3: 104 | AM3: 100 | AN3: 96 | AO3: 92 | AP3: 88 | AQ3: 85 | AR3: 82 | AS3: 79 | AT3: 74 | AU3: 67 | AV3: 60 | AW3: 53 | AX3: 50 | AY3: 45 | AZ3: 40 | BA3: 38 | BB3: 30 | BC3: 27 | BD3: 18 | BE3: 10 | BF3: 6 | BG3: 5 | BH3: 2 | BI3: 1 | BJ3: 0 | BK3: 0 | BL3: 0
A4: pl_count | B4: 0 | C4: 0 | D4: 0 | E4: 0 | F4: 0 | G4: 0 | H4: 0 | I4: 0 | J4: 0 | K4: 0 | L4: 0 | M4: 0 | N4: 0 | O4: 0 | P4: 0 | Q4: 0 | R4: 0 | S4: 0 | T4: 0 | U4: 0 | V4: 0 | W4: 0 | X4: 0 | Y4: 0 | Z4: 0 | AA4: 0 | AB4: 0 | AC4: 0 | AD4: 0 | AE4: 0 | AF4: 0 | AG4: 0 | AH4: 0 | AI4: 0 | AJ4: 0 | AK4: 0 | AL4: 0 | AM4: 0 | AN4: 0 | AO4: 0 | AP4: 0 | AQ4: 0 | AR4: 0 | AS4: 0 | AT4: 0 | AU4: 0 | AV4: 0 | AW4: 0 | AX4: 0 | AY4: 0 | AZ4: 0 | BA4: 0 | BB4: 0 | BC4: 0 | BD4: 0 | BE4: 0 | BF4: 0 | BG4: 0 | BH4: 0 | BI4: 0 | BJ4: 0 | BK4: 0 | BL4: 0
A5: revenue_p_m | B5: 16127040 | C5: 15239223 | D5: 14717657 | E5: 14505775 | F5: 14321213 | G5: 13772766 | H5: 13517174 | I5: 13310992 | J5: 13167462 | K5: 12789063 | L5: 12598405 | M5: 12434826 | N5: 12325540 | O5: 11973744 | P5: 11768593 | Q5: 11589088 | R5: 11321743 | S5: 11177794 | T5: 11007944 | U5: 10914272 | V5: 10739297 | W5: 10474954 | X5: 10274019 | Y5: 10045501 | Z5: 9721704.3 | AA5: 9556281.3 | AB5: 9163771.4 | AC5: 8963679.5 | AD5: 8721353.2 | AE5: 8212815.9 | AF5: 7669016.6 | AG5: 7377795.7 | AH5: 7203636.6 | AI5: 6823360.5 | AJ5: 6393571.9 | AK5: 6026372.3 | AL5: 5766606.2 | AM5: 5666464.2 | AN5: 5520302.2 | AO5: 5208808.3 | AP5: 4863541.7 | AQ5: 4606219.7 | AR5: 4240707.8 | AS5: 3978452.2 | AT5: 3767338.7 | AU5: 3430065.6 | AV5: 3235107.9 | AW5: 2951011.1 | AX5: 2685508.5 | AY5: 2509123.3 | AZ5: 2384012.5 | BA5: 2223967.5 | BB5: 1776292.7 | BC5: 1643750.9 | BD5: 1217863.2 | BE5: 722253.11 | BF5: 656067.21 | BG5: 581968.53 | BH5: 405249.73 | BI5: 296662.07 | BJ5: 142642.7 | BK5: 63033.12 | BL5: 30708.41
A6: depreciation_p_m | B6: 8195520.9 | C6: 7809633.6 | D6: 7678876.3 | E6: 7567981.3 | F6: 7500487.5 | G6: 7268934.2 | H6: 7157705 | I6: 7059796.8 | J6: 6977621.9 | K6: 6782284.6 | L6: 6684578.8 | M6: 6597332.9 | N6: 6542129.5 | O6: 6325833.4 | P6: 6225785.6 | Q6: 6124803 | R6: 5976249.3 | S6: 5895284.6 | T6: 5803407.9 | U6: 5749418.3 | V6: 5661647.4 | W6: 5529025.8 | X6: 5416649.4 | Y6: 5287246.8 | Z6: 5106663.7 | AA6: 5012811.8 | AB6: 4802839.8 | AC6: 4695024.4 | AD6: 4564331.8 | AE6: 4232130.2 | AF6: 3964503.7 | AG6: 3814301.2 | AH6: 3713161.5 | AI6: 3505757.6 | AJ6: 3263870.9 | AK6: 3078966.8 | AL6: 2939999.4 | AM6: 2886283.7 | AN6: 2808502.7 | AO6: 2652921.1 | AP6: 2486868.8 | AQ6: 2362707.5 | AR6: 2193954.2 | AS6: 2062117.5 | AT6: 1952104.9 | AU6: 1773782.9 | AV6: 1658545.9 | AW6: 1507991.7 | AX6: 1377747.2 | AY6: 1289722 | AZ6: 1223615.5 | BA6: 1146728.9 | BB6: 885935.39 | BC6: 812479.94 | BD6: 591673.96 | BE6: 335097.08 | BF6: 300000.25 | BG6: 264957.93 | BH6: 181711.64 | BI6: 133689.06 | BJ6: 64456.26 | BK6: 27819.93 | BL6: 13602.56
A7: interest_p_m | B7: 3772599.2 | C7: 3565955.2 | D7: 3503221.7 | E7: 3451076.6 | F7: 3415099.8 | G7: 3300988.3 | H7: 3251919.6 | I7: 3208429.9 | J7: 3182781.8 | K7: 3089200.4 | L7: 3044340.1 | M7: 3002445.4 | N7: 2973020.8 | O7: 2901752 | P7: 2853375.3 | Q7: 2812042 | R7: 2750989.6 | S7: 2720941.5 | T7: 2682634.8 | U7: 2660009.1 | V7: 2617445.4 | W7: 2551409.7 | X7: 2507112.9 | Y7: 2452955.8 | Z7: 2388748.2 | AA7: 2354822.3 | AB7: 2259085.5 | AC7: 2212557.9 | AD7: 2158100.5 | AE7: 2061751.3 | AF7: 1930253.3 | AG7: 1855527.6 | AH7: 1816500.6 | AI7: 1725210.1 | AJ7: 1631133.7 | AK7: 1545279 | AL7: 1483413.9 | AM7: 1458685.6 | AN7: 1418154.7 | AO7: 1337446.3 | AP7: 1252823.6 | AQ7: 1184858.2 | AR7: 1081239.3 | AS7: 1012982.6 | AT7: 959096.04 | AU7: 870621.28 | AV7: 825067.56 | AW7: 748719.1 | AX7: 680895.09 | AY7: 636152.4 | AZ7: 603646.6 | BA7: 560856.41 | BB7: 456870.27 | BC7: 424715 | BD7: 318353.08 | BE7: 196450.7 | BF7: 179344.65 | BG7: 160017.23 | BH7: 117030.32 | BI7: 87664.5 | BJ7: 45230.45 | BK7: 21043.04 | BL7: 10483.77
A8: admin_p_m | B8: 1399193.8 | C8: 1312101.3 | D8: 1254974.2 | E8: 1237628.9 | F8: 1218909.1 | G8: 1158306 | H8: 1130609 | I8: 1107600.1 | J8: 1093005.2 | K8: 1058425.5 | L8: 1039380.5 | M8: 1025347.2 | N8: 1015800.3 | O8: 987635.18 | P8: 974223.26 | Q8: 958260.43 | R8: 935641.98 | S8: 924231.91 | T8: 911420.72 | U8: 903256.55 | V8: 889932.36 | W8: 867721.99 | X8: 852507.42 | Y8: 832993.63 | Z8: 806632.46 | AA8: 794438.65 | AB8: 762805.62 | AC8: 746814.82 | AD8: 726644.21 | AE8: 685200.27 | AF8: 641846 | AG8: 622734.36 | AH8: 608777.43 | AI8: 577171.65 | AJ8: 541355.75 | AK8: 510100.77 | AL8: 487521.11 | AM8: 477148.83 | AN8: 461051.02 | AO8: 433006.42 | AP8: 404718.81 | AQ8: 383802.46 | AR8: 356870.39 | AS8: 335189.51 | AT8: 316660.28 | AU8: 289245.08 | AV8: 267962 | AW8: 242353.63 | AX8: 220958.49 | AY8: 207668.93 | AZ8: 195176.63 | BA8: 183259.4 | BB8: 136503.33 | BC8: 125377.66 | BD8: 91386.3 | BE8: 53335.32 | BF8: 46394.53 | BG8: 40874.35 | BH8: 25227.17 | BI8: 16981.26 | BJ8: 6260 | BK8: 2555 | BL8: 1115
A9: maint_prov_p_m | B9: 47943650 | C9: 40485229 | D9: 35835238 | E9: 34590985 | F9: 32985793 | G9: 29256656 | H9: 27529092 | I9: 26550465 | J9: 25865058 | K9: 24095760 | L9: 23131235 | M9: 22595738 | N9: 22141198 | O9: 21281047 | P9: 20378141 | Q9: 19965092 | R9: 19362034 | S9: 18847277 | T9: 18332483 | U9: 18187441 | V9: 17618586 | W9: 16709954 | X9: 16278808 | Y9: 15757795 | Z9: 14974229 | AA9: 14690258 | AB9: 13712699 | AC9: 13305542 | AD9: 12804556 | AE9: 12300114 | AF9: 10853166 | AG9: 10022445 | AH9: 9820580.3 | AI9: 9134427.4 | AJ9: 8663301.8 | AK9: 8221355.5 | AL9: 7939579.5 | AM9: 7748511.4 | AN9: 7619724.9 | AO9: 7092117.1 | AP9: 6053301.7 | AQ9: 5576968.7 | AR9: 4671827.3 | AS9: 4192461.5 | AT9: 3826825.8 | AU9: 3297302.2 | AV9: 3160938.5 | AW9: 2882528.9 | AX9: 2539293.3 | AY9: 2467156.5 | AZ9: 2375091.2 | BA9: 2064755.5 | BB9: 1780105.8 | BC9: 1585520 | BD9: 1086776.9 | BE9: 612172.29 | BF9: 572219.26 | BG9: 473879.22 | BH9: 328366.26 | BI9: 250512.08 | BJ9: 166540 | BK9: 78827.17 | BL9: 35022.12
A10: maintenance_fund | B10: 25735541 | C10: 23606401 | D10: 22000094 | E10: 21803585 | F10: 21163977 | G10: 18858428 | H10: 18125853 | I10: 17476221 | J10: 16985727 | K10: 16049170 | L10: 15334028 | M10: 15193981 | N10: 14921197 | O10: 14375300 | P10: 13837438 | Q10: 13582798 | R10: 13247261 | S10: 12903937 | T10: 12671558 | U10: 12570998 | V10: 12122603 | W10: 11552049 | X10: 11255932 | Y10: 10860594 | Z10: 10371295 | AA10: 10173596 | AB10: 9650211.7 | AC10: 9449495.4 | AD10: 9082915.3 | AE10: 8723693.8 | AF10: 8451256.2 | AG10: 7804249.4 | AH10: 7640191.4 | AI10: 7173240.6 | AJ10: 6840379.2 | AK10: 6482773.3 | AL10: 6207513.7 | AM10: 6041273.6 | AN10: 5935267.1 | AO10: 5485055.8 | AP10: 4957042.5 | AQ10: 4576178.5 | AR10: 4093187.6 | AS10: 3686525.7 | AT10: 3402830.2 | AU10: 2969126.6 | AV10: 2837392.6 | AW10: 2609733.5 | AX10: 2308698 | AY10: 2236636.2 | AZ10: 2147725.8 | BA10: 1845529 | BB10: 1596100.3 | BC10: 1436018.3 | BD10: 987599.61 | BE10: 570377.95 | BF10: 530424.92 | BG10: 442968.35 | BH10: 297455.39 | BI10: 221169.18 | BJ10: 139291.76 | BK10: 53761.1 | BL10: 10853.45
A11: other_fee_p_m | B11: 717563.38 | C11: 667958.14 | D11: 644918.91 | E11: 636473.91 | F11: 627429.91 | G11: 593914.86 | H11: 577662.48 | I11: 570756.4 | J11: 567916.4 | K11: 553391.38 | L11: 545121.38 | M11: 538766.38 | N11: 533466.38 | O11: 523014.38 | P11: 512031.08 | Q11: 505545.17 | R11: 490135.17 | S11: 486685.17 | T11: 477148.27 | U11: 474030.91 | V11: 465885.91 | W11: 452389.94 | X11: 440959.94 | Y11: 431796.94 | Z11: 410407.94 | AA11: 405957.94 | AB11: 393615.63 | AC11: 383565.63 | AD11: 374005.63 | AE11: 359195.63 | AF11: 335275.63 | AG11: 323075.63 | AH11: 317381.63 | AI11: 302379.63 | AJ11: 289612.63 | AK11: 276092.63 | AL11: 268222.63 | AM11: 264402.63 | AN11: 259456.58 | AO11: 247318.58 | AP11: 228058.58 | AQ11: 212858.56 | AR11: 195203.68 | AS11: 180210.09 | AT11: 169893.45 | AU11: 155768.45 | AV11: 148496.45 | AW11: 139540.87 | AX11: 126513.87 | AY11: 104368.87 | AZ11: 99449.87 | BA11: 90213.87 | BB11: 77341.87 | BC11: 73544.38 | BD11: 55854.04 | BE11: 37004.04 | BF11: 34945 | BG11: 32020 | BH11: 23895 | BI11: 17400 | BJ11: 10025 | BK11: 4025 | BL11: 1725
A12: total_cost | B12: 6.3843719e+08 | C12: 6.0106623e+08 | D12: 5.8626665e+08 | E12: 5.7789935e+08 | F12: 5.7089583e+08 | G12: 5.4819186e+08 | H12: 5.3828152e+08 | I12: 5.3020977e+08 | J12: 5.2509984e+08 | K12: 5.0922165e+08 | L12: 5.0139748e+08 | M12: 4.9485184e+08 | N12: 4.8985131e+08 | O12: 4.7743178e+08 | P12: 4.6957935e+08 | Q12: 4.6257721e+08 | R12: 4.5268963e+08 | S12: 4.4762578e+08 | T12: 4.4139053e+08 | U12: 4.3765176e+08 | V12: 4.3106037e+08 | W12: 4.207063e+08 | X12: 4.1313086e+08 | Y12: 4.0433569e+08 | Z12: 3.9363256e+08 | AA12: 3.8814605e+08 | AB12: 3.7308774e+08 | AC12: 3.6538758e+08 | AD12: 3.5670143e+08 | AE12: 3.3999473e+08 | AF12: 3.1940706e+08 | AG12: 3.0740511e+08 | AH12: 3.0106043e+08 | AI12: 2.8669481e+08 | AJ12: 2.7127928e+08 | AK12: 2.5775225e+08 | AL12: 2.4801064e+08 | AM12: 2.4379578e+08 | AN12: 2.3720761e+08 | AO12: 2.2429551e+08 | AP12: 2.1016393e+08 | AQ12: 1.9922831e+08 | AR12: 1.8345679e+08 | AS12: 1.7196593e+08 | AT12: 1.6277834e+08 | AU12: 1.4804003e+08 | AV12: 1.4002522e+08 | AW12: 1.2775066e+08 | AX12: 1.1645484e+08 | AY12: 1.0898533e+08 | AZ12: 1.0337811e+08 | BA12: 96044913 | BB12: 77623904 | BC12: 71787981 | BD12: 53438433 | BE12: 32510680 | BF12: 29512066 | BG12: 26334619 | BH12: 19215410 | BI12: 14571383 | BJ12: 7614517.7 | BK12: 3475512 | BL12: 1724233.1
