Workbook

Sheet BOT
A1: Value | B1: 2025/11/17 | C1: 2025/11/30 | D1: 2025/12/31 | E1: 2026/01/31 | F1: 2026/02/28 | G1: 2026/03/31 | H1: 2026/04/30 | I1: 2026/05/31 | J1: 2026/06/30 | K1: 2026/07/31 | L1: 2026/08/31 | M1: 2026/09/30 | N1: 2026/10/31 | O1: 2026/11/30 | P1: 2026/12/31 | Q1: 2027/01/31 | R1: 2027/02/28 | S1: 2027/03/31 | T1: 2027/04/30 | U1: 2027/05/31 | V1: 2027/06/30 | W1: 2027/07/31 | X1: 2027/08/31 | Y1: 2027/09/30 | Z1: 2027/10/31 | AA1: 2027/11/30 | AB1: 2027/12/31 | AC1: 2028/01/31 | AD1: 2028/02/29 | AE1: 2028/03/31 | AF1: 2028/04/30 | AG1: 2028/05/31 | AH1: 2028/06/30 | AI1: 2028/07/31 | AJ1: 2028/08/31 | AK1: 2028/09/30 | AL1: 2028/10/31 | AM1: 2028/11/30 | AN1: 2028/12/31 | AO1: 2029/01/31 | AP1: 2029/02/28 | AQ1: 2029/03/31 | AR1: 2029/04/30 | AS1: 2029/05/31 | AT1: 2029/06/30 | AU1: 2029/07/31 | AV1: 2029/08/31 | AW1: 2029/09/30 | AX1: 2029/10/31 | AY1: 2029/11/30 | AZ1: 2029/12/31 | BA1: 2030/01/31 | BB1: 2030/02/28 | BC1: 2030/03/31 | BD1: 2030/04/30 | BE1: 2030/05/31 | BF1: 2030/06/30 | BG1: 2030/07/31 | BH1: 2030/08/31 | BI1: 2030/09/30 | BJ1: 2030/10/31 | BK1: 2030/11/30 | BL1: 2030/12/31
A2: fml_count | B2: 455 | C2: 367 | D2: 361 | E2: 360 | F2: 357 | G2: 336 | H2: 323 | I2: 293 | J2: 277 | K2: 268 | L2: 258 | M2: 240 | N2: 234 | O2: 223 | P2: 215 | Q2: 208 | R2: 203 | S2: 194 | T2: 190 | U2: 184 | V2: 182 | W2: 177 | X2: 166 | Y2: 162 | Z2: 150 | AA2: 148 | AB2: 147 | AC2: 146 | AD2: 142 | AE2: 135 | AF2: 108 | AG2: 89 | AH2: 86 | AI2: 80 | AJ2: 76 | AK2: 68 | AL2: 61 | AM2: 53 | AN2: 53 | AO2: 50 | AP2: 46 | AQ2: 43 | AR2: 42 | AS2: 39 | AT2: 37 | AU2: 29 | AV2: 28 | AW2: 23 | AX2: 21 | AY2: 16 | AZ2: 14 | BA2: 13 | BB2: 11 | BC2: 11 | BD2: 7 | BE2: 3 | BF2: 2 | BG2: 2 | BH2: 0 | BI2: 0 | BJ2: 0 | BK2: 0 | BL2: 0
A3: olmm_count | B3: 25 | C3: 21 | D3: 20 | E3: 20 | F3: 20 | G3: 19 | H3: 18 | I3: 18 | J3: 18 | K3: 18 | L3: 18 | M3: 17 | N3: 17 | O3: 17 | P3: 17 | Q3: 17 | R3: 16 | S3: 15 | T3: 14 | U3: 13 | V3: 12 | W3: 12 | X3: 10 | Y3: 10 | Z3: 10 | AA3: 10 | AB3: 9 | AC3: 9 | AD3: 9 | AE3: 8 | AF3: 8 | AG3: 8 | AH3: 8 | AI3: 7 | AJ3: 6 | AK3: 6 | AL3: 6 | AM3: 6 | AN3: 6 | AO3: 6 | AP3: 6 | AQ3: 6 | AR3: 6 | AS3: 6 | AT3: 6 | AU3: 6 | AV3: 6 | AW3: 5 | AX3: 5 | AY3: 5 | AZ3: 5 | BA3: 5 | BB3: 5 | BC3: 5 | BD3: 5 | BE3: 5 | BF3: 5 | BG3: 4 | BH3: 4 | BI3: 1 | BJ3: 1 | BK3: 1 | BL3: 1
A4: pl_count | B4: 0 | C4: 0 | D4: 0 | E4: 0 | F4: 0 | G4: 0 | H4: 0 | I4: 0 | J4: 0 | K4: 0 | L4: 0 | M4: 0 | N4: 0 | O4: 0 | P4: 0 | Q4: 0 | R4: 0 | S4: 0 | T4: 0 | U4: 0 | V4: 0 | W4: 0 | X4: 0 | Y4: 0 | Z4: 0 | AA4: 0 | AB4: 0 | AC4: 0 | AD4: 0 | AE4: 0 | AF4: 0 | AG4: 0 | AH4: 0 | AI4: 0 | AJ4: 0 | AK4: 0 | AL4: 0 | AM4: 0 | AN4: 0 | AO4: 0 | AP4: 0 | AQ4: 0 | AR4: 0 | AS4: 0 | AT4: 0 | AU4: 0 | AV4: 0 | AW4: 0 | AX4: 0 | AY4: 0 | AZ4: 0 | BA4: 0 | BB4: 0 | BC4: 0 | BD4: 0 | BE4: 0 | BF4: 0 | BG4: 0 | BH4: 0 | BI4: 0 | BJ4: 0 | BK4: 0 | BL4: 0
A5: revenue_p_m | B5: 5081053.4 | C5: 4259103.1 | D5: 4215213.9 | E5: 4201713.7 | F5: 4163586 | G5: 4012113.7 | H5: 3884762.8 | I5: 3615460.8 | J5: 3440605 | K5: 3347418.7 | L5: 3250530.3 | M5: 3029093.2 | N5: 2921123.3 | O5: 2783749.3 | P5: 2679016.6 | Q5: 2589491.8 | R5: 2502689.1 | S5: 2402952.8 | T5: 2343937.8 | U5: 2251476 | V5: 2217258.3 | W5: 2099640.8 | X5: 1999478.7 | Y5: 1906524.7 | Z5: 1744996.8 | AA5: 1726710 | AB5: 1705233.4 | AC5: 1672656.5 | AD5: 1621986.3 | AE5: 1533685.4 | AF5: 1359397.8 | AG5: 1144108.4 | AH5: 1121500.8 | AI5: 1047594 | AJ5: 963186.9 | AK5: 876411.53 | AL5: 770158.16 | AM5: 686904.21 | AN5: 686904.21 | AO5: 625687.02 | AP5: 586084.54 | AQ5: 535785.79 | AR5: 523697.24 | AS5: 498067.55 | AT5: 478026.26 | AU5: 382320.6 | AV5: 369861.19 | AW5: 284181.19 | AX5: 261172.78 | AY5: 201693.16 | AZ5: 182956.89 | BA5: 176550.81 | BB5: 156874.08 | BC5: 156874.08 | BD5: 100112.61 | BE5: 49390.65 | BF5: 43907.04 | BG5: 31287.92 | BH5: 19619.79 | BI5: 10503.15 | BJ5: 10503.15 | BK5: 10503.15 | BL5: 10503.15
A6: depreciation_p_m | B6: 2704957.9 | C6: 2263032.2 | D6: 2241103.3 | E6: 2236227.1 | F6: 2221835.2 | G6: 2136646.7 | H6: 2062584.1 | I6: 1916210.9 | J6: 1832675.7 | K6: 1783498.2 | L6: 1733536.6 | M6: 1615629 | N6: 1547048 | O6: 1470202.3 | P6: 1412206.2 | Q6: 1362511.9 | R6: 1314408 | S6: 1268642.7 | T6: 1244772.8 | U6: 1192984.9 | V6: 1172053.4 | W6: 1096276.6 | X6: 1045111.1 | Y6: 989256.22 | Z6: 901352.72 | AA6: 890433.03 | AB6: 878216.27 | AC6: 857611.09 | AD6: 828357.02 | AE6: 778039.68 | AF6: 690893.47 | AG6: 578882.87 | AH6: 568221.35 | AI6: 527652.4 | AJ6: 496873.66 | AK6: 451456.19 | AL6: 402067.54 | AM6: 362324.8 | AN6: 362324.8 | AO6: 328738.14 | AP6: 307304.06 | AQ6: 289051.68 | AR6: 282317.77 | AS6: 270157.78 | AT6: 258923.05 | AU6: 205998.01 | AV6: 199712.05 | AW6: 155344.06 | AX6: 143126.42 | AY6: 110991.3 | AZ6: 100519.45 | BA6: 96992.55 | BB6: 85497.51 | BC6: 85497.51 | BD6: 51528.76 | BE6: 26495.25 | BF6: 23840.28 | BG6: 16079.75 | BH6: 11836.53 | BI6: 5534.64 | BJ6: 5534.64 | BK6: 5534.64 | BL6: 5534.64
A7: interest_p_m | B7: 802604.78 | C7: 696309.83 | D7: 689179.69 | E7: 688931.9 | F7: 685952.7 | G7: 671246.26 | H7: 649724.25 | I7: 598057.12 | J7: 565759.68 | K7: 552064.44 | L7: 533286.16 | M7: 492336.41 | N7: 480321.86 | O7: 459917.68 | P7: 444407.19 | Q7: 429647.67 | R7: 418621.18 | S7: 405561.62 | T7: 400294.79 | U7: 384194.73 | V7: 379116.85 | W7: 362999.9 | X7: 344304.4 | Y7: 332893.74 | Z7: 304752.6 | AA7: 301432.86 | AB7: 296778.97 | AC7: 291326.41 | AD7: 281558.9 | AE7: 263621.09 | AF7: 233339.2 | AG7: 194645.43 | AH7: 190255.64 | AI7: 177490.37 | AJ7: 167030.66 | AK7: 153788.87 | AL7: 137889.56 | AM7: 122518.46 | AN7: 122518.46 | AO7: 113494.62 | AP7: 105947.28 | AQ7: 98680.53 | AR7: 95850.58 | AS7: 91819.71 | AT7: 87563.37 | AU7: 73390.06 | AV7: 70842.46 | AW7: 55630.7 | AX7: 49816.35 | AY7: 39772.01 | AZ7: 36315.24 | BA7: 35152.43 | BB7: 31438.7 | BC7: 31438.7 | BD7: 20415.04 | BE7: 11131.83 | BF7: 10209.01 | BG7: 7401.02 | BH7: 4344.87 | BI7: 2841.42 | BJ7: 2841.42 | BK7: 2841.42 | BL7: 2841.42
A8: admin_p_m | B8: 489997.36 | C8: 431525.42 | D8: 426758.97 | E8: 425687.86 | F8: 423369.59 | G8: 415521.48 | H8: 405527.27 | I8: 375865.38 | J8: 355192.08 | K8: 348406.48 | L8: 338345.75 | M8: 313490.72 | N8: 304532.16 | O8: 293559.67 | P8: 287025.78 | Q8: 278053.11 | R8: 271281.25 | S8: 259393.74 | T8: 251844.55 | U8: 241961.76 | V8: 238799.2 | W8: 230312.85 | X8: 220828.39 | Y8: 214591.51 | Z8: 200231.91 | AA8: 198421.07 | AB8: 195645.68 | AC8: 190122.04 | AD8: 184816.77 | AE8: 174495.21 | AF8: 156077.27 | AG8: 132348.94 | AH8: 129886.81 | AI8: 122281.94 | AJ8: 115397.14 | AK8: 106549.94 | AL8: 94529.18 | AM8: 85341.2 | AN8: 85341.2 | AO8: 79559.89 | AP8: 75501.4 | AQ8: 70851.96 | AR8: 69408.98 | AS8: 66956.94 | AT8: 64468.16 | AU8: 50919.39 | AV8: 49606.17 | AW8: 36166.25 | AX8: 33251.41 | AY8: 26615.18 | AZ8: 24698.47 | BA8: 24052.97 | BB8: 21976.77 | BC8: 21976.77 | BD8: 15854.01 | BE8: 9102.14 | BF8: 8040.16 | BG8: 6049.56 | BH8: 3198.39 | BI8: 2067.09 | BJ8: 2067.09 | BK8: 2067.09 | BL8: 2067.09
A9: maint_prov_p_m | B9: 23793608 | C9: 13694590 | D9: 13411201 | E9: 13307409 | F9: 13022969 | G9: 12093983 | H9: 11396089 | I9: 10506372 | J9: 9657186.3 | K9: 9108787.8 | L9: 8748463.2 | M9: 8103467 | N9: 7768700.7 | O9: 7252087.7 | P9: 6910355.1 | Q9: 6601900.9 | R9: 6334706.2 | S9: 5731543.8 | T9: 5359900.7 | U9: 5061280 | V9: 4891609.6 | W9: 4718584 | X9: 4245833.9 | Y9: 4090488.5 | Z9: 3732560.7 | AA9: 3689503.8 | AB9: 3648450.1 | AC9: 3643772.5 | AD9: 3490718 | AE9: 3374598 | AF9: 3099699.9 | AG9: 2469819.1 | AH9: 2355964.9 | AI9: 2157147.3 | AJ9: 1816139.8 | AK9: 1603586.4 | AL9: 1339627.1 | AM9: 1048719.6 | AN9: 1048719.6 | AO9: 873919.51 | AP9: 719562.65 | AQ9: 567511.54 | AR9: 547077.34 | AS9: 479044.31 | AT9: 450442.69 | AU9: 357859.96 | AV9: 321817.88 | AW9: 271512.09 | AX9: 246500.15 | AY9: 147772.19 | AZ9: 118390.91 | BA9: 111507.21 | BB9: 96052.99 | BC9: 96052.99 | BD9: 61425.67 | BE9: 8111.97 | BF9: 4192.77 | BG9: 4192.77 | BH9: 0 | BI9: 0 | BJ9: 0 | BK9: 0 | BL9: 0
A10: maintenance_fund | B10: 12792296 | C10: 8527201.5 | D10: 8339842.6 | E10: 8287906.2 | F10: 8290527.1 | G10: 8071824.8 | H10: 7916841.3 | I10: 7560305.3 | J10: 6977642.2 | K10: 6791445 | L10: 6638330.7 | M10: 6206277 | N10: 5917667.4 | O10: 5559477.5 | P10: 5294400.1 | Q10: 5072172.4 | R10: 4919233.5 | S10: 4543706.3 | T10: 4265201 | U10: 4049833.9 | V10: 3903250 | W10: 3737477.7 | X10: 3342452.2 | Y10: 3210868.4 | Z10: 3035698.1 | AA10: 2992641.2 | AB10: 2961078.3 | AC10: 2956400.7 | AD10: 2834266.4 | AE10: 2730930.4 | AF10: 2466745.8 | AG10: 2073474.4 | AH10: 1967344.5 | AI10: 1784375.9 | AJ10: 1516336.2 | AK10: 1322066.6 | AL10: 1083338.7 | AM10: 819419.21 | AN10: 819419.21 | AO10: 731835.08 | AP10: 620691.3 | AQ10: 546082.9 | AR10: 525648.7 | AS10: 460979.83 | AT10: 432378.21 | AU10: 343786.7 | AV10: 317721.97 | AW10: 267416.18 | AX10: 243884.92 | AY10: 147772.19 | AZ10: 118390.91 | BA10: 111507.21 | BB10: 96052.99 | BC10: 96052.99 | BD10: 61425.67 | BE10: 8111.97 | BF10: 4192.77 | BG10: 4192.77 | BH10: 0 | BI10: 0 | BJ10: 0 | BK10: 0 | BL10: 0
A11: other_fee_p_m | B11: 186516.38 | C11: 176401.72 | D11: 175196 | E11: 175136 | F11: 172664.36 | G11: 169821.88 | H11: 169041.88 | I11: 157782.24 | J11: 148221.6 | K11: 147375.1 | L11: 142717.98 | M11: 134267.59 | N11: 128629.94 | O11: 121352.95 | P11: 108985.7 | Q11: 104511.04 | R11: 97598.52 | S11: 96692.02 | T11: 93287.09 | U11: 88994.18 | V11: 88794.18 | W11: 87406.66 | X11: 84856.36 | Y11: 81721.93 | Z11: 75460.56 | AA11: 74122.17 | AB11: 74002.17 | AC11: 73942.17 | AD11: 73319.67 | AE11: 71207.17 | AF11: 60644.99 | AG11: 53122.81 | AH11: 52620.31 | AI11: 51232.81 | AJ11: 40216.25 | AK11: 38446.25 | AL11: 33543.11 | AM11: 28161.51 | AN11: 28161.51 | AO11: 22042.63 | AP11: 21802.63 | AQ11: 13449.75 | AR11: 13389.75 | AS11: 12137.18 | AT11: 12017.18 | AU11: 9924.68 | AV11: 9864.68 | AW11: 7101.62 | AX11: 6921.62 | AY11: 4485.02 | AZ11: 4042.52 | BA11: 3660.02 | BB11: 2895.02 | BC11: 2895.02 | BD11: 2010.02 | BE11: 480 | BF11: 420 | BG11: 360 | BH11: 240 | BI11: 60 | BJ11: 60 | BK11: 60 | BL11: 60
A12: total_cost | B12: 1.7865867e+08 | C12: 1.5218292e+08 | D12: 1.5033989e+08 | E12: 1.4991145e+08 | F12: 1.4900384e+08 | G12: 1.4485934e+08 | H12: 1.4026212e+08 | I12: 1.3018792e+08 | J12: 1.2309499e+08 | K12: 1.198191e+08 | L12: 1.1604043e+08 | M12: 1.0781393e+08 | N12: 1.0507005e+08 | O12: 1.0014909e+08 | P12: 96943121 | Q12: 93993419 | R12: 91605057 | S12: 87809120 | T12: 85838949 | U12: 82368472 | V12: 81063396 | W12: 77624907 | X12: 73494245 | Y12: 71081450 | Z12: 65613812 | AA12: 64834473 | AB12: 63881584 | AC12: 62845900 | AD12: 60802147 | AE12: 57164565 | AF12: 51179077 | AG12: 43551122 | AH12: 42606578 | AI12: 39427460 | AJ12: 36807026 | AK12: 33809975 | AL12: 30216176 | AM12: 26953292 | AN12: 26953292 | AO12: 24646125 | AP12: 22943558 | AQ12: 21237419 | AR12: 20660226 | AS12: 19778281 | AT12: 18846749 | AU12: 15573877 | AV12: 15048587 | AW12: 11744475 | AX12: 10578537 | AY12: 8488059.1 | AZ12: 7706603.3 | BA12: 7439497.6 | BB12: 6578543.9 | BC12: 6578543.9 | BD12: 4099184.7 | BE12: 2325924.9 | BF12: 2126802.1 | BG12: 1529619.2 | BH12: 995023.58 | BI12: 659528.18 | BJ12: 659528.18 | BK12: 659528.18 | BL12: 659528.18
A13: nbv | B13: 1.0879258e+08 | C13: 1.0200352e+08 | D13: 99053581 | E13: 96757912 | F13: 94175153 | G13: 90761327 | H13: 86929354 | I13: 79930875 | J13: 74789415 | K13: 71813398 | L13: 68252490 | M13: 62681568 | N13: 60522457 | O13: 57065719 | P13: 54361809 | Q13: 51816373 | R13: 49665417 | S13: 47303198 | T13: 45711285 | U13: 43469731 | V13: 42114025 | W13: 39862797 | X13: 37214802 | Y13: 35624884 | Z13: 32309959 | AA13: 31208412 | AB13: 30027752 | AC13: 28732007 | AD13: 27307112 | AE13: 25008271 | AF13: 21441280 | AG13: 18065835 | AH13: 17060561 | AI13: 15618985 | AJ13: 14558392 | AK13: 13218890 | AL13: 11801219 | AM13: 10363091 | AN13: 10000766 | AO13: 9333707.8 | AP13: 8589391.8 | AQ13: 7767678.6 | AR13: 7305468.5 | AS13: 6790879.4 | AT13: 6178672.4 | AU13: 5246444.9 | AV13: 4892315 | AW13: 3786105.4 | AX13: 3191897.2 | AY13: 2639548.3 | AZ13: 2375412.2 | BA13: 2215874.1 | BB13: 1943714.8 | BC13: 1858217.3 | BD13: 1312769.9 | BE13: 786790.62 | BF13: 717815.79 | BG13: 562424.41 | BH13: 262099.03 | BI13: 292880.5 | BJ13: 287345.86 | BK13: 281811.22 | BL13: 276276.58
... A16: olmm_fleet_drop | B16: 0 | C16: 4 | D16: 1 | E16: 0 | F16: 0 | G16: 1 | H16: 1 | I16: 0 | J16: 0 | K16: 0 | L16: 0 | M16: 1 | N16: 0 | O16: 0 | P16: 0 | Q16: 0 | R16: 1 | S16: 1 | T16: 1 | U16: 1 | V16: 1 | W16: 0 | X16: 2 | Y16: 0 | Z16: 0 | AA16: 0 | AB16: 1 | AC16: 0 | AD16: 0 | AE16: 1 | AF16: 0 | AG16: 0 | AH16: 0 | AI16: 1 | AJ16: 1 | AK16: 0 | AL16: 0 | AM16: 0 | AN16: 0 | AO16: 0 | AP16: 0 | AQ16: 0 | AR16: 0 | AS16: 0 | AT16: 0 | AU16: 0 | AV16: 0 | AW16: 1 | AX16: 0 | AY16: 0 | AZ16: 0 | BA16: 0 | BB16: 0 | BC16: 0 | BD16: 0 | BE16: 0 | BF16: 0 | BG16: 1 | BH16: 0 | BI16: 3 | BJ16: 0 | BK16: 0 | BL16: 0

Sheet GHA
A1: Value | B1: 2025/11/17 | C1: 2025/11/30 | D1: 2025/12/31 | E1: 2026/01/31 | F1: 2026/02/28 | G1: 2026/03/31 | H1: 2026/04/30 | I1: 2026/05/31 | J1: 2026/06/30 | K1: 2026/07/31 | L1: 2026/08/31 | M1: 2026/09/30 | N1: 2026/10/31 | O1: 2026/11/30 | P1: 2026/12/31 | Q1: 2027/01/31 | R1: 2027/02/28 | S1: 2027/03/31 | T1: 2027/04/30 | U1: 2027/05/31 | V1: 2027/06/30 | W1: 2027/07/31 | X1: 2027/08/31 | Y1: 2027/09/30 | Z1: 2027/10/31 | AA1: 2027/11/30 | AB1: 2027/12/31 | AC1: 2028/01/31 | AD1: 2028/02/29 | AE1: 2028/03/31 | AF1: 2028/04/30 | AG1: 2028/05/31 | AH1: 2028/06/30 | AI1: 2028/07/31 | AJ1: 2028/08/31 | AK1: 2028/09/30 | AL1: 2028/10/31 | AM1: 2028/11/30 | AN1: 2028/12/31 | AO1: 2029/01/31 | AP1: 2029/02/28 | AQ1: 2029/03/31 | AR1: 2029/04/30 | AS1: 2029/05/31 | AT1: 2029/06/30 | AU1: 2029/07/31 | AV1: 2029/08/31 | AW1: 2029/09/30 | AX1: 2029/10/31 | AY1: 2029/11/30 | AZ1: 2029/12/31 | BA1: 2030/01/31 | BB1: 2030/02/28 | BC1: 2030/03/31 | BD1: 2030/04/30 | BE1: 2030/05/31 | BF1: 2030/06/30 | BG1: 2030/07/31 | BH1: 2030/08/31 | BI1: 2030/09/30 | BJ1: 2030/10/31 | BK1: 2030/11/30 | BL1: 2030/12/31
A2: fml_count | B2: 5 | C2: 4 | D2: 0 | E2: 0 | F2: 0 | G2: 0 | H2: 0 | I2: 0 | J2: 0 | K2: 0 | L2: 0 | M2: 0 | N2: 0 | O2: 0 | P2: 0 | Q2: 0 | R2: 0 | S2: 0 | T2: 0 | U2: 0 | V2: 0 | W2: 0 | X2: 0 | Y2: 0 | Z2: 0 | AA2: 0 | AB2: 0 | AC2: 0 | AD2: 0 | AE2: 0 | AF2: 0 | AG2: 0 | AH2: 0 | AI2: 0 | AJ2: 0 | AK2: 0 | AL2: 0 | AM2: 0 | AN2: 0 | AO2: 0 | AP2: 0 | AQ2: 0 | AR2: 0 | AS2: 0 | AT2: 0 | AU2: 0 | AV2: 0 | AW2: 0 | AX2: 0 | AY2: 0 | AZ2: 0 | BA2: 0 | BB2: 0 | BC2: 0 | BD2: 0 | BE2: 0 | BF2: 0 | BG2: 0 | BH2: 0 | BI2: 0 | BJ2: 0 | BK2: 0 | BL2: 0
A3: olmm_count | B3: 0 | C3: 0 | D3: 0 | E3: 0 | F3: 0 | G3: 0 | H3: 0 | I3: 0 | J3: 0 | K3: 0 | L3: 0 | M3: 0 | N3: 0 | O3: 0 | P3: 0 | Q3: 0 | R3: 0 | S3: 0 | T3: 0 | U3: 0 | V3: 0 | W3: 0 | X3: 0 | Y3: 0 | Z3: 0 | AA3: 0 | AB3: 0 | AC3: 0 | AD3: 0 | AE3: 0 | AF3: 0 | AG3: 0 | AH3: 0 | AI3: 0 | AJ3: 0 | AK3: 0 | AL3: 0 | AM3: 0 | AN3: 0 | AO3: 0 | AP3: 0 | AQ3: 0 | AR3: 0 | AS3: 0 | AT3: 0 | AU3: 0 | AV3: 0 | AW3: 0 | AX3: 0 | AY3: 0 | AZ3: 0 | BA3: 0 | BB3: 0 | BC3: 0 | BD3: 0 | BE3: 0 | BF3: 0 | BG3: 0 | BH3: 0 | BI3: 0 | BJ3: 0 | BK3: 0 | BL3: 0
A4: pl_count | B4: 0 | C4: 0 | D4: 0 | E4: 0 | F4: 0 | G4: 0 | H4: 0 | I4: 0 | J4: 0 | K4: 0 | L4: 0 | M4: 0 | N4: 0 | O4: 0 | P4: 0 | Q4: 0 | R4: 0 | S4: 0 | T4: 0 | U4: 0 | V4: 0 | W4: 0 | X4: 0 | Y4: 0 | Z4: 0 | AA4: 0 | AB4: 0 | AC4: 0 | AD4: 0 | AE4: 0 | AF4: 0 | AG4: 0 | AH4: 0 | AI4: 0 | AJ4: 0 | AK4: 0 | AL4: 0 | AM4: 0 | AN4: 0 | AO4: 0 | AP4: 0 | AQ4: 0 | AR4: 0 | AS4: 0 | AT4: 0 | AU4: 0 | AV4: 0 | AW4: 0 | AX4: 0 | AY4: 0 | AZ4: 0 | BA4: 0 | BB4: 0 | BC4: 0 | BD4: 0 | BE4: 0 | BF4: 0 | BG4: 0 | BH4: 0 | BI4: 0 | BJ4: 0 | BK4: 0 | BL4: 0
A5: revenue_p_m | B5: 2199.37 | C5: 1804.33 | D5: 0 | E5: 0 | F5: 0 | G5: 0 | H5: 0 | I5: 0 | J5: 0 | K5: 0 | L5: 0 | M5: 0 | N5: 0 | O5: 0 | P5: 0 | Q5: 0 | R5: 0 | S5: 0 | T5: 0 | U5: 0 | V5: 0 | W5: 0 | X5: 0 | Y5: 0 | Z5: 0 | AA5: 0 | AB5: 0 | AC5: 0 | AD5: 0 | AE5: 0 | AF5: 0 | AG5: 0 | AH5: 0 | AI5: 0 | AJ5: 0 | AK5: 0 | AL5: 0 | AM5: 0 | AN5: 0 | AO5: 0 | AP5: 0 | AQ5: 0 | AR5: 0 | AS5: 0 | AT5: 0 | AU5: 0 | AV5: 0 | AW5: 0 | AX5: 0 | AY5: 0 | AZ5: 0 | BA5: 0 | BB5: 0 | BC5: 0 | BD5: 0 | BE5: 0 | BF5: 0 | BG5: 0 | BH5: 0 | BI5: 0 | BJ5: 0 | BK5: 0 | BL5: 0
A6: depreciation_p_m | B6: 425.01 | C6: 358.15 | D6: 0 | E6: 0 | F6: 0 | G6: 0 | H6: 0 | I6: 0 | J6: 0 | K6: 0 | L6: 0 | M6: 0 | N6: 0 | O6: 0 | P6: 0 | Q6: 0 | R6: 0 | S6: 0 | T6: 0 | U6: 0 | V6: 0 | W6: 0 | X6: 0 | Y6: 0 | Z6: 0 | AA6: 0 | AB6: 0 | AC6: 0 | AD6: 0 | AE6: 0 | AF6: 0 | AG6: 0 | AH6: 0 | AI6: 0 | AJ6: 0 | AK6: 0 | AL6: 0 | AM6: 0 | AN6: 0 | AO6: 0 | AP6: 0 | AQ6: 0 | AR6: 0 | AS6: 0 | AT6: 0 | AU6: 0 | AV6: 0 | AW6: 0 | AX6: 0 | AY6: 0 | AZ6: 0 | BA6: 0 | BB6: 0 | BC6: 0 | BD6: 0 | BE6: 0 | BF6: 0 | BG6: 0 | BH6: 0 | BI6: 0 | BJ6: 0 | BK6: 0 | BL6: 0
A7: interest_p_m | B7: 341.63 | C7: 316.52 | D7: 0 | E7: 0 | F7: 0 | G7: 0 | H7: 0 | I7: 0 | J7: 0 | K7: 0 | L7: 0 | M7: 0 | N7: 0 | O7: 0 | P7: 0 | Q7: 0 | R7: 0 | S7: 0 | T7: 0 | U7: 0 | V7: 0 | W7: 0 | X7: 0 | Y7: 0 | Z7: 0 | AA7: 0 | AB7: 0 | AC7: 0 | AD7: 0 | AE7: 0 | AF7: 0 | AG7: 0 | AH7: 0 | AI7: 0 | AJ7: 0 | AK7: 0 | AL7: 0 | AM7: 0 | AN7: 0 | AO7: 0 | AP7: 0 | AQ7: 0 | AR7: 0 | AS7: 0 | AT7: 0 | AU7: 0 | AV7: 0 | AW7: 0 | AX7: 0 | AY7: 0 | AZ7: 0 | BA7: 0 | BB7: 0 | BC7: 0 | BD7: 0 | BE7: 0 | BF7: 0 | BG7: 0 | BH7: 0 | BI7: 0 | BJ7: 0 | BK7: 0 | BL7: 0
A8: admin_p_m | B8: 400 | C8: 320 | D8: 0 | E8: 0 | F8: 0 | G8: 0 | H8: 0 | I8: 0 | J8: 0 | K8: 0 | L8: 0 | M8: 0 | N8: 0 | O8: 0 | P8: 0 | Q8: 0 | R8: 0 | S8: 0 | T8: 0 | U8: 0 | V8: 0 | W8: 0 | X8: 0 | Y8: 0 | Z8: 0 | AA8: 0 | AB8: 0 | AC8: 0 | AD8: 0 | AE8: 0 | AF8: 0 | AG8: 0 | AH8: 0 | AI8: 0 | AJ8: 0 | AK8: 0 | AL8: 0 | AM8: 0 | AN8: 0 | AO8: 0 | AP8: 0 | AQ8: 0 | AR8: 0 | AS8: 0 | AT8: 0 | AU8: 0 | AV8: 0 | AW8: 0 | AX8: 0 | AY8: 0 | AZ8: 0 | BA8: 0 | BB8: 0 | BC8: 0 | BD8: 0 | BE8: 0 | BF8: 0 | BG8: 0 | BH8: 0 | BI8: 0 | BJ8: 0 | BK8: 0 | BL8: 0
A9: maint_prov_p_m | B9: 29541.93 | C9: 23286.77 | D9: 0 | E9: 0 | F9: 0 | G9: 0 | H9: 0 | I9: 0 | J9: 0 | K9: 0 | L9: 0 | M9: 0 | N9: 0 | O9: 0 | P9: 0 | Q9: 0 | R9: 0 | S9: 0 | T9: 0 | U9: 0 | V9: 0 | W9: 0 | X9: 0 | Y9: 0 | Z9: 0 | AA9: 0 | AB9: 0 | AC9: 0 | AD9: 0 | AE9: 0 | AF9: 0 | AG9: 0 | AH9: 0 | AI9: 0 | AJ9: 0 | AK9: 0 | AL9: 0 | AM9: 0 | AN9: 0 | AO9: 0 | AP9: 0 | AQ9: 0 | AR9: 0 | AS9: 0 | AT9: 0 | AU9: 0 | AV9: 0 | AW9: 0 | AX9: 0 | AY9: 0 | AZ9: 0 | BA9: 0 | BB9: 0 | BC9: 0 | BD9: 0 | BE9: 0 | BF9: 0 | BG9: 0 | BH9: 0 | BI9: 0 | BJ9: 0 | BK9: 0 | BL9: 0
A10: maintenance_fund | B10: 7649.6 | C10: 4685.07 | D10: 0 | E10: 0 | F10: 0 | G10: 0 | H10: 0 | I10: 0 | J10: 0 | K10: 0 | L10: 0 | M10: 0 | N10: 0 | O10: 0 | P10: 0 | Q10: 0 | R10: 0 | S10: 0 | T10: 0 | U10: 0 | V10: 0 | W10: 0 | X10: 0 | Y10: 0 | Z10: 0 | AA10: 0 | AB10: 0 | AC10: 0 | AD10: 0 | AE10: 0 | AF10: 0 | AG10: 0 | AH10: 0 | AI10: 0 | AJ10: 0 | AK10: 0 | AL10: 0 | AM10: 0 | AN10: 0 | AO10: 0 | AP10: 0 | AQ10: 0 | AR10: 0 | AS10: 0 | AT10: 0 | AU10: 0 | AV10: 0 | AW10: 0 | AX10: 0 | AY10: 0 | AZ10: 0 | BA10: 0 | BB10: 0 | BC10: 0 | BD10: 0 | BE10: 0 | BF10: 0 | BG10: 0 | BH10: 0 | BI10: 0 | BJ10: 0 | BK10: 0 | BL10: 0
A11: other_fee_p_m | B11: 543.57 | C11: 434.84 | D11: 0 | E11: 0 | F11: 0 | G11: 0 | H11: 0 | I11: 0 | J11: 0 | K11: 0 | L11: 0 | M11: 0 | N11: 0 | O11: 0 | P11: 0 | Q11: 0 | R11: 0 | S11: 0 | T11: 0 | U11: 0 | V11: 0 | W11: 0 | X11: 0 | Y11: 0 | Z11: 0 | AA11: 0 | AB11: 0 | AC11: 0 | AD11: 0 | AE11: 0 | AF11: 0 | AG11: 0 | AH11: 0 | AI11: 0 | AJ11: 0 | AK11: 0 | AL11: 0 | AM11: 0 | AN11: 0 | AO11: 0 | AP11: 0 | AQ11: 0 | AR11: 0 | AS11: 0 | AT11: 0 | AU11: 0 | AV11: 0 | AW11: 0 | AX11: 0 | AY11: 0 | AZ11: 0 | BA11: 0 | BB11: 0 | BC11: 0 | BD11: 0 | BE11: 0 | BF11: 0 | BG11: 0 | BH11: 0 | BI11: 0 | BJ11: 0 | BK11: 0 | BL11: 0
A12: total_cost | B12: 66498.7 | C12: 53197 | D12: 0 | E12: 0 | F12: 0 | G12: 0 | H12: 0 | I12: 0 | J12: 0 | K12: 0 | L12: 0 | M12: 0 | N12: 0 | O12: 0 | P12: 0 | Q12: 0 | R12: 0 | S12: 0 | T12: 0 | U12: 0 | V12: 0 | W12: 0 | X12: 0 | Y12: 0 | Z12: 0 | AA12: 0 | AB12: 0 | AC12: 0 | AD12: 0 | AE12: 0 | AF12: 0 | AG12: 0 | AH12: 0 | AI12: 0 | AJ12: 0 | AK12: 0 | AL12: 0 | AM12: 0 | AN12: 0 | AO12: 0 | AP12: 0 | AQ12: 0 | AR12: 0 | AS12: 0 | AT12: 0 | AU12: 0 | AV12: 0 | AW12: 0 | AX12: 0 | AY12: 0 | AZ12: 0 | BA12: 0 | BB12: 0 | BC12: 0 | BD12: 0 | BE12: 0 | BF12: 0 | BG12: 0 | BH12: 0 | BI12: 0 | BJ12: 0 | BK12: 0 | BL12: 0
A13: nbv | B13: 16610.2 | C13: 14926.72 | D13: 0 | E13: 0 | F13: 0 | G13: 0 | H13: 0 | I13: 0 | J13: 0 | K13: 0 | L13: 0 | M13: 0 | N13: 0 | O13: 0 | P13: 0 | Q13: 0 | R13: 0 | S13: 0 | T13: 0 | U13: 0 | V13: 0 | W13: 0 | X13: 0 | Y13: 0 | Z13: 0 | AA13: 0 | AB13: 0 | AC13: 0 | AD13: 0 | AE13: 0 | AF13: 0 | AG13: 0 | AH13: 0 | AI13: 0 | AJ13: 0 | AK13: 0 | AL13: 0 | AM13: 0 | AN13: 0 | AO13: 0 | AP13: 0 | AQ13: 0 | AR13: 0 | AS13: 0 | AT13: 0 | AU13: 0 | AV13: 0 | AW13: 0 | AX13: 0 | AY13: 0 | AZ13: 0 | BA13: 0 | BB13: 0 | BC13: 0 | BD13: 0 | BE13: 0 | BF13: 0 | BG13: 0 | BH13: 0 | BI13: 0 | BJ13: 0 | BK13: 0 | BL13: 0
... A16: olmm_fleet_drop | B16: 0 | C16: 0 | D16: 0 | E16: 0 | F16: 0 | G16: 0 | H16: 0 | I16: 0 | J16: 0 | K16: 0 | L16: 0 | M16: 0 | N16: 0 | O16: 0 | P16: 0 | Q16: 0 | R16: 0 | S16: 0 | T16: 0 | U16: 0 | V16: 0 | W16: 0 | X16: 0 | Y16: 0 | Z16: 0 | AA16: 0 | AB16: 0 | AC16: 0 | AD16: 0 | AE16: 0 | AF16: 0 | AG16: 0 | AH16: 0 | AI16: 0 | AJ16: 0 | AK16: 0 | AL16: 0 | AM16: 0 | AN16: 0 | AO16: 0 | AP16: 0 | AQ16: 0 | AR16: 0 | AS16: 0 | AT16: 0 | AU16: 0 | AV16: 0 | AW16: 0 | AX16: 0 | AY16: 0 | AZ16: 0 | BA16: 0 | BB16: 0 | BC16: 0 | BD16: 0 | BE16: 0 | BF16: 0 | BG16: 0 | BH16: 0 | BI16: 0 | BJ16: 0 | BK16: 0 | BL16: 0

Sheet GHC
A1: Value | B1: 2025/11/17 | C1: 2025/11/30 | D1: 2025/12/31 | E1: 2026/01/31 | F1: 2026/02/28 | G1: 2026/03/31 | H1: 2026/04/30 | I1: 2026/05/31 | J1: 2026/06/30 | K1: 2026/07/31 | L1: 2026/08/31 | M1: 2026/09/30 | N1: 2026/10/31 | O1: 2026/11/30 | P1: 2026/12/31 | Q1: 2027/01/31 | R1: 2027/02/28 | S1: 2027/03/31 | T1: 2027/04/30 | U1: 2027/05/31 | V1: 2027/06/30 | W1: 2027/07/31 | X1: 2027/08/31 | Y1: 2027/09/30 | Z1: 2027/10/31 | AA1: 2027/11/30 | AB1: 2027/12/31 | AC1: 2028/01/31 | AD1: 2028/02/29 | AE1: 2028/03/31 | AF1: 2028/04/30 | AG1: 2028/05/31 | AH1: 2028/06/30 | AI1: 2028/07/31 | AJ1: 2028/08/31 | AK1: 2028/09/30 | AL1: 2028/10/31 | AM1: 2028/11/30 | AN1: 2028/12/31 | AO1: 2029/01/31 | AP1: 2029/02/28 | AQ1: 2029/03/31 | AR1: 2029/04/30 | AS1: 2029/05/31 | AT1: 2029/06/30 | AU1: 2029/07/31 | AV1: 2029/08/31 | AW1: 2029/09/30 | AX1: 2029/10/31 | AY1: 2029/11/30 | AZ1: 2029/12/31 | BA1: 2030/01/31 | BB1: 2030/02/28 | BC1: 2030/03/31 | BD1: 2030/04/30 | BE1: 2030/05/31 | BF1: 2030/06/30 | BG1: 2030/07/31 | BH1: 2030/08/31 | BI1: 2030/09/30 | BJ1: 2030/10/31 | BK1: 2030/11/30 | BL1: 2030/12/31
A2: fml_count | B2: 156 | C2: 135 | D2: 134 | E2: 133 | F2: 130 | G2: 121 | H2: 120 | I2: 107 | J2: 104 | K2: 103 | L2: 68 | M2: 67 | N2: 67 | O2: 67 | P2: 67 | Q2: 66 | R2: 64 | S2: 59 | T2: 58 | U2: 58 | V2: 47 | W2: 47 | X2: 46 | Y2: 46 | Z2: 46 | AA2: 46 | AB2: 46 | AC2: 44 | AD2: 44 | AE2: 44 | AF2: 44 | AG2: 44 | AH2: 44 | AI2: 43 | AJ2: 43 | AK2: 42 | AL2: 42 | AM2: 42 | AN2: 42 | AO2: 42 | AP2: 42 | AQ2: 42 | AR2: 42 | AS2: 41 | AT2: 1 | AU2: 1 | AV2: 1 | AW2: 0 | AX2: 0 | AY2: 0 | AZ2: 0 | BA2: 0 | BB2: 0 | BC2: 0 | BD2: 0 | BE2: 0 | BF2: 0 | BG2: 0 | BH2: 0 | BI2: 0 | BJ2: 0 | BK2: 0 | BL2: 0
A3: olmm_count | B3: 0 | C3: 0 | D3: 0 | E3: 0 | F3: 0 | G3: 0 | H3: 0 | I3: 0 | J3: 0 | K3: 0 | L3: 0 | M3: 0 | N3: 0 | O3: 0 | P3: 0 | Q3: 0 | R3: 0 | S3: 0 | T3: 0 | U3: 0 | V3: 0 | W3: 0 | X3: 0 | Y3: 0 | Z3: 0 | AA3: 0 | AB3: 0 | AC3: 0 | AD3: 0 | AE3: 0 | AF3: 0 | AG3: 0 | AH3: 0 | AI3: 0 | AJ3: 0 | AK3: 0 | AL3: 0 | AM3: 0 | AN3: 0 | AO3: 0 | AP3: 0 | AQ3: 0 | AR3: 0 | AS3: 0 | AT3: 0 | AU3: 0 | AV3: 0 | AW3: 0 | AX3: 0 | AY3: 0 | AZ3: 0 | BA3: 0 | BB3: 0 | BC3: 0 | BD3: 0 | BE3: 0 | BF3: 0 | BG3: 0 | BH3: 0 | BI3: 0 | BJ3: 0 | BK3: 0 | BL3: 0
A4: pl_count | B4: 0 | C4: 0 | D4: 0 | E4: 0 | F4: 0 | G4: 0 | H4: 0 | I4: 0 | J4: 0 | K4: 0 | L4: 0 | M4: 0 | N4: 0 | O4: 0 | P4: 0 | Q4: 0 | R4: 0 | S4: 0 | T4: 0 | U4: 0 | V4: 0 | W4: 0 | X4: 0 | Y4: 0 | Z4: 0 | AA4: 0 | AB4: 0 | AC4: 0 | AD4: 0 | AE4: 0 | AF4: 0 | AG4: 0 | AH4: 0 | AI4: 0 | AJ4: 0 | AK4: 0 | AL4: 0 | AM4: 0 | AN4: 0 | AO4: 0 | AP4: 0 | AQ4: 0 | AR4: 0 | AS4: 0 | AT4: 0 | AU4: 0 | AV4: 0 | AW4: 0 | AX4: 0 | AY4: 0 | AZ4: 0 | BA4: 0 | BB4: 0 | BC4: 0 | BD4: 0 | BE4: 0 | BF4: 0 | BG4: 0 | BH4: 0 | BI4: 0 | BJ4: 0 | BK4: 0 | BL4: 0
A5: revenue_p_m | B5: 2581623 | C5: 2438219.6 | D5: 2427539.8 | E5: 2422632.9 | F5: 2396392.4 | G5: 2321409.6 | H5: 2309260.8 | I5: 2189055.5 | J5: 2137963 | K5: 2129865.1 | L5: 1783905.7 | M5: 1761137.1 | N5: 1761137.1 | O5: 1761137.1 | P5: 1761137.1 | Q5: 1733951.6 | R5: 1712641.7 | S5: 1662008 | T5: 1652026.7 | U5: 1652026.7 | V5: 1319308.9 | W5: 1319308.9 | X5: 1307002.4 | Y5: 1307002.4 | Z5: 1307002.4 | AA5: 1307002.4 | AB5: 1307002.4 | AC5: 1261301.6 | AD5: 1261301.6 | AE5: 1261301.6 | AF5: 1261301.6 | AG5: 1261301.6 | AH5: 1261301.6 | AI5: 1242826.4 | AJ5: 1242826.4 | AK5: 1222232.9 | AL5: 1222232.9 | AM5: 1222232.9 | AN5: 1222232.9 | AO5: 1222232.9 | AP5: 1222232.9 | AQ5: 1222232.9 | AR5: 1222232.9 | AS5: 1170874.2 | AT5: 53283.12 | AU5: 53283.12 | AV5: 53283.12 | AW5: 0 | AX5: 0 | AY5: 0 | AZ5: 0 | BA5: 0 | BB5: 0 | BC5: 0 | BD5: 0 | BE5: 0 | BF5: 0 | BG5: 0 | BH5: 0 | BI5: 0 | BJ5: 0 | BK5: 0 | BL5: 0
A6: depreciation_p_m | B6: 681549.87 | C6: 650889.88 | D6: 649903.75 | E6: 649326.31 | F6: 646950.81 | G6: 635463.51 | H6: 633257.7 | I6: 598011.2 | J6: 584597.88 | K6: 582703.14 | L6: 525935.64 | M6: 518846.57 | N6: 518846.57 | O6: 518846.57 | P6: 518846.57 | Q6: 512065.39 | R6: 509604.22 | S6: 496075.42 | T6: 493072.15 | U6: 493072.15 | V6: 371382.61 | W6: 371382.61 | X6: 369912.03 | Y6: 369912.03 | Z6: 369912.03 | AA6: 369912.03 | AB6: 369912.03 | AC6: 357769.37 | AD6: 357769.37 | AE6: 357769.37 | AF6: 357769.37 | AG6: 357769.37 | AH6: 357769.37 | AI6: 352515.79 | AJ6: 352515.79 | AK6: 347492.57 | AL6: 347492.57 | AM6: 347492.57 | AN6: 347492.57 | AO6: 347492.57 | AP6: 347492.57 | AQ6: 347492.57 | AR6: 347492.57 | AS6: 332726.37 | AT6: 17606.19 | AU6: 17606.19 | AV6: 17606.19 | AW6: 0 | AX6: 0 | AY6: 0 | AZ6: 0 | BA6: 0 | BB6: 0 | BC6: 0 | BD6: 0 | BE6: 0 | BF6: 0 | BG6: 0 | BH6: 0 | BI6: 0 | BJ6: 0 | BK6: 0 | BL6: 0
A7: interest_p_m | B7: 788844.33 | C7: 785491.08 | D7: 784216.77 | E7: 783015.15 | F7: 779507.71 | G7: 759252.34 | H7: 756371.47 | I7: 726189.68 | J7: 705810.56 | K7: 702820.23 | L7: 614085.27 | M7: 605513.64 | N7: 605513.64 | O7: 605513.64 | P7: 605513.64 | Q7: 593741.66 | R7: 588957.91 | S7: 575913.95 | T7: 573236.27 | U7: 573236.27 | V7: 466201.6 | W7: 466201.6 | X7: 463247.82 | Y7: 463247.82 | Z7: 463247.82 | AA7: 463247.82 | AB7: 463247.82 | AC7: 448109.06 | AD7: 448109.06 | AE7: 448109.06 | AF7: 448109.06 | AG7: 448109.06 | AH7: 448109.06 | AI7: 441649.64 | AJ7: 441649.64 | AK7: 435084.11 | AL7: 435084.11 | AM7: 435084.11 | AN7: 435084.11 | AO7: 435084.11 | AP7: 435084.11 | AQ7: 435084.11 | AR7: 435084.11 | AS7: 412867.42 | AT7: 23615.34 | AU7: 23615.34 | AV7: 23615.34 | AW7: 0 | AX7: 0 | AY7: 0 | AZ7: 0 | BA7: 0 | BB7: 0 | BC7: 0 | BD7: 0 | BE7: 0 | BF7: 0 | BG7: 0 | BH7: 0 | BI7: 0 | BJ7: 0 | BK7: 0 | BL7: 0
A8: admin_p_m | B8: 207094.8 | C8: 181269.11 | D8: 179301.92 | E8: 178052.09 | F8: 175087.52 | G8: 165850.82 | H8: 164397.75 | I8: 155147.61 | J8: 151763.05 | K8: 150661.85 | L8: 109922.39 | M8: 107304.74 | N8: 107304.74 | O8: 107304.74 | P8: 107304.74 | Q8: 105071.36 | R8: 103158.63 | S8: 98377.04 | T8: 97057.47 | U8: 97057.47 | V8: 69870.41 | W8: 69870.41 | X8: 68554.51 | Y8: 68554.51 | Z8: 68554.51 | AA8: 68554.51 | AB8: 68554.51 | AC8: 65045.61 | AD8: 65045.61 | AE8: 65045.61 | AF8: 65045.61 | AG8: 65045.61 | AH8: 65045.61 | AI8: 63644.85 | AJ8: 63644.85 | AK8: 62533.85 | AL8: 62533.85 | AM8: 62533.85 | AN8: 62533.85 | AO8: 62533.85 | AP8: 62533.85 | AQ8: 62533.85 | AR8: 62533.85 | AS8: 58842.3 | AT8: 3619.07 | AU8: 3619.07 | AV8: 3619.07 | AW8: 0 | AX8: 0 | AY8: 0 | AZ8: 0 | BA8: 0 | BB8: 0 | BC8: 0 | BD8: 0 | BE8: 0 | BF8: 0 | BG8: 0 | BH8: 0 | BI8: 0 | BJ8: 0 | BK8: 0 | BL8: 0
A9: maint_prov_p_m | B9: 11506883 | C9: 9036976.6 | D9: 8958349.4 | E9: 8851066.2 | F9: 8382776.3 | G9: 7439986.9 | H9: 7346267.6 | I9: 6553890.5 | J9: 6391642.5 | K9: 6372081.5 | L9: 3573444.7 | M9: 3530029 | N9: 3530029 | O9: 3530029 | P9: 3530029 | Q9: 3476659.3 | R9: 3316247.6 | S9: 2978051.3 | T9: 2939359.4 | U9: 2939359.4 | V9: 2538745.7 | W9: 2538745.7 | X9: 2471593.2 | Y9: 2471593.2 | Z9: 2471593.2 | AA9: 2471593.2 | AB9: 2471593.2 | AC9: 2270193.2 | AD9: 2270193.2 | AE9: 2270193.2 | AF9: 2270193.2 | AG9: 2270193.2 | AH9: 2270193.2 | AI9: 2211484.8 | AJ9: 2211484.8 | AK9: 2166284.8 | AL9: 2166284.8 | AM9: 2166284.8 | AN9: 2166284.8 | AO9: 2166284.8 | AP9: 2166284.8 | AQ9: 2166284.8 | AR9: 2166284.8 | AS9: 2149148.8 | AT9: 109980.78 | AU9: 109980.78 | AV9: 109980.78 | AW9: 0 | AX9: 0 | AY9: 0 | AZ9: 0 | BA9: 0 | BB9: 0 | BC9: 0 | BD9: 0 | BE9: 0 | BF9: 0 | BG9: 0 | BH9: 0 | BI9: 0 | BJ9: 0 | BK9: 0 | BL9: 0
A10: maintenance_fund | B10: 5588732.6 | C10: 4182501.4 | D10: 4181438.6 | E10: 4122455.7 | F10: 3971393.1 | G10: 3606197.4 | H10: 3540489.9 | I10: 3287022.7 | J10: 3222842.5 | K10: 3217284.9 | L10: 2306356.4 | M10: 2291480.5 | N10: 2291480.5 | O10: 2291480.5 | P10: 2291480.5 | Q10: 2260283.7 | R10: 2256794.5 | S10: 2202955.3 | T10: 2194966.5 | U10: 2194966.5 | V10: 2011477.5 | W10: 2011477.5 | X10: 2033942.4 | Y10: 2033942.4 | Z10: 2033942.4 | AA10: 2033942.4 | AB10: 2033942.4 | AC10: 1907933.3 | AD10: 1907933.3 | AE10: 1907933.3 | AF10: 1907933.3 | AG10: 1907933.3 | AH10: 1907933.3 | AI10: 1886439.5 | AJ10: 1886439.5 | AK10: 1895181.9 | AL10: 1895181.9 | AM10: 1895181.9 | AN10: 1895181.9 | AO10: 1895181.9 | AP10: 1895181.9 | AQ10: 1895181.9 | AR10: 1895181.9 | AS10: 1878045.9 | AT10: 105871.77 | AU10: 105871.77 | AV10: 105871.77 | AW10: 0 | AX10: 0 | AY10: 0 | AZ10: 0 | BA10: 0 | BB10: 0 | BC10: 0 | BD10: 0 | BE10: 0 | BF10: 0 | BG10: 0 | BH10: 0 | BI10: 0 | BJ10: 0 | BK10: 0 | BL10: 0
A11: other_fee_p_m | B11: 479464.3 | C11: 460098.71 | D11: 458146.52 | E11: 458018.52 | F11: 455394.16 | G11: 448917.82 | H11: 446308.69 | I11: 425516.78 | J11: 416457.15 | K11: 414567.69 | L11: 354776.37 | M11: 351236.81 | N11: 351236.81 | O11: 351236.81 | P11: 351236.81 | Q11: 346298.45 | R11: 343168.57 | S11: 335570.34 | T11: 333542.34 | U11: 333542.34 | V11: 269326.31 | W11: 269326.31 | X11: 267287.94 | Y11: 267287.94 | Z11: 267287.94 | AA11: 267287.94 | AB11: 267287.94 | AC11: 260433.48 | AD11: 260433.48 | AE11: 260433.48 | AF11: 260433.48 | AG11: 260433.48 | AH11: 260433.48 | AI11: 257096.48 | AJ11: 257096.48 | AK11: 253531.51 | AL11: 253531.51 | AM11: 253531.51 | AN11: 253531.51 | AO11: 253531.51 | AP11: 253531.51 | AQ11: 253531.51 | AR11: 253531.51 | AS11: 245295.26 | AT11: 586.75 | AU11: 586.75 | AV11: 586.75 | AW11: 0 | AX11: 0 | AY11: 0 | AZ11: 0 | BA11: 0 | BB11: 0 | BC11: 0 | BD11: 0 | BE11: 0 | BF11: 0 | BG11: 0 | BH11: 0 | BI11: 0 | BJ11: 0 | BK11: 0 | BL11: 0
A12: total_cost | B12: 58351201 | C12: 54424638 | D12: 54118569 | E12: 53925074 | F12: 53405219 | G12: 51535047 | H12: 51210310 | I12: 48182020 | J12: 46878008 | K12: 46591950 | L12: 37818280 | M12: 37304750 | N12: 37304750 | O12: 37304750 | P12: 37304750 | Q12: 36649734 | R12: 36135651 | S12: 35012062 | T12: 34758147 | U12: 34758147 | V12: 25493859 | W12: 25493859 | X12: 25214041 | Y12: 25214041 | Z12: 25214041 | AA12: 25214041 | AB12: 25214041 | AC12: 24371905 | AD12: 24371905 | AE12: 24371905 | AF12: 24371905 | AG12: 24371905 | AH12: 24371905 | AI12: 23951675 | AJ12: 23951675 | AK12: 23547275 | AL12: 23547275 | AM12: 23547275 | AN12: 23547275 | AO12: 23547275 | AP12: 23547275 | AQ12: 23547275 | AR12: 23547275 | AS12: 22439810 | AT12: 1240825 | AU12: 1240825 | AV12: 1240825 | AW12: 0 | AX12: 0 | AY12: 0 | AZ12: 0 | BA12: 0 | BB12: 0 | BC12: 0 | BD12: 0 | BE12: 0 | BF12: 0 | BG12: 0 | BH12: 0 | BI12: 0 | BJ12: 0 | BK12: 0 | BL12: 0
A13: nbv | B13: 32316761 | C13: 31704628 | D13: 30976234 | E13: 30281419 | F13: 29515550 | G13: 28298599 | H13: 27570581 | I13: 26075069 | J13: 24982427 | K13: 24290271 | L13: 21416982 | M13: 20744360 | N13: 20225514 | O13: 19706667 | P13: 19187820 | Q13: 18399773 | R13: 17734798 | S13: 16935034 | T13: 16371063 | U13: 15877990 | V13: 12047591 | W13: 11676209 | X13: 11205964 | Y13: 10836052 | Z13: 10466140 | AA13: 10096227 | AB13: 9726315.5 | AC13: 9121400.3 | AD13: 8763630.9 | AE13: 8405861.5 | AF13: 8048092.2 | AG13: 7690322.8 | AH13: 7332553.4 | AI13: 6869768.3 | AJ13: 6517252.5 | AK13: 6058006.7 | AL13: 5710514.1 | AM13: 5363021.5 | AN13: 5015529 | AO13: 4668036.4 | AP13: 4320543.8 | AQ13: 3973051.3 | AR13: 3625558.7 | AS13: 2879378.6 | AT13: 254878.36 | AU13: 237272.17 | AV13: 219665.98 | AW13: 0 | AX13: 0 | AY13: 0 | AZ13: 0 | BA13: 0 | BB13: 0 | BC13: 0 | BD13: 0 | BE13: 0 | BF13: 0 | BG13: 0 | BH13: 0 | BI13: 0 | BJ13: 0 | BK13: 0 | BL13: 0
... A16: olmm_fleet_drop | B16: 0 | C16: 0 | D16: 0 | E16: 0 | F16: 0 | G16: 0 | H16: 0 | I16: 0 | J16: 0 | K16: 0 | L16: 0 | M16: 0 | N16: 0 | O16: 0 | P16: 0 | Q16: 0 | R16: 0 | S16: 0 | T16: 0 | U16: 0 | V16: 0 | W16: 0 | X16: 0 | Y16: 0 | Z16: 0 | AA16: 0 | AB16: 0 | AC16: 0 | AD16: 0 | AE16: 0 | AF16: 0 | AG16: 0 | AH16: 0 | AI16: 0 | AJ16: 0 | AK16: 0 | AL16: 0 | AM16: 0 | AN16: 0 | AO16: 0 | AP16: 0 | AQ16: 0 | AR16: 0 | AS16: 0 | AT16: 0 | AU16: 0 | AV16: 0 | AW16: 0 | AX16: 0 | AY16: 0 | AZ16: 0 | BA16: 0 | BB16: 0 | BC16: 0 | BD16: 0 | BE16: 0 | BF16: 0 | BG16: 0 | BH16: 0 | BI16: 0 | BJ16: 0 | BK16: 0 | BL16: 0

Sheet LES
A1: Value | B1: 2025/11/17 | C1: 2025/11/30 | D1: 2025/12/31 | E1: 2026/01/31 | F1: 2026/02/28 | G1: 2026/03/31 | H1: 2026/04/30 | I1: 2026/05/31 | J1: 2026/06/30 | K1: 2026/07/31 | L1: 2026/08/31 | M1: 2026/09/30 | N1: 2026/10/31 | O1: 2026/11/30 | P1: 2026/12/31 | Q1: 2027/01/31 | R1: 2027/02/28 | S1: 2027/03/31 | T1: 2027/04/30 | U1: 2027/05/31 | V1: 2027/06/30 | W1: 2027/07/31 | X1: 2027/08/31 | Y1: 2027/09/30 | Z1: 2027/10/31 | AA1: 2027/11/30 | AB1: 2027/12/31 | AC1: 2028/01/31 | AD1: 2028/02/29 | AE1: 2028/03/31 | AF1: 2028/04/30 | AG1: 2028/05/31 | AH1: 2028/06/30 | AI1: 2028/07/31 | AJ1: 2028/08/31 | AK1: 2028/09/30 | AL1: 2028/10/31 | AM1: 2028/11/30 | AN1: 2028/12/31 | AO1: 2029/01/31 | AP1: 2029/02/28 | AQ1: 2029/03/31 | AR1: 2029/04/30 | AS1: 2029/05/31 | AT1: 2029/06/30 | AU1: 2029/07/31 | AV1: 2029/08/31 | AW1: 2029/09/30 | AX1: 2029/10/31 | AY1: 2029/11/30 | AZ1: 2029/12/31 | BA1: 2030/01/31 | BB1: 2030/02/28 | BC1: 2030/03/31 | BD1: 2030/04/30 | BE1: 2030/05/31 | BF1: 2030/06/30 | BG1: 2030/07/31 | BH1: 2030/08/31 | BI1: 2030/09/30 | BJ1: 2030/10/31 | BK1: 2030/11/30 | BL1: 2030/12/31
A2: fml_count | B2: 181 | C2: 165 | D2: 163 | E2: 156 | F2: 155 | G2: 153 | H2: 150 | I2: 149 | J2: 149 | K2: 148 | L2: 145 | M2: 133 | N2: 132 | O2: 132 | P2: 131 | Q2: 129 | R2: 125 | S2: 125 | T2: 121 | U2: 116 | V2: 115 | W2: 113 | X2: 111 | Y2: 97 | Z2: 87 | AA2: 86 | AB2: 86 | AC2: 81 | AD2: 75 | AE2: 69 | AF2: 65 | AG2: 63 | AH2: 48 | AI2: 37 | AJ2: 35 | AK2: 34 | AL2: 29 | AM2: 29 | AN2: 28 | AO2: 22 | AP2: 22 | AQ2: 22 | AR2: 20 | AS2: 17 | AT2: 14 | AU2: 12 | AV2: 11 | AW2: 11 | AX2: 8 | AY2: 8 | AZ2: 8 | BA2: 8 | BB2: 8 | BC2: 6 | BD2: 5 | BE2: 3 | BF2: 3 | BG2: 2 | BH2: 1 | BI2: 1 | BJ2: 1 | BK2: 1 | BL2: 1
A3: olmm_count | B3: 9 | C3: 9 | D3: 9 | E3: 9 | F3: 8 | G3: 8 | H3: 8 | I3: 8 | J3: 8 | K3: 8 | L3: 8 | M3: 8 | N3: 8 | O3: 8 | P3: 8 | Q3: 8 | R3: 8 | S3: 8 | T3: 8 | U3: 7 | V3: 7 | W3: 7 | X3: 7 | Y3: 7 | Z3: 2 | AA3: 2 | AB3: 2 | AC3: 2 | AD3: 2 | AE3: 2 | AF3: 2 | AG3: 1 | AH3: 1 | AI3: 1 | AJ3: 1 | AK3: 1 | AL3: 1 | AM3: 1 | AN3: 1 | AO3: 1 | AP3: 1 | AQ3: 1 | AR3: 1 | AS3: 1 | AT3: 1 | AU3: 1 | AV3: 1 | AW3: 1 | AX3: 1 | AY3: 1 | AZ3: 1 | BA3: 1 | BB3: 1 | BC3: 0 | BD3: 0 | BE3: 0 | BF3: 0 | BG3: 0 | BH3: 0 | BI3: 0 | BJ3: 0 | BK3: 0 | BL3: 0
A4: pl_count | B4: 0 | C4: 0 | D4: 0 | E4: 0 | F4: 0 | G4: 0 | H4: 0 | I4: 0 | J4: 0 | K4: 0 | L4: 0 | M4: 0 | N4: 0 | O4: 0 | P4: 0 | Q4: 0 | R4: 0 | S4: 0 | T4: 0 | U4: 0 | V4: 0 | W4: 0 | X4: 0 | Y4: 0 | Z4: 0 | AA4: 0 | AB4: 0 | AC4: 0 | AD4: 0 | AE4: 0 | AF4: 0 | AG4: 0 | AH4: 0 | AI4: 0 | AJ4: 0 | AK4: 0 | AL4: 0 | AM4: 0 | AN4: 0 | AO4: 0 | AP4: 0 | AQ4: 0 | AR4: 0 | AS4: 0 | AT4: 0 | AU4: 0 | AV4: 0 | AW4: 0 | AX4: 0 | AY4: 0 | AZ4: 0 | BA4: 0 | BB4: 0 | BC4: 0 | BD4: 0 | BE4: 0 | BF4: 0 | BG4: 0 | BH4: 0 | BI4: 0 | BJ4: 0 | BK4: 0 | BL4: 0
A5: revenue_p_m | B5: 2983657.9 | C5: 2851671.5 | D5: 2821250.9 | E5: 2749320.5 | F5: 2728690.6 | G5: 2710170.1 | H5: 2682284.7 | I5: 2671786.7 | J5: 2671786.7 | K5: 2658626.4 | L5: 2624016.2 | M5: 2520804.6 | N5: 2515422.4 | O5: 2515422.4 | P5: 2508946.5 | Q5: 2471139.1 | R5: 2402942.1 | S5: 2402942.1 | T5: 2353233.8 | U5: 2239391.1 | V5: 2228613 | W5: 2201771 | X5: 2183719.9 | Y5: 1579648.3 | Z5: 1237894.6 | AA5: 1220328.6 | AB5: 1220328.6 | AC5: 1150233 | AD5: 1083409.4 | AE5: 1008373.8 | AF5: 966068.27 | AG5: 906861.93 | AH5: 783337.99 | AI5: 671960.78 | AJ5: 662237.12 | AK5: 648718.43 | AL5: 573481.17 | AM5: 573481.17 | AN5: 559661.9 | AO5: 483985.09 | AP5: 483985.09 | AQ5: 483985.09 | AR5: 439007.22 | AS5: 392004.64 | AT5: 349958.11 | AU5: 326501.13 | AV5: 311487.32 | AW5: 311487.32 | AX5: 268303.54 | AY5: 268303.54 | AZ5: 268303.54 | BA5: 268303.54 | BB5: 268303.54 | BC5: 136730.74 | BD5: 128963.45 | BE5: 103063.11 | BF5: 103063.11 | BG5: 88259.64 | BH5: 75021.41 | BI5: 75021.41 | BJ5: 75021.41 | BK5: 75021.41 | BL5: 75021.41
A6: depreciation_p_m | B6: 1373374.2 | C6: 1314913.1 | D6: 1303752.6 | E6: 1272085.1 | F6: 1260890.2 | G6: 1252857.4 | H6: 1241690.6 | I6: 1237122.9 | J6: 1237122.9 | K6: 1232141.4 | L6: 1213774.2 | M6: 1179340.7 | N6: 1177289 | O6: 1177289 | P6: 1174798.8 | Q6: 1157909.5 | R6: 1128698.9 | S6: 1128698.9 | T6: 1106566.3 | U6: 1049857.1 | V6: 1046153.9 | W6: 1034020.3 | X6: 1026062.1 | Y6: 697459.79 | Z6: 502274.58 | AA6: 494600.22 | AB6: 494600.22 | AC6: 469407.97 | AD6: 440570.84 | AE6: 406862.22 | AF6: 389716.65 | AG6: 357397.76 | AH6: 310788.99 | AI6: 272242.81 | AJ6: 268666.79 | AK6: 264076.36 | AL6: 234676.87 | AM6: 234676.87 | AN6: 230230.94 | AO6: 199549.95 | AP6: 199549.95 | AQ6: 199549.95 | AR6: 179950.43 | AS6: 162249.96 | AT6: 146453.03 | AU6: 138142.21 | AV6: 132181.49 | AW6: 132181.49 | AX6: 114535.16 | AY6: 114535.16 | AZ6: 114535.16 | BA6: 114535.16 | BB6: 114535.16 | BC6: 56303.72 | BD6: 53403.43 | BE6: 42635.18 | BF6: 42635.18 | BG6: 36920.86 | BH6: 31574.16 | BI6: 31574.16 | BJ6: 31574.16 | BK6: 31574.16 | BL6: 31574.16
A7: interest_p_m | B7: 732074.57 | C7: 703558.55 | D7: 697901.21 | E7: 677964.1 | F7: 672007.51 | G7: 667155.66 | H7: 661721.84 | I7: 658777.82 | J7: 658777.82 | K7: 654677.55 | L7: 650117.03 | M7: 628134.32 | N7: 626898.88 | O7: 626898.88 | P7: 625010.86 | Q7: 614761.04 | R7: 595700.14 | S7: 595700.14 | T7: 581914.85 | U7: 562703.26 | V7: 560359.61 | W7: 550964.11 | X7: 544235.08 | Y7: 437079.37 | Z7: 349101.62 | AA7: 343264.16 | AB7: 343264.16 | AC7: 321237.56 | AD7: 297413.02 | AE7: 275669.15 | AF7: 260886.71 | AG7: 249126.58 | AH7: 214913.48 | AI7: 180721.92 | AJ7: 177515.04 | AK7: 173634.48 | AL7: 153740.28 | AM7: 153740.28 | AN7: 150472.38 | AO7: 130029.09 | AP7: 130029.09 | AQ7: 130029.09 | AR7: 118417.67 | AS7: 105242.27 | AT7: 92856.99 | AU7: 85164.77 | AV7: 80909.14 | AW7: 80909.14 | AX7: 67652.02 | AY7: 67652.02 | AZ7: 67652.02 | BA7: 67652.02 | BB7: 67652.02 | BC7: 36265.9 | BD7: 34783.77 | BE7: 29207.52 | BF7: 29207.52 | BG7: 24635.88 | BH7: 20130 | BI7: 20130 | BJ7: 20130 | BK7: 20130 | BL7: 20130
A8: admin_p_m | B8: 187249.11 | C8: 178308.7 | D8: 176431.11 | E8: 172682.52 | F8: 172055.11 | G8: 171229.26 | H8: 169993.26 | I8: 169685.46 | J8: 169685.46 | K8: 168734.97 | L8: 166823.83 | M8: 154736.48 | N8: 154316.48 | O8: 154316.48 | P8: 153756.81 | Q8: 151369.82 | R8: 146871.19 | S8: 146871.19 | T8: 143227.34 | U8: 136572.21 | V8: 135509.09 | W8: 133307.57 | X8: 131754.83 | Y8: 102327 | Z8: 87801.96 | AA8: 87451.96 | AB8: 87451.96 | AC8: 83206.86 | AD8: 79185.38 | AE8: 73629.51 | AF8: 70003.01 | AG8: 65896.08 | AH8: 59823.72 | AI8: 50590.37 | AJ8: 49785.77 | AK8: 48690.15 | AL8: 43175.82 | AM8: 43175.82 | AN8: 42055.71 | AO8: 36075.64 | AP8: 36075.64 | AQ8: 36075.64 | AR8: 32810.94 | AS8: 29385.36 | AT8: 26029.99 | AU8: 24002.62 | AV8: 22870.67 | AW8: 22870.67 | AX8: 19393.15 | AY8: 19393.15 | AZ8: 19393.15 | BA8: 19393.15 | BB8: 19393.15 | BC8: 10251.02 | BD8: 9813.25 | BE8: 8173.8 | BF8: 8173.8 | BG8: 6994.2 | BH8: 5826.68 | BI8: 5826.68 | BJ8: 5826.68 | BK8: 5826.68 | BL8: 5826.68
A9: maint_prov_p_m | B9: 8378143.9 | C9: 7182478.7 | D9: 6978291.7 | E9: 6804364.1 | F9: 6775809.5 | G9: 6719442.7 | H9: 6380891.1 | I9: 6354463.6 | J9: 6354463.6 | K9: 6322978.3 | L9: 6145957.1 | M9: 5575452.9 | N9: 5529407.1 | O9: 5529407.1 | P9: 5460646.1 | Q9: 5444374.9 | R9: 5401765.2 | S9: 5401765.2 | T9: 5285674.1 | U9: 4739333.8 | V9: 4689867.3 | W9: 4642487.5 | X9: 4625540.9 | Y9: 3431886.8 | Z9: 3161375 | AA9: 3147046.4 | AB9: 3147046.4 | AC9: 2889882.8 | AD9: 2625013.8 | AE9: 2431551.5 | AF9: 2369519.7 | AG9: 2281338.8 | AH9: 1612672.3 | AI9: 1305472.8 | AJ9: 1251846.5 | AK9: 1210325.9 | AL9: 996299.87 | AM9: 996299.87 | AN9: 904421.02 | AO9: 678329.86 | AP9: 678329.86 | AQ9: 678329.86 | AR9: 606872.76 | AS9: 450042.12 | AT9: 371878.73 | AU9: 309824.76 | AV9: 267391 | AW9: 267391 | AX9: 189139.86 | AY9: 189139.86 | AZ9: 189139.86 | BA9: 189139.86 | BB9: 189139.86 | BC9: 71758.82 | BD9: 58358.18 | BE9: 36033.02 | BF9: 36033.02 | BG9: 24785.52 | BH9: 19966.64 | BI9: 19966.64 | BJ9: 19966.64 | BK9: 19966.64 | BL9: 19966.64
A10: maintenance_fund | B10: 4838646 | C10: 4445256.6 | D10: 4428157.8 | E10: 4337526.3 | F10: 4331284.2 | G10: 4289222.1 | H10: 4282543 | I10: 4266368 | J10: 4266368 | K10: 4254848.4 | L10: 4165403.7 | M10: 3959008.1 | N10: 3947143.9 | O10: 3947143.9 | P10: 3895635.7 | Q10: 3887549.4 | R10: 3852403.6 | S10: 3852403.6 | T10: 3795149.1 | U10: 3556367.9 | V10: 3531454.7 | W10: 3519751.6 | X10: 3508214.5 | Y10: 2546461.5 | Z10: 2340240.5 | AA10: 2325911.9 | AB10: 2325911.9 | AC10: 2145859.3 | AD10: 1943023.6 | AE10: 1792809.1 | AF10: 1751999.4 | AG10: 1695024.9 | AH10: 1267729.1 | AI10: 1076966.2 | AJ10: 1042186.9 | AK10: 1018331.7 | AL10: 855839.33 | AM10: 855839.33 | AN10: 779292.73 | AO10: 595136.53 | AP10: 595136.53 | AQ10: 595136.53 | AR10: 530599.46 | AS10: 393050.23 | AT10: 334033.84 | AU10: 286211.2 | AV10: 258308.2 | AW10: 258308.2 | AX10: 189139.86 | AY10: 189139.86 | AZ10: 189139.86 | BA10: 189139.86 | BB10: 189139.86 | BC10: 71758.82 | BD10: 58358.18 | BE10: 36033.02 | BF10: 36033.02 | BG10: 24785.52 | BH10: 19966.64 | BI10: 19966.64 | BJ10: 19966.64 | BK10: 19966.64 | BL10: 19966.64
A11: other_fee_p_m | B11: 315192.43 | C11: 305717.25 | D11: 303552.64 | E11: 292526.73 | F11: 290252.3 | G11: 287203.78 | H11: 286756.34 | I11: 284930.27 | J11: 284930.27 | K11: 282888.1 | L11: 279576.51 | M11: 277314.07 | N11: 277239.07 | O11: 277239.07 | P11: 277164.07 | Q11: 272085.82 | R11: 262330.7 | S11: 262330.7 | T11: 258324.24 | U11: 243939.13 | V11: 241660.76 | W11: 241510.76 | X11: 240790.76 | Y11: 182393.09 | Z11: 148651.73 | AA11: 146049.77 | AB11: 146049.77 | AC11: 136528.86 | AD11: 134368.86 | AE11: 127688.26 | AF11: 124392.44 | AG11: 115821.52 | AH11: 104419.81 | AI11: 85949.85 | AJ11: 85799.85 | AK11: 83385.57 | AL11: 71546.17 | AM11: 71546.17 | AN11: 69185.95 | AO11: 60093.82 | AP11: 60093.82 | AQ11: 60093.82 | AR11: 53352.49 | AS11: 49770.64 | AT11: 44550.74 | AU11: 42262.36 | AV11: 41248.96 | AW11: 41248.96 | AX11: 38208.76 | AY11: 38208.76 | AZ11: 38208.76 | BA11: 38208.76 | BB11: 38208.76 | BC11: 20068.28 | BD11: 18796.26 | BE11: 14600.73 | BF11: 14600.73 | BG11: 13512.32 | BH11: 12498.91 | BI11: 12498.91 | BJ11: 12498.91 | BK11: 12498.91 | BL11: 12498.91
A12: total_cost | B12: 1.0350131e+08 | C12: 99015807 | D12: 98069007 | E12: 95450285 | F12: 94579736 | G12: 93905462 | H12: 92975813 | I12: 92558193 | J12: 92558193 | K12: 92082946 | L12: 91157365 | M12: 87054089 | N12: 86865225 | O12: 86865225 | P12: 86585389 | Q12: 85435765 | R12: 83216445 | S12: 83216445 | T12: 81467112 | U12: 78215083 | V12: 77717620 | W12: 76616850 | X12: 75840471 | Y12: 60093320 | Z12: 48264735 | AA12: 47660555 | AB12: 47660555 | AC12: 44767881 | AD12: 41448696 | AE12: 38406843 | AF12: 36593588 | AG12: 34540116 | AH12: 29788728 | AI12: 25242024 | AJ12: 24839714 | AK12: 24291904 | AL12: 21534726 | AM12: 21534726 | AN12: 20974667 | AO12: 18006820 | AP12: 18006820 | AQ12: 18006820 | AR12: 16374462 | AS12: 14661662 | AT12: 12983970 | AU12: 11970281 | AV12: 11404306 | AW12: 11404306 | AX12: 9665545.4 | AY12: 9665545.4 | AZ12: 9665545.4 | BA12: 9665545.4 | BB12: 9665545.4 | BC12: 5114472.4 | BD12: 4895585.3 | BE12: 4075854.7 | BF12: 4075854.7 | BG12: 3486050.1 | BH12: 2913340 | BI12: 2913340 | BJ12: 2913340 | BK12: 2913340 | BL12: 2913340
A13: nbv | B13: 77404909 | C13: 75630020 | D13: 73854712 | E13: 70942671 | F13: 69185447 | G13: 67531432 | H13: 65972461 | I13: 64477585 | J13: 63240462 | K13: 61707429 | L13: 60179696 | M13: 57024919 | N13: 55764744 | O13: 54587456 | P13: 53277252 | Q13: 51311387 | R13: 48672213 | S13: 47543514 | T13: 45468456 | U13: 43258699 | V13: 42022629 | W13: 40300382 | X13: 38773599 | Y13: 33341545 | Z13: 28015234 | AA13: 27185056 | AB13: 26690455 | AC13: 24643406 | AD13: 22560631 | AE13: 20701176 | AF13: 19244639 | AG13: 18200942 | AH13: 15680933 | AI13: 13021670 | AJ13: 12558103 | AK13: 12017052 | AL13: 10554279 | AM13: 10319603 | AN13: 9840527.4 | AO13: 8501156 | AP13: 8301606 | AQ13: 8102056.1 | AR13: 7426519.8 | AS13: 6537435.6 | AT13: 5602271.2 | AU13: 4963959 | AV13: 4617484.9 | AW13: 4485303.4 | AX13: 3667065 | AY13: 3552529.8 | AZ13: 3437994.6 | BA13: 3323459.5 | BB13: 3208924.3 | BC13: 1978971.1 | BD13: 1877797.6 | BE13: 1639990.4 | BF13: 1597355.2 | BG13: 1307774.7 | BH13: 1018890.4 | BI13: 987316.24 | BJ13: 955742.08 | BK13: 924167.92 | BL13: 892593.76
... A16: olmm_fleet_drop | B16: 0 | C16: 0 | D16: 0 | E16: 0 | F16: 1 | G16: 0 | H16: 0 | I16: 0 | J16: 0 | K16: 0 | L16: 0 | M16: 0 | N16: 0 | O16: 0 | P16: 0 | Q16: 0 | R16: 0 | S16: 0 | T16: 0 | U16: 1 | V16: 0 | W16: 0 | X16: 0 | Y16: 0 | Z16: 5 | AA16: 0 | AB16: 0 | AC16: 0 | AD16: 0 | AE16: 0 | AF16: 0 | AG16: 1 | AH16: 0 | AI16: 0 | AJ16: 0 | AK16: 0 | AL16: 0 | AM16: 0 | AN16: 0 | AO16: 0 | AP16: 0 | AQ16: 0 | AR16: 0 | AS16: 0 | AT16: 0 | AU16: 0 | AV16: 0 | AW16: 0 | AX16: 0 | AY16: 0 | AZ16: 0 | BA16: 0 | BB16: 0 | BC16: 1 | BD16: 0 | BE16: 0 | BF16: 0 | BG16: 0 | BH16: 0 | BI16: 0 | BJ16: 0 | BK16: 0 | BL16: 0

Sheet MOZ
A1: Value | B1: 2025/11/17 | C1: 2025/11/30 | D1: 2025/12/31 | E1: 2026/01/31 | F1: 2026/02/28 | G1: 2026/03/31 | H1: 2026/04/30 | I1: 2026/05/31 | J1: 2026/06/30 | K1: 2026/07/31 | L1: 2026/08/31 | M1: 2026/09/30 | N1: 2026/10/31 | O1: 2026/11/30 | P1: 2026/12/31 | Q1: 2027/01/31 | R1: 2027/02/28 | S1: 2027/03/31 | T1: 2027/04/30 | U1: 2027/05/31 | V1: 2027/06/30 | W1: 2027/07/31 | X1: 2027/08/31 | Y1: 2027/09/30 | Z1: 2027/10/31 | AA1: 2027/11/30 | AB1: 2027/12/31 | AC1: 2028/01/31 | AD1: 2028/02/29 | AE1: 2028/03/31 | AF1: 2028/04/30 | AG1: 2028/05/31 | AH1: 2028/06/30 | AI1: 2028/07/31 | AJ1: 2028/08/31 | AK1: 2028/09/30 | AL1: 2028/10/31 | AM1: 2028/11/30 | AN1: 2028/12/31 | AO1: 2029/01/31 | AP1: 2029/02/28 | AQ1: 2029/03/31 | AR1: 2029/04/30 | AS1: 2029/05/31 | AT1: 2029/06/30 | AU1: 2029/07/31 | AV1: 2029/08/31 | AW1: 2029/09/30 | AX1: 2029/10/31 | AY1: 2029/11/30 | AZ1: 2029/12/31 | BA1: 2030/01/31 | BB1: 2030/02/28 | BC1: 2030/03/31 | BD1: 2030/04/30 | BE1: 2030/05/31 | BF1: 2030/06/30 | BG1: 2030/07/31 | BH1: 2030/08/31 | BI1: 2030/09/30 | BJ1: 2030/10/31 | BK1: 2030/11/30 | BL1: 2030/12/31
A2: fml_count | B2: 257 | C2: 238 | D2: 237 | E2: 232 | F2: 231 | G2: 224 | H2: 222 | I2: 220 | J2: 218 | K2: 218 | L2: 208 | M2: 208 | N2: 205 | O2: 204 | P2: 203 | Q2: 203 | R2: 202 | S2: 202 | T2: 193 | U2: 181 | V2: 180 | W2: 153 | X2: 140 | Y2: 122 | Z2: 122 | AA2: 114 | AB2: 108 | AC2: 106 | AD2: 102 | AE2: 98 | AF2: 93 | AG2: 93 | AH2: 93 | AI2: 80 | AJ2: 68 | AK2: 67 | AL2: 62 | AM2: 58 | AN2: 57 | AO2: 57 | AP2: 57 | AQ2: 55 | AR2: 51 | AS2: 49 | AT2: 37 | AU2: 30 | AV2: 29 | AW2: 29 | AX2: 27 | AY2: 27 | AZ2: 25 | BA2: 23 | BB2: 23 | BC2: 22 | BD2: 22 | BE2: 22 | BF2: 17 | BG2: 7 | BH2: 7 | BI2: 0 | BJ2: 0 | BK2: 0 | BL2: 0
A3: olmm_count | B3: 36 | C3: 36 | D3: 34 | E3: 34 | F3: 33 | G3: 33 | H3: 32 | I3: 30 | J3: 30 | K3: 28 | L3: 28 | M3: 18 | N3: 18 | O3: 18 | P3: 18 | Q3: 18 | R3: 18 | S3: 18 | T3: 18 | U3: 16 | V3: 16 | W3: 16 | X3: 16 | Y3: 16 | Z3: 16 | AA3: 14 | AB3: 10 | AC3: 9 | AD3: 9 | AE3: 9 | AF3: 9 | AG3: 7 | AH3: 7 | AI3: 5 | AJ3: 4 | AK3: 1 | AL3: 1 | AM3: 1 | AN3: 1 | AO3: 0 | AP3: 0 | AQ3: 0 | AR3: 0 | AS3: 0 | AT3: 0 | AU3: 0 | AV3: 0 | AW3: 0 | AX3: 0 | AY3: 0 | AZ3: 0 | BA3: 0 | BB3: 0 | BC3: 0 | BD3: 0 | BE3: 0 | BF3: 0 | BG3: 0 | BH3: 0 | BI3: 0 | BJ3: 0 | BK3: 0 | BL3: 0
A4: pl_count | B4: 0 | C4: 0 | D4: 0 | E4: 0 | F4: 0 | G4: 0 | H4: 0 | I4: 0 | J4: 0 | K4: 0 | L4: 0 | M4: 0 | N4: 0 | O4: 0 | P4: 0 | Q4: 0 | R4: 0 | S4: 0 | T4: 0 | U4: 0 | V4: 0 | W4: 0 | X4: 0 | Y4: 0 | Z4: 0 | AA4: 0 | AB4: 0 | AC4: 0 | AD4: 0 | AE4: 0 | AF4: 0 | AG4: 0 | AH4: 0 | AI4: 0 | AJ4: 0 | AK4: 0 | AL4: 0 | AM4: 0 | AN4: 0 | AO4: 0 | AP4: 0 | AQ4: 0 | AR4: 0 | AS4: 0 | AT4: 0 | AU4: 0 | AV4: 0 | AW4: 0 | AX4: 0 | AY4: 0 | AZ4: 0 | BA4: 0 | BB4: 0 | BC4: 0 | BD4: 0 | BE4: 0 | BF4: 0 | BG4: 0 | BH4: 0 | BI4: 0 | BJ4: 0 | BK4: 0 | BL4: 0
A5: revenue_p_m | B5: 22807645 | C5: 21662615 | D5: 21266685 | E5: 20920125 | F5: 20662883 | G5: 20262628 | H5: 20017323 | I5: 19672711 | J5: 19447910 | K5: 19287649 | L5: 18708683 | M5: 17597523 | N5: 17363352 | O5: 17285512 | P5: 17231287 | Q5: 17231287 | R5: 17147141 | S5: 17147141 | T5: 16292494 | U5: 15185445 | V5: 15115097 | W5: 13828765 | X5: 13053370 | Y5: 11979650 | Z5: 11979650 | AA5: 11331219 | AB5: 10231818 | AC5: 10115686 | AD5: 9833919.4 | AE5: 9123181.8 | AF5: 8478120.2 | AG5: 8248958.4 | AH5: 8248958.4 | AI5: 7172329.4 | AJ5: 6184661.4 | AK5: 5776927.7 | AL5: 5461498.1 | AM5: 5160698.1 | AN5: 5119423 | AO5: 5041121.9 | AP5: 5041121.9 | AQ5: 4907550.9 | AR5: 4544621.1 | AS5: 4464979.4 | AT5: 3745783 | AU5: 3130131.2 | AV5: 3044825.8 | AW5: 3044825.8 | AX5: 2756367.7 | AY5: 2756367.7 | AZ5: 2514361.2 | BA5: 2344771.7 | BB5: 2344771.7 | BC5: 2304950.8 | BD5: 2304950.8 | BE5: 2304950.8 | BF5: 1993741.9 | BG5: 353701.25 | BH5: 353701.25 | BI5: 0 | BJ5: 0 | BK5: 0 | BL5: 0
A6: depreciation_p_m | B6: 9276224.4 | C6: 8861310.8 | D6: 8614082.7 | E6: 8478914.2 | F6: 8340043.6 | G6: 8190155.3 | H6: 8083625.9 | I6: 7931354.7 | J6: 7819080.3 | K6: 7745362.4 | L6: 7496120.1 | M6: 6983620.1 | N6: 6869273.8 | O6: 6840171.2 | P6: 6819368.6 | Q6: 6819368.6 | R6: 6783243.6 | S6: 6783243.6 | T6: 6395964.4 | U6: 5945152.9 | V6: 5919635.3 | W6: 5425613.9 | X6: 5135828.4 | Y6: 4757021.1 | Z6: 4757021.1 | AA6: 4491374.4 | AB6: 3975788.7 | AC6: 3934029.7 | AD6: 3798916.5 | AE6: 3420424.1 | AF6: 3064516.9 | AG6: 2957329.4 | AH6: 2957329.4 | AI6: 2523239.7 | AJ6: 2093755.2 | AK6: 1904541.8 | AL6: 1771265.5 | AM6: 1641969.1 | AN6: 1627865.8 | AO6: 1587214.6 | AP6: 1587214.6 | AQ6: 1538203.7 | AR6: 1391057.9 | AS6: 1364503.7 | AT6: 1090713 | AU6: 867671.76 | AV6: 836976.22 | AW6: 836976.22 | AX6: 704250.36 | AY6: 704250.36 | AZ6: 608270.96 | BA6: 543180.72 | BB6: 543180.72 | BC6: 529903.61 | BD6: 529903.61 | BE6: 529903.61 | BF6: 420991.29 | BG6: 111939.59 | BH6: 111939.59 | BI6: 0 | BJ6: 0 | BK6: 0 | BL6: 0
A7: interest_p_m | B7: 7012245.6 | C7: 6763848.8 | D7: 6660989.8 | E7: 6531138.5 | F7: 6445075.3 | G7: 6331742.7 | H7: 6241639.1 | I7: 6137534.9 | J7: 6067100.5 | K7: 5999982.9 | L7: 5827310.7 | M7: 5360697.5 | N7: 5308203.7 | O7: 5279651.6 | P7: 5260461.1 | Q7: 5260461.1 | R7: 5227570.6 | S7: 5227570.6 | T7: 4947052.4 | U7: 4565103.4 | V7: 4536686.7 | W7: 4081242.9 | X7: 3833767.2 | Y7: 3473170.7 | Z7: 3473170.7 | AA7: 3245148.1 | AB7: 2898459.5 | AC7: 2857118.6 | AD7: 2782254.9 | AE7: 2609806.1 | AF7: 2466411 | AG7: 2369422.3 | AH7: 2369422.3 | AI7: 2026196.6 | AJ7: 1727301.8 | AK7: 1564575.7 | AL7: 1474617.4 | AM7: 1387926.6 | AN7: 1374493.9 | AO7: 1345557.5 | AP7: 1345557.5 | AQ7: 1309473 | AR7: 1168331.5 | AS7: 1142885 | AT7: 905428.61 | AU7: 671937.01 | AV7: 639736.22 | AW7: 639736.22 | AX7: 538213.4 | AY7: 538213.4 | AZ7: 455655.4 | BA7: 404504.4 | BB7: 404504.4 | BC7: 391781.14 | BD7: 391781.14 | BE7: 391781.14 | BF7: 314057.58 | BG7: 112444.78 | BH7: 112444.78 | BI7: 0 | BJ7: 0 | BK7: 0 | BL7: 0
A8: admin_p_m | B8: 1800220.3 | C8: 1729073.7 | D8: 1702573.3 | E8: 1671184.5 | F8: 1648150.4 | G8: 1618094.6 | H8: 1595490.9 | I8: 1574874.3 | J8: 1556563.3 | K8: 1539362.5 | L8: 1483407.3 | M8: 1363824 | N8: 1342211.7 | O8: 1335503.4 | P8: 1330674.2 | Q8: 1330674.2 | R8: 1322245.1 | S8: 1322245.1 | T8: 1250830 | U8: 1151793.8 | V8: 1144852.2 | W8: 1028030.9 | X8: 965297.1 | Y8: 875274.28 | Z8: 875274.28 | AA8: 817870.92 | AB8: 735446.04 | AC8: 717978.85 | AD8: 705948.2 | AE8: 655395.91 | AF8: 604658.37 | AG8: 584650.05 | AH8: 584650.05 | AI8: 504464.85 | AJ8: 421673.54 | AK8: 386684.98 | AL8: 362438.2 | AM8: 339489.13 | AN8: 336600.13 | AO8: 330132.9 | AP8: 330132.9 | AQ8: 321470.94 | AR8: 291187.04 | AS8: 285725.4 | AT8: 232505.15 | AU8: 180467.98 | AV8: 173306.65 | AW8: 173306.65 | AX8: 147270.21 | AY8: 147270.21 | AZ8: 126501.12 | BA8: 113232.1 | BB8: 113232.1 | BC8: 110501.28 | BD8: 110501.28 | BE8: 110501.28 | BF8: 88078.18 | BG8: 27984.88 | BH8: 27984.88 | BI8: 0 | BJ8: 0 | BK8: 0 | BL8: 0
A9: maint_prov_p_m | B9: 87574402 | C9: 70819961 | D9: 70459961 | E9: 68648013 | F9: 68403985 | G9: 64560081 | H9: 63615053 | I9: 62415925 | J9: 61614032 | K9: 61614032 | L9: 57472490 | M9: 57472490 | N9: 55727210 | O9: 55166704 | P9: 54981631 | Q9: 54981631 | R9: 54712476 | S9: 54712476 | T9: 51469659 | U9: 46309197 | V9: 45989052 | W9: 39019045 | X9: 34795757 | Y9: 28620611 | Z9: 28620611 | AA9: 26540929 | AB9: 24292671 | AC9: 23855343 | AD9: 22419784 | AE9: 21392992 | AF9: 20356370 | AG9: 20356370 | AH9: 20356370 | AI9: 16253386 | AJ9: 12822859 | AK9: 12517337 | AL9: 11223226 | AM9: 10018382 | AN9: 9802382.1 | AO9: 9802382.1 | AP9: 9802382.1 | AQ9: 9401390.1 | AR9: 8657390.1 | AS9: 8303990.1 | AT9: 6418409.8 | AU9: 4871760.2 | AV9: 4670794 | AW9: 4670794 | AX9: 4336627.2 | AY9: 4336627.2 | AZ9: 3868627.2 | BA9: 3527377.2 | BB9: 3527377.2 | BC9: 3443677.2 | BD9: 3443677.2 | BE9: 3443677.2 | BF9: 2886277.8 | BG9: 223146 | BH9: 223146 | BI9: 0 | BJ9: 0 | BK9: 0 | BL9: 0
A10: maintenance_fund | B10: 52210783 | C10: 40157121 | D10: 39811387 | E10: 38900522 | F10: 38716146 | G10: 37622807 | H10: 37126130 | I10: 36512003 | J10: 35893972 | K10: 35893972 | L10: 34966946 | M10: 34966946 | N10: 34068295 | O10: 33755791 | P10: 33681510 | Q10: 33681510 | R10: 33594206 | S10: 33594206 | T10: 31774247 | U10: 29689035 | V10: 29471655 | W10: 27410156 | X10: 25332932 | Y10: 22386693 | Z10: 22386693 | AA10: 20307011 | AB10: 18944407 | AC10: 18638560 | AD10: 17498232 | AE10: 16909458 | AF10: 16244468 | AG10: 16244468 | AH10: 16244468 | AI10: 13203241 | AJ10: 11103649 | AK10: 10849831 | AL10: 10035945 | AM10: 9356894.7 | AN10: 9238473.5 | AO10: 9238473.5 | AP10: 9238473.5 | AQ10: 8861200.4 | AR10: 8249328.9 | AS10: 7934243.9 | AT10: 6232324 | AU10: 4731553.8 | AV10: 4530587.5 | AW10: 4530587.5 | AX10: 4270686.1 | AY10: 4270686.1 | AZ10: 3831728 | BA10: 3508127.4 | BB10: 3508127.4 | BC10: 3438595.1 | BD10: 3438595.1 | BE10: 3438595.1 | BF10: 2886277.8 | BG10: 223146 | BH10: 223146 | BI10: 0 | BJ10: 0 | BK10: 0 | BL10: 0
A11: other_fee_p_m | B11: 1141434.9 | C11: 1132094.9 | D11: 1127752.3 | E11: 1119707.3 | F11: 1117611 | G11: 1111661 | H11: 1108663.7 | I11: 1104155.9 | J11: 1102430.4 | K11: 1100205.7 | L11: 1091680.2 | M11: 1079217.2 | N11: 1076667.2 | O11: 1074867.2 | P11: 1070752.2 | Q11: 1070752.2 | R11: 1069902.2 | S11: 1069902.2 | T11: 1055987.2 | U11: 1033979.4 | V11: 1032129.4 | W11: 989000.9 | X11: 966369.9 | Y11: 936967.9 | Z11: 936967.9 | AA11: 926243.2 | AB11: 908214.8 | AC11: 905268.5 | AD11: 900471.4 | AE11: 893806.4 | AF11: 887556.4 | AG11: 882579.12 | AH11: 882579.12 | AI11: 857856.52 | AJ11: 809920.22 | AK11: 800430.22 | AL11: 782888.6 | AM11: 769218.6 | AN11: 767368.6 | AO11: 765122.3 | AP11: 765122.3 | AQ11: 761482.65 | AR11: 754324.05 | AS11: 750744.75 | AT11: 721208.6 | AU11: 708258.6 | AV11: 706408.6 | AW11: 706408.6 | AX11: 702768.95 | AY11: 702768.95 | AZ11: 699068.95 | BA11: 691489.65 | BB11: 691489.65 | BC11: 689700 | BD11: 689700 | BE11: 689700 | BF11: 680450 | BG11: 26950 | BH11: 26950 | BI11: 0 | BJ11: 0 | BK11: 0 | BL11: 0
A12: total_cost | B12: 6.2699128e+08 | C12: 5.904305e+08 | D12: 5.8134466e+08 | E12: 5.706102e+08 | F12: 5.6271277e+08 | G12: 5.5242851e+08 | H12: 5.4468552e+08 | I12: 5.3541437e+08 | J12: 5.2913632e+08 | K12: 5.2323888e+08 | L12: 5.0577538e+08 | M12: 4.6477538e+08 | N12: 4.573723e+08 | O12: 4.550723e+08 | P12: 4.5341659e+08 | Q12: 4.5341659e+08 | R12: 4.5052659e+08 | S12: 4.5052659e+08 | T12: 4.2606884e+08 | U12: 3.9216839e+08 | V12: 3.8978839e+08 | W12: 3.4975592e+08 | X12: 3.2833287e+08 | Y12: 2.9746787e+08 | Z12: 2.9746787e+08 | AA12: 2.777867e+08 | AB12: 2.4954729e+08 | AC12: 2.4607791e+08 | AD12: 2.3806958e+08 | AE12: 2.2156918e+08 | AF12: 2.0731164e+08 | AG12: 2.0045164e+08 | AH12: 2.0045164e+08 | AI12: 1.7295955e+08 | AJ12: 1.4457393e+08 | AK12: 1.3257784e+08 | AL12: 1.2426465e+08 | AM12: 1.1639639e+08 | AN12: 1.1540587e+08 | AO12: 1.1318853e+08 | AP12: 1.1318853e+08 | AQ12: 1.1021871e+08 | AR12: 99835656 | AS12: 97963092 | AT12: 79716136 | AU12: 61874802 | AV12: 59419486 | AW12: 59419486 | AX12: 50492703 | AY12: 50492703 | AZ12: 43371870 | BA12: 38822489 | BB12: 38822489 | BC12: 37886207 | BD12: 37886207 | BE12: 37886207 | BF12: 30198276 | BG12: 9594827.6 | BH12: 9594827.6 | BI12: 0 | BJ12: 0 | BK12: 0 | BL12: 0
A13: nbv | B13: 3.5565563e+08 | C13: 3.5132765e+08 | D13: 3.41205e+08 | E13: 3.2826898e+08 | F13: 3.1813396e+08 | G13: 3.0803619e+08 | H13: 2.9843636e+08 | I13: 2.8801936e+08 | J13: 2.7825621e+08 | K13: 2.6888905e+08 | L13: 2.5902511e+08 | M13: 2.4076649e+08 | N13: 2.3236481e+08 | O13: 2.249126e+08 | P13: 2.1739443e+08 | Q13: 2.1057507e+08 | R13: 2.030332e+08 | S13: 1.9624995e+08 | T13: 1.8395532e+08 | U13: 1.6921114e+08 | V13: 1.6241704e+08 | W13: 1.4598099e+08 | X13: 1.3322993e+08 | Y13: 1.16486e+08 | Z13: 1.1172898e+08 | AA13: 1.0016963e+08 | AB13: 90050955 | AC13: 85102228 | AD13: 79687572 | AE13: 74216985 | AF13: 70023530 | AG13: 65136826 | AH13: 62179496 | AI13: 54814643 | AJ13: 48473661 | AK13: 43646466 | AL13: 41377331 | AM13: 39495588 | AN13: 37709300 | AO13: 35815353 | AP13: 34228139 | AQ13: 32229206 | AR13: 29136691 | AS13: 27466322 | AT13: 23758710 | AU13: 18086353 | AV13: 16574402 | AW13: 15737426 | AX13: 13916993 | AY13: 13212743 | AZ13: 11146423 | BA13: 9861640.1 | BB13: 9318459.4 | BC13: 8635623.4 | BD13: 8105719.7 | BE13: 7575816.1 | BF13: 5892720.7 | BG13: 3102331.4 | BH13: 2990391.8 | BI13: 0 | BJ13: 0 | BK13: 0 | BL13: 0
... A16: olmm_fleet_drop | B16: 0 | C16: 0 | D16: 2 | E16: 0 | F16: 1 | G16: 0 | H16: 1 | I16: 2 | J16: 0 | K16: 2 | L16: 0 | M16: 10 | N16: 0 | O16: 0 | P16: 0 | Q16: 0 | R16: 0 | S16: 0 | T16: 0 | U16: 2 | V16: 0 | W16: 0 | X16: 0 | Y16: 0 | Z16: 0 | AA16: 2 | AB16: 4 | AC16: 1 | AD16: 0 | AE16: 0 | AF16: 0 | AG16: 2 | AH16: 0 | AI16: 2 | AJ16: 1 | AK16: 3 | AL16: 0 | AM16: 0 | AN16: 0 | AO16: 1 | AP16: 0 | AQ16: 0 | AR16: 0 | AS16: 0 | AT16: 0 | AU16: 0 | AV16: 0 | AW16: 0 | AX16: 0 | AY16: 0 | AZ16: 0 | BA16: 0 | BB16: 0 | BC16: 0 | BD16: 0 | BE16: 0 | BF16: 0 | BG16: 0 | BH16: 0 | BI16: 0 | BJ16: 0 | BK16: 0 | BL16: 0

Sheet NAM
